File: SU - Suspension/test en traction/Courbes/triangles/Specimen_RawData_2.csv
Temps;Déplacement;Charge
(sec);(mm);(N)
0;0,08586;43,83308
0,08;0,0858;42,394
0,16;0,08598;42,1625
0,24;0,08616;42,01449
0,32;0,08717;45,8482
0,4;0,08855;54,9668
0,48;0,08998;62,30121
0,56;0,09166;73,25447
0,64;0,09303;80,7658
0,72;0,09441;88,83715
0,8;0,09578;97,55595
0,88;0,09722;105,25702
0,96;0,09853;113,13356
1,04;0,09973;118,89883
1,12;0,10116;126,86789
1,2;0,1026;134,41846
1,28;0,10391;141,97652
1,36;0,10523;149,16075
1,44;0,1066;156,90584
1,52;0,10798;164,47499
1,6;0,10924;171,51224
1,68;0,11031;177,68613
1,76;0,11181;185,99271
1,84;0,11318;193,46996
1,92;0,11456;200,47596
2;0,11587;207,71325
2,08;0,11713;214,8693
2,16;0,1185;222,53713
2,24;0,11982;230,12776
2,32;0,12101;237,65524
2,4;0,12251;243,71159
2,48;0,12382;252,74267
2,56;0,1252;259,23769
2,64;0,12651;267,02066
2,72;0,12783;274,16213
2,8;0,12926;281,97325
2,88;0,13052;288,44138
2,96;0,13172;294,83878
3,04;0,13321;302,55716
3,12;0,13453;310,03044
3,2;0,1359;317,04325
3,28;0,13722;323,95571
3,36;0,13853;329,67262
3,44;0,13991;336,92955
3,52;0,1411;343,56518
3,6;0,14236;349,27977
3,68;0,14385;356,81645
3,76;0,14523;363,08435
3,84;0,1466;370,49276
3,92;0,14792;376,72026
4;0,14923;383,15414
4,08;0,15061;389,07663
4,16;0,15181;394,86843
4,24;0,15306;400,02032
4,32;0,15462;407,87053
4,4;0,15587;415,73839
4,48;0,15725;421,20977
4,56;0,15856;427,78673
4,64;0,15994;434,3247
4,72;0,16131;441,26799
4,8;0,16245;445,87199
4,88;0,1637;451,46313
4,96;0,1652;459,49835
5,04;0,16651;465,03157
5,12;0,16783;471,41751
5,2;0,1692;477,41537
5,28;0,17058;484,32504
5,36;0,17189;490,34809
5,44;0,17309;495,37444
5,52;0,17441;501,80024
5,6;0,1759;507,73029
5,68;0,17722;513,17154
5,76;0,17853;518,75999
5,84;0,17991;524,79357
5,92;0,18128;529,81474
6;0,18254;534,24966
6,08;0,18373;537,77141
6,16;0,18511;540,33943
6,24;0,18654;543,98952
6,32;0,18786;546,56444
6,4;0,18917;550,60452
6,48;0,19049;556,60568
6,56;0,19192;563,11772
6,64;0,19324;569,65961
6,72;0,19438;573,71273
6,8;0,19581;579,36208
6,88;0,19725;587,90515
6,96;0,1985;592,7904
7,04;0,19988;599,10743
7,12;0,20125;605,01383
7,2;0,20269;613,81641
7,28;0,20388;619,72258
7,36;0,20502;624,44676
7,44;0,20651;631,09337
7,52;0,20789;637,10995
7,6;0,2092;642,83349
7,68;0,21058;649,01616
7,76;0,21189;654,43572
7,84;0,21327;659,96004
7,92;0,21446;665,52884
8;0,21572;670,82709
8,08;0,21722;676,68818
8,16;0,21853;682,23584
8,24;0,21985;687,75183
8,32;0,22122;694,33833
8,4;0,22254;698,68588
8,48;0,22391;704,52197
8,56;0,22517;710,07353
8,64;0,22618;713,76376
8,72;0,22792;722,83936
8,8;0,22917;726,74113
8,88;0,23055;732,16092
8,96;0,23186;737,37414
9,04;0,23324;741,43284
9,12;0,23455;747,22245
9,2;0,23575;750,66588
9,28;0,23707;754,84645
9,36;0,23856;759,62436
9,44;0,23988;765,47829
9,52;0,24125;769,76521
9,6;0,24257;774,25614
9,68;0,24394;779,0965
9,76;0,24526;783,7832
9,84;0,24639;786,90704
9,92;0,24777;790,00322
10;0,2492;794,69634
10,08;0,25052;798,71081
10,16;0,25189;803,15331
10,24;0,25321;806,37401
10,32;0,25458;810,64394
10,4;0,25596;815,68854
10,48;0,25709;817,01297
10,56;0,25847;820,7432
10,64;0,25985;823,60758
10,72;0,26116;827,49091
10,8;0,2626;832,22296
10,88;0,26391;836,04734
10,96;0,26529;839,14287
11,04;0,26654;842,55943
11,12;0,26768;843,59804
11,2;0,26917;845,27452
11,28;0,27055;848,5416
11,36;0,27192;850,96685
11,44;0,27324;852,52281
11,52;0,27455;854,92013
11,6;0,27599;856,79004
11,68;0,27712;858,22642
11,76;0,27838;858,49585
11,84;0,27993;860,97354
11,92;0,28119;862,25085
12;0,28257;863,19959
12,08;0,28388;864,7643
12,16;0,28526;865,36147
12,24;0,28663;867,32311
12,32;0,28783;867,34593
12,4;0,28908;867,34723
12,48;0,29058;868,78007
12,56;0,29189;872,02964
12,64;0,29321;873,15738
12,72;0,29452;871,74531
12,8;0,2959;872,10359
12,88;0,29727;872,50182
12,96;0,29835;870,91252
13,04;0,29972;871,02307
13,12;0,30122;873,20851
13,2;0,30253;872,60166
13,28;0,30391;873,06863
13,36;0,30523;872,30699
13,44;0,3066;873,03901
13,52;0,30786;872,59328
13,6;0,30899;870,80989
13,68;0,31049;870,05561
13,76;0,31192;871,27546
13,84;0,31318;871,09664
13,92;0,31455;871,5583
14;0,31587;871,51434
14,08;0,3173;871,92077
14,16;0,31856;871,68664
14,24;0,31969;870,02274
14,32;0,32113;868,88513
14,4;0,32256;870,89473
14,48;0,32388;869,77612
14,56;0,32525;869,64779
14,64;0,32657;870,21412
14,72;0,32801;870,09696
14,8;0,3292;869,53174
14,88;0,33034;868,01071
14,96;0,33183;867,18919
15,04;0,33321;869,337
15,12;0,33458;870,47005
15,2;0,3359;869,83005
15,28;0,33721;868,71656
15,36;0,33859;868,23422
15,44;0,33978;867,79147
15,52;0,34104;865,27932
15,6;0,34253;866,02466
15,68;0,34385;866,2967
15,76;0,34516;864,9583
15,84;0,34654;865,3379
15,92;0,34786;864,66875
16;0,34929;865,36659
16,08;0,35043;863,82097
16,16;0,35174;862,51367
16,24;0,35324;864,02586
16,32;0,35455;862,84392
16,4;0,35587;862,83721
16,48;0,35712;862,10668
16,56;0,3585;861,7972
16,64;0,35993;862,40945
16,72;0,36107;861,02374
16,8;0,36244;860,19766
16,88;0,36394;860,72162
16,96;0,36519;860,35617
17,04;0,36657;859,08733
17,12;0,36788;859,53362
17,2;0,36926;859,12775
17,28;0,37058;859,1773
17,36;0,37171;858,50805
17,44;0,37315;856,76657
17,52;0,37458;858,39136
17,6;0,3759;857,64127
17,68;0,37721;857,32248
17,76;0,37859;857,21007
17,84;0,37996;857,10399
17,92;0,38122;857,44504
18;0,38241;855,9132
18,08;0,38379;855,13098
18,16;0,38522;856,5967
18,24;0,38654;856,971
18,32;0,38791;856,90599
18,4;0,38929;855,94906
18,48;0,39066;855,70058
18,56;0,39186;853,66378
18,64;0,393;851,8585
18,72;0,39449;852,55653
18,8;0,39587;853,29423
18,88;0,39718;851,94036
18,96;0,39856;852,61846
19,04;0,39987;854,85503
19,12;0,40125;860,5903
19,2;0,4025;866,51249
19,28;0,4037;870,95732
19,36;0,40513;877,2999
19,44;0,40651;885,37093
19,52;0,40782;890,97396
19,6;0,4092;899,01052
19,68;0,41051;905,39427
19,76;0,41189;911,94417
19,84;0,41315;917,84103
19,92;0,4144;923,32521
20;0,4159;930,40848
20,08;0,41721;936,96499
20,16;0,41853;943,95438
20,24;0,4199;950,54936
20,32;0,42134;957,4757
20,4;0,42265;964,27528
20,48;0,42379;969,56342
20,56;0,42504;974,7019
20,64;0,42642;981,94657
20,72;0,42785;989,48628
20,8;0,42923;995,42504
20,88;0,43054;1001,66546
20,96;0,43192;1008,74379
21,04;0,43323;1014,8285
21,12;0,43443;1020,10733
21,2;0,43581;1025,97112
21,28;0,43724;1033,0135
21,36;0,4385;1038,23747
21,44;0,43987;1044,2229
21,52;0,44119;1050,6778
21,6;0,44262;1056,81149
21,68;0,44394;1063,76866
21,76;0,44513;1069,23366
21,84;0,44645;1074,70946
21,92;0,44788;1081,24446
22;0,4492;1086,65302
22,08;0,45051;1092,58322
22,16;0,45183;1098,95933
22,24;0,4532;1105,23244
22,32;0,45452;1111,59803
22,4;0,45572;1116,54019
22,48;0,45709;1122,0837
22,56;0,45853;1128,96794
22,64;0,45984;1134,49767
22,72;0,46116;1140,19783
22,8;0,46253;1145,90032
22,88;0,46391;1152,76314
22,96;0,46516;1158,3386
23,04;0,46636;1162,48103
23,12;0,46785;1168,39251
23,2;0,46923;1175,34399
23,28;0,47054;1180,60932
23,36;0,47186;1186,38771
23,44;0,47317;1192,41495
23,52;0,47461;1201,0579
23,6;0,4758;1205,47647
23,68;0,477;1209,97168
23,76;0,47856;1216,32479
23,84;0,47981;1223,0495
23,92;0,48119;1228,27515
24;0,48256;1234,84991
24,08;0,48394;1240,64721
24,16;0,48525;1246,58691
24,24;0,48639;1251,53055
24,32;0,48776;1256,61008
24,4;0,48926;1262,99039
24,48;0,49057;1268,21809
24,56;0,49195;1273,07326
24,64;0,49326;1279,34013
24,72;0,49458;1285,21677
24,8;0,49589;1290,39064
24,88;0,49703;1295,37974
24,96;0,49846;1299,98652
25,04;0,4999;1307,35673
25,12;0,50116;1312,63332
25,2;0,50253;1317,94224
25,28;0,50385;1323,10288
25,36;0,50522;1328,78711
25,44;0,50654;1334,91876
25,52;0,50773;1338,98463
25,6;0,50917;1344,67119
25,68;0,51054;1350,47697
25,76;0,51186;1356,17917
25,84;0,51323;1362,29461
25,92;0,51455;1366,98382
26;0,51592;1372,27001
26,08;0,51724;1378,70554
26,16;0,51837;1381,98053
26,24;0,51981;1386,98202
26,32;0,52113;1392,75389
26,4;0,5225;1398,75337
26,48;0,52388;1405,00534
26,56;0,52519;1410,1591
26,64;0,52663;1415,74303
26,72;0,52782;1420,53524
26,8;0,52902;1425,2373
26,88;0,53051;1431,24415
26,96;0,53189;1437,08261
27,04;0,5332;1442,11976
27,12;0,53452;1447,46117
27,2;0,53589;1453,41596
27,28;0,53733;1459,0784
27,36;0,53852;1465,13525
27,44;0,53978;1469,13724
27,52;0,54121;1475,54036
27,6;0,54253;1480,00354
27,68;0,54385;1485,6902
27,76;0,54522;1490,56008
27,84;0,5466;1496,47892
27,92;0,54797;1500,92039
28;0,54911;1505,42744
28,08;0,55036;1509,84386
28,16;0,55186;1517,05919
28,24;0,55317;1521,81005
28,32;0,55455;1527,48954
28,4;0,55586;1533,12758
28,48;0,55724;1537,7813
28,56;0,55861;1543,15596
28,64;0,55975;1547,50319
28,72;0,56112;1552,25461
28,8;0,56256;1558,56265
28,88;0,56387;1564,09312
28,96;0,56525;1569,35174
29,04;0,56657;1574,43006
29,12;0,56794;1579,04699
29,2;0,56926;1584,87707
29,28;0,57039;1588,17507
29,36;0,57177;1592,27997
29,44;0,57326;1599,20901
29,52;0,57452;1603,44895
29,6;0,57583;1608,82249
29,68;0,57715;1614,59092
29,76;0,57858;1619,32241
29,84;0,5799;1624,20217
29,92;0,58103;1628,53152
30;0,58253;1634,2856
30,08;0,5839;1643,76479
30,16;0,58528;1648,03155
30,24;0,58659;1653,0456
30,32;0,58785;1657,98422
30,4;0,58929;1663,43376
30,48;0,59048;1667,26075
30,56;0,59174;1670,84131
30,64;0,59329;1676,81333
30,72;0,59455;1682,1634
30,8;0,59586;1687,21285
30,88;0,59718;1692,28595
30,96;0,59855;1697,72971
31,04;0,59993;1703,12785
31,12;0,60112;1707,49407
31,2;0,60238;1711,40693
31,28;0,60387;1717,34504
31,36;0,60513;1723,28334
31,44;0,6065;1726,66591
31,52;0,60788;1732,10893
31,6;0,60931;1737,54543
31,68;0,61063;1742,50826
31,76;0,61177;1745,78708
31,84;0,61308;1750,58469
31,92;0,61458;1756,76998
32;0,61589;1761,27553
32,08;0,61721;1766,40004
32,16;0,61858;1770,92515
32,24;0,61996;1776,66526
32,32;0,62127;1780,46152
32,4;0,62241;1785,025
32,48;0,62372;1789,52087
32,56;0,62516;1795,83691
32,64;0,62647;1799,54711
32,72;0,62785;1804,55782
32,8;0,62922;1810,13383
32,88;0,6306;1814,61312
32,96;0,63192;1819,37199
33,04;0,63311;1823,36215
33,12;0,63449;1828,32722
33,2;0,63592;1833,27198
33,28;0,63718;1838,27747
33,36;0,63855;1843,06167
33,44;0,63993;1848,46167
33,52;0,64124;1852,85024
33,6;0,64256;1857,44278
33,68;0,64375;1864,28018
33,76;0,64519;1868,16901
33,84;0,6465;1873,55485
33,92;0,64788;1877,31273
34;0,64919;1883,3641
34,08;0,65057;1888,51524
34,16;0,65194;1892,93027
34,24;0,6532;1897,48444
34,32;0,6544;1900,45424
34,4;0,65589;1905,52883
34,48;0,65721;1911,36729
34,56;0,65858;1916,329
34,64;0,6599;1920,23143
34,72;0,66121;1924,84539
34,8;0,66265;1930,07886
34,88;0,66384;1934,13943
34,96;0,66504;1936,76259
35,04;0,66653;1942,27323
35,12;0,66785;1946,74674
35,2;0,66922;1952,39075
35,28;0,67054;1956,52544
35,36;0,67191;1960,60967
35,44;0,67329;1965,82675
35,52;0,67449;1969,31753
35,6;0,67574;1972,67998
35,68;0,67724;1978,22545
35,76;0,67855;1982,49221
35,84;0,67993;1986,24339
35,92;0,68124;1990,78415
36;0,68262;1995,04849
36,08;0,68399;2000,34976
36,16;0,68507;2003,24003
36,24;0,68644;2006,46389
36,32;0,68794;2012,83153
36,4;0,68919;2016,13456
36,48;0,69057;2019,51321
36,56;0,69188;2024,53025
36,64;0,69326;2028,85978
36,72;0,69457;2034,36855
36,8;0,69571;2036,39902
36,88;0,69709;2041,08376
36,96;0,69852;2046,34853
37,04;0,6999;2050,27163
37,12;0,70127;2055,01951
37,2;0,70259;2059,46248
37,28;0,70396;2063,91457
37,36;0,70522;2067,49961
37,44;0,70635;2070,11588
37,52;0,70785;2075,19159
37,6;0,70922;2080,15069
37,68;0,71054;2084,16674
37,76;0,71191;2088,04477
37,84;0,71323;2092,76583
37,92;0,7146;2097,15292
38;0,71586;2099,43745
38,08;0,717;2102,64679
38,16;0,71855;2107,05306
38,24;0,71987;2113,08226
38,32;0,72118;2115,93695
38,4;0,72256;2121,13652
38,48;0,72393;2124,14823
38,56;0,72531;2128,59027
38,64;0,7265;2131,33674
38,72;0,7277;2134,04465
38,8;0,72919;2139,11161
38,88;0,73057;2144,25605
38,96;0,73194;2149,57148
39,04;0,7332;2153,17756
39,12;0,73457;2157,09955
39,2;0,73595;2160,8267
39,28;0,73708;2164,04665
39,36;0,7384;2166,17547
39,44;0,73984;2171,7567
39,52;0,74115;2174,55458
39,6;0,74253;2179,42037
39,68;0,74384;2183,52862
39,76;0,74522;2186,68133
39,84;0,74659;2190,09016
39,92;0,74779;2193,65265
40;0,7491;2196,44103
40,08;0,75054;2200,79608
40,16;0,75185;2204,35541
40,24;0,75323;2207,60945
40,32;0,75448;2211,1278
40,4;0,75592;2215,20439
40,48;0,75729;2218,80395
40,56;0,75843;2222,11145
40,64;0,7598;2224,41237
40,72;0,76118;2228,76482
40,8;0,7625;2232,30496
40,88;0,76387;2236,39626
40,96;0,76519;2239,68755
41,04;0,76656;2243,18411
41,12;0,76794;2247,68799
41,2;0,76907;2250,21616
41,28;0,77045;2252,82293
41,36;0,77188;2256,88163
41,44;0,77326;2260,99361
41,52;0,77457;2264,34581
41,6;0,77589;2267,83622
41,68;0,77726;2271,22009
41,76;0,77858;2275,57942
41,84;0,77971;2277,48528
41,92;0,78109;2280,92838
42;0,78252;2285,07947
42,08;0,78384;2289,43415
42,16;0,78516;2292,70495
42,24;0,78647;2295,91653
42,32;0,78791;2299,9594
42,4;0,78916;2303,37027
42,48;0,79036;2305,46426
42,56;0,79179;2308,9584
42,64;0,79323;2314,31704
42,72;0,79454;2316,93741
42,8;0,79586;2321,30028
42,88;0,79723;2324,1736
42,96;0,79861;2327,60664
43,04;0,79986;2330,6787
43,12;0,80106;2333,33893
43,2;0,80249;2337,06702
43,28;0,80393;2341,99353
43,36;0,80524;2344,9
43,44;0,80656;2347,92382
43,52;0,80788;2352,01195
43,6;0,80925;2356,54153
43,68;0,81051;2359,45322
43,76;0,8117;2361,25384
43,84;0,8132;2365,95087
43,92;0,81457;2370,15579
44;0,81589;2372,95721
44,08;0,81726;2377,13661
44,16;0,81864;2380,72257
44,24;0,82001;2383,36213
44,32;0,82121;2386,88774
44,4;0,8224;2388,15751
44,48;0,8239;2392,90446
44,56;0,82521;2396,18719
44,64;0,82653;2400,03802
44,72;0,82791;2403,86743
44,8;0,82928;2407,18238
44,88;0,83066;2410,98478
44,96;0,83179;2413,80762
45,04;0,83299;2416,40303
45,12;0,83448;2420,11119
45,2;0,83586;2424,45655
45,28;0,83717;2427,83632
45,36;0,83849;2431,12687
45,44;0,83986;2435,12914
45,52;0,84124;2438,46886
45,6;0,84243;2441,81491
45,68;0,84369;2443,83682
45,76;0,84518;2448,96095
45,84;0,8465;2453,12192
45,92;0,84787;2456,19006
46;0,84925;2460,05245
46,08;0,85057;2462,91962
46,16;0,85194;2467,63323
46,24;0,85314;2469,66761
46,32;0,85439;2472,10171
46,4;0,85589;2476,48396
46,48;0,8572;2480,56967
46,56;0,85858;2484,93273
46,64;0,85989;2488,4047
46,72;0,86127;2492,04915
46,8;0,86264;2495,79735
46,88;0,86378;2497,93287
46,96;0,86509;2500,41727
47,04;0,86659;2505,86085
47,12;0,8679;2509,56714
47,2;0,86928;2512,90575
47,28;0,87059;2516,496
47,36;0,87191;2520,11493
47,44;0,87329;2523,36506
47,52;0,87442;2525,73229
47,6;0,8758;2527,94642
47,68;0,87723;2532,78911
47,76;0,87855;2536,27319
47,84;0,87992;2539,51848
47,92;0,88124;2544,31106
48;0,88261;2546,84612
48,08;0,88393;2551,57463
48,16;0,88506;2552,59629
48,24;0,8865;2556,23814
48,32;0,88787;2560,21321
48,4;0,88919;2562,71921
48,48;0,89092;2574,22626
48,56;0,89206;2579,97643
48,64;0,8932;2580,81574
48,72;0,89433;2581,04596
48,8;0,89583;2584,52222
48,88;0,8972;2589,05571
48,96;0,89852;2591,37694
49,04;0,89989;2593,95856
49,12;0,90121;2597,7755
49,2;0,90258;2600,41654
49,28;0,90384;2603,29321
49,36;0,90497;2604,87944
49,44;0,90647;2608,72617
49,52;0,90784;2612,74856
49,6;0,90922;2615,78746
49,68;0,91059;2619,4524
49,76;0,91191;2623,13001
49,84;0,91328;2626,42074
49,92;0,91448;2629,08377
50;0,91574;2631,6762
50,08;0,91723;2635,02374
50,16;0,91849;2638,62293
50,24;0,91992;2641,89318
50,32;0,92124;2644,40272
50,4;0,92261;2648,06878
50,48;0,92393;2651,18331
50,56;0,92506;2653,06067
50,64;0,92638;2655,17104
50,72;0,92787;2660,98846
50,8;0,92919;2663,56766
50,88;0,9305;2666,02989
50,96;0,93188;2669,73227
51,04;0,93319;2672,51041
51,12;0,93427;2676,11276
51,2;0,93577;2683,15803
51,28;0,9372;2685,0434
51,36;0,93858;2689,14681
51,44;0,93983;2691,51647
51,52;0,94121;2694,71388
51,6;0,94252;2698,12997
51,68;0,9439;2701,46839
51,76;0,94521;2704,35903
51,84;0,94635;2705,89013
51,92;0,94784;2710,12485
52;0,94922;2714,18709
52,08;0,95053;2716,24196
52,16;0,95191;2719,83463
52,24;0,95316;2723,10749
52,32;0,95454;2726,34029
52,4;0,95579;2729,68207
52,48;0,95705;2731,28878
52,56;0,95849;2734,86115
52,64;0,95986;2738,9884
52,72;0,96124;2741,99843
52,8;0,96261;2746,23986
52,88;0,96393;2748,58139
52,96;0,96512;2751,37071
53,04;0,9665;2756,68725
53,12;0,96775;2757,90822
53,2;0,96925;2761,59588
53,28;0,9705;2765,56201
53,36;0,97188;2767,89609
53,44;0,97319;2771,03335
53,52;0,97451;2773,70643
53,6;0,97594;2777,68373
53,68;0,97708;2779,54247
53,76;0,9784;2780,76772
53,84;0,97983;2785,18833
53,92;0,98121;2788,90114
54;0,98252;2792,10806
54,08;0,9839;2795,3878
54,16;0,98527;2798,89833
54,24;0,98665;2802,24495
54,32;0,98772;2803,66596
54,4;0,98904;2805,45559
54,48;0,99053;2809,45562
54,56;0,99191;2813,5052
54,64;0,99328;2816,53125
54,72;0,99454;2820,6408
54,8;0,99591;2823,44986
54,88;0,99729;2827,12318
54,96;0,99842;2828,27765
55,04;0,99974;2830,88218
55,12;1,00118;2835,34471
55,2;1,00249;2838,5574
55,28;1,00387;2841,67323
55,36;1,00518;2844,91684
55,44;1,00662;2848,80567
55,52;1,00787;2851,94702
55,6;1,00901;2852,91839
55,68;1,01044;2856,01709
55,76;1,01188;2861,09205
55,84;1,01319;2863,24825
55,92;1,01451;2866,69433
56;1,01588;2872,80027
56,08;1,01732;2875,89133
56,16;1,01851;2878,74974
56,24;1,01971;2879,64493
56,32;1,0212;2884,18066
56,4;1,02252;2887,05472
56,48;1,02384;2890,47193
56,56;1,02521;2894,33468
56,64;1,02653;2896,8256
56,72;1,0279;2900,58162
56,8;1,02916;2903,3063
56,88;1,03041;2905,1939
56,96;1,03191;2908,68804
57,04;1,03322;2913,71066
57,12;1,03454;2915,8663
57,2;1,03591;2919,11848
57,28;1,03723;2922,8257
57,36;1,03866;2925,77948
57,44;1,03986;2928,07762
57,52;1,04111;2930,58269
57,6;1,04255;2934,72391
57,68;1,04386;2938,59765
57,76;1,04518;2941,61756
57,84;1,04656;2944,40165
57,92;1,04757;2947,75292
58;1,04931;2955,17128
58,08;1,05044;2956,28067
58,16;1,05176;2957,76725
58,24;1,05319;2962,57176
58,32;1,05457;2967,08979
58,4;1,05588;2969,84967
58,48;1,05726;2974,1466
58,56;1,05857;2976,94728
58,64;1,05995;2979,81258
58,72;1,06108;2981,40869
58,8;1,0624;2983,78561
58,88;1,06389;2989,21485
58,96;1,06521;2992,14106
59,04;1,06658;2995,91627
59,12;1,0679;2999,01664
59,2;1,06928;3002,95986
59,28;1,07059;3005,82219
59,36;1,07173;3007,29256
59,44;1,0731;3010,61142
59,52;1,07454;3015,20471
59,6;1,07591;3019,23361
59,68;1,07723;3024,52631
59,76;1,07854;3027,03157
59,84;1,07992;3030,69558
59,92;1,08123;3033,85761
60;1,08237;3035,7074
60,08;1,0838;3038,35459
60,16;1,08524;3043,47854
60,24;1,08661;3046,40178
60,32;1,08793;3050,10267
60,4;1,08924;3053,73948
60,48;1,09062;3056,77261
60,56;1,09188;3059,52262
60,64;1,09307;3062,02397
60,72;1,09451;3065,87629
60,8;1,09588;3070,14808
60,88;1,0972;3074,14159
60,96;1,09857;3077,6104
61,04;1,09989;3080,62267
61,12;1,10126;3084,56514
61,2;1,10252;3088,04084
61,28;1,10371;3089,8273
61,36;1,10521;3093,81709
61,44;1,10652;3097,39113
61,52;1,1079;3101,61095
61,6;1,10921;3103,61367
61,68;1,11053;3108,7039
61,76;1,11196;3111,24995
61,84;1,11316;3115,21683
61,92;1,11436;3116,61121
62;1,11585;3121,03219
62,08;1,11717;3124,97057
62,16;1,11848;3127,83308
62,24;1,1198;3131,40005
62,32;1,12123;3137,5289
62,4;1,12261;3140,26065
62,48;1,12368;3142,6467
62,56;1,12506;3145,05324
62,64;1,12655;3150,6341
62,72;1,12787;3154,54528
62,8;1,12918;3158,15918
62,88;1,1305;3161,32233
62,96;1,13193;3165,43169
63,04;1,13325;3169,66176
63,12;1,13439;3172,11337
63,2;1,13582;3175,66358
63,28;1,1372;3180,5139
63,36;1,13851;3183,75826
63,44;1,13989;3188,17236
63,52;1,1412;3191,81196
63,6;1,14264;3196,56804
63,68;1,14389;3199,59559
63,76;1,14503;3202,12543
63,84;1,14652;3206,93888
63,92;1,1479;3212,31708
64;1,14921;3216,07664
64,08;1,15059;3220,29442
64,16;1,1519;3224,26781
64,24;1,15328;3228,20619
64,32;1,15454;3233,02746
64,4;1,15573;3234,82975
64,48;1,15723;3240,56856
64,56;1,15854;3246,14979
64,64;1,15992;3251,5984
64,72;1,16123;3256,08663
64,8;1,16255;3259,07283
64,88;1,16392;3263,32599
64,96001;1,16512;3266,79684
65,04;1,16637;3269,52748
65,12;1,16787;3275,52557
65,2;1,16918;3279,62786
65,28001;1,17056;3284,11683
65,36;1,17187;3288,71012
65,44;1,17319;3292,72188
65,52;1,17456;3297,54129
65,60001;1,17576;3301,28744
65,68;1,17708;3304,54223
65,76;1,17851;3310,12569
65,84001;1,17983;3314,29765
65,92001;1,1812;3319,15841
66;1,18258;3323,34153
66,08;1,18395;3328,40756
66,16;1,18527;3333,02915
66,24001;1,1864;3336,09916
66,32;1,18778;3339,19227
66,4;1,18921;3345,16205
66,48;1,19053;3349,71882
66,56001;1,19184;3353,63336
66,64;1,19322;3360,85483
66,72;1,19459;3365,71187
66,8;1,19591;3369,64317
66,88001;1,19705;3372,74149
66,96001;1,19848;3376,75475
67,04;1,19986;3381,55366
67,12;1,20123;3386,24045
67,20001;1,20261;3391,34708
67,28001;1,20392;3393,70035
67,36;1,2053;3398,48809
67,44;1,20655;3403,50717
67,52001;1,20775;3406,48107
67,60001;1,20918;3411,03151
67,68;1,21056;3416,55686
67,76;1,21193;3420,53957
67,84001;1,21319;3424,12628
67,92001;1,2145;3428,10377
68;1,21594;3433,49539
68,08;1,21719;3438,29356
68,16;1,21833;3441,07971
68,24001;1,21983;3446,15988
68,32;1,2212;3451,50754
68,4;1,22252;3455,94808
68,48;1,22383;3461,23949
68,56001;1,22521;3465,15998
68,64001;1,22658;3470,66522
68,72;1,22778;3474,60136
68,8;1,22903;3478,19366
68,88001;1,23059;3483,96674
68,96001;1,2319;3489,52673
69,04;1,23322;3494,58493
69,12;1,23453;3498,50208
69,20001;1,23591;3503,67986
69,28001;1,23728;3509,92791
69,36;1,23848;3513,82196
69,44;1,23973;3517,46529
69,52001;1,24123;3523,94208
69,60001;1,24261;3529,65742
69,68;1,24392;3540,38812
69,76;1,24524;3544,05753
69,84001;1,24661;3549,03899
69,92001;1,24787;3553,95973
70;1,24906;3557,44287
70,08;1,25056;3563,4473
70,16;1,25193;3569,20063
70,24001;1,25325;3573,79131
70,32;1,25462;3579,36546
70,4;1,25594;3585,5379
70,48;1,25731;3590,81365
70,56001;1,25857;3596,03576
70,64001;1,2597;3599,59565
70,72;1,2612;3605,05767
70,8;1,26251;3611,03453
70,88001;1,26383;3615,61179
70,96001;1,26521;3622,23275
71,04;1,26658;3626,78468
71,12;1,26796;3633,25663
71,20001;1,26915;3638,6244
71,28001;1,27035;3642,50019
71,36;1,27184;3648,7706
71,44;1,27322;3654,73367
71,52001;1,27453;3659,10977
71,60001;1,27591;3664,6001
71,68;1,27722;3669,9187
71,76;1,2786;3676,055
71,84001;1,27985;3681,33932
71,92001;1,28111;3685,38313
72;1,2826;3692,67389
72,08;1,28386;3699,07692
72,16;1,28523;3704,91706
72,24001;1,28655;3709,82327
72,32;1,28787;3714,78386
72,4;1,28924;3720,34423
72,48;1,29044;3725,76416
72,56001;1,29175;3730,3891
72,64001;1,29325;3736,69602
72,72;1,29456;3741,71063
72,8;1,29588;3746,62951
72,88001;1,29725;3753,20949
72,96001;1,29863;3758,1332
73,04;1,29994;3763,71592
73,12;1,30114;3767,90874
73,20001;1,30239;3772,07547
73,28001;1,30389;3778,27249
73,36;1,3052;3784,20167
73,44;1,30658;3790,07831
73,52001;1,3079;3795,41889
73,60001;1,30921;3801,09102
73,68;1,31059;3806,12537
73,76;1,31178;3810,25448
73,84001;1,3131;3815,20204
73,92001;1,31453;3822,45183
74;1,31591;3829,08396
74,08;1,31722;3835,48848
74,16;1,31854;3840,04563
74,24001;1,31991;3845,98449
74,32001;1,32123;3851,35785
74,4;1,32242;3855,3115
74,48;1,32386;3860,13351
74,56001;1,32523;3866,31675
74,64001;1,32655;3871,06799
74,72;1,32792;3877,66846
74,8;1,32918;3883,48512
74,88001;1,33062;3888,7471
74,96001;1,33187;3894,29145
75,04;1,33307;3898,60757
75,12;1,3345;3903,70004
75,20001;1,33582;3910,08705
75,28001;1,33719;3915,4131
75,36;1,33851;3919,99781
75,44;1,33982;3926,00186
75,52001;1,34126;3933,28294
75,60001;1,34251;3937,93359
75,68;1,34371;3942,65465
75,76;1,3452;3948,95039
75,84001;1,34658;3955,45997
75,92001;1,34789;3960,76143
76;1,34921;3965,7902
76,08;1,35058;3971,28314
76,16;1,35196;3977,21604
76,24001;1,35316;3982,40797
76,32001;1,35441;3986,07813
76,4;1,35585;3992,45881
76,48;1,35716;3997,89587
76,56001;1,35854;4003,38285
76,64001;1,35985;4008,50624
76,72;1,36123;4013,92579
76,8;1,3626;4019,38222
76,88001;1,36374;4024,01946
76,96001;1,36511;4028,6351
77,04;1,36661;4035,7966
77,12;1,36792;4040,6175
77,20001;1,36924;4047,24218
77,28001;1,37055;4052,48255
77,36;1,37193;4057,4152
77,44;1,37325;4062,92267
77,52001;1,37444;4067,02198
77,60001;1,376;4075,52645
77,68;1,37725;4085,21183
77,76;1,37857;4089,07272
77,84001;1,37988;4095,13116
77,92001;1,3812;4099,80416
78;1,38257;4105,75829
78,08;1,38377;4108,92591
78,16;1,38502;4112,81735
78,24001;1,38652;4119,65251
78,32001;1,38783;4125,515
78,4;1,38927;4130,48416
78,48;1,39058;4137,34838
78,56001;1,3919;4142,19424
78,64001;1,39327;4147,62124
78,72;1,39447;4152,49616
78,8;1,39573;4156,0933
78,88001;1,39722;4162,58872
78,96001;1,39848;4168,05409
79,04;1,39985;4174,89335
79,12;1,40123;4180,21418
79,20001;1,40254;4185,39196
79,28001;1,40392;4191,26451
79,36;1,40511;4195,06691
79,44;1,40637;4199,00492
79,52001;1,40786;4205,91906
79,60001;1,40918;4210,49483
79,68;1,41049;4216,02428
79,76;1,41181;4221,16108
79,84001;1,41318;4226,41933
79,92001;1,41462;4233,16844
80;1,41582;4237,68722
80,08;1,41707;4241,83793
80,16;1,41851;4247,96455
80,24001;1,41988;4253,09241
80,32001;1,4212;4259,56696
80,4;1,42251;4264,77268
80,48;1,42383;4270,92947
80,56001;1,42526;4280,70202
80,64001;1,4264;4283,27359
80,72;1,42789;4289,4356
80,8;1,42927;4295,50372
80,88001;1,43058;4300,6435
80,96001;1,4319;4305,49085
81,04;1,43315;4309,95375
81,12;1,43459;4315,95705
81,20001;1,43584;4320,72207
81,28001;1,43704;4325,63052
81,36;1,43854;4331,35144
81,44;1,43991;4338,75583
81,52001;1,44123;4343,90754
81,60001;1,44254;4348,75786
81,68;1,44392;4353,07175
81,76;1,44529;4359,45131
81,84001;1,44649;4364,84665
81,92001;1,44768;4368,62223
82,00001;1,44924;4375,71071
82,08;1,45055;4380,82851
82,16;1,45187;4386,0212
82,24001;1,45318;4391,31372
82,32001;1,45456;4396,56153
82,4;1,45599;4402,80102
82,48;1,45719;4407,24827
82,56001;1,45833;4411,5264
82,64001;1,45988;4418,5441
82,72;1,46126;4427,48629
82,8;1,46257;4433,28358
82,88001;1,46389;4438,75007
82,96001;1,46526;4443,61456
83,04;1,46658;4449,67747
83,12;1,46777;4453,78684
83,20001;1,46909;4459,55321
83,28001;1,47058;4466,76277
83,36;1,4719;4472,22702
83,44;1,47321;4477,88872
83,52001;1,47459;4482,98454
83,60001;1,47596;4490,1073
83,68;1,47728;4495,59949
83,76;1,47841;4498,61214
83,84001;1,47979;4503,8458
83,92001;1,48122;4511,33251
84,00001;1,48248;4516,10163
84,08;1,48386;4521,84007
84,16;1,48529;4528,40403
84,24001;1,48667;4533,98898
84,32001;1,48792;4539,62199
84,4;1,48906;4543,74403
84,48;1,49043;4548,15254
84,56001;1,49187;4554,53135
84,64001;1,49294;4560,9951
84,72;1,49462;4570,34707
84,8;1,49593;4574,71758
84,88001;1,49725;4580,81923
84,96001;1,4985;4584,41488
85,04;1,4997;4589,73683
85,12;1,50119;4595,28938
85,20001;1,50251;4600,91606
85,28001;1,50389;4606,13072
85,36;1,5052;4611,76038
85,44;1,50652;4618,03935
85,52001;1,50795;4623,27637
85,60001;1,50915;4628,77452
85,68;1,5104;4633,01092
85,76;1,5119;4639,13269
85,84001;1,51321;4644,74261
85,92001;1,51453;4650,47583
86,00001;1,5159;4655,60071
86,08;1,51728;4660,91707
86,16;1,51865;4666,88797
86,24001;1,51985;4672,13802
86,32001;1,52104;4674,90554
86,4;1,52254;4681,45013
86,48;1,52385;4688,08822
86,56001;1,52523;4693,55695
86,64001;1,52655;4698,45012
86,72;1,52786;4703,18086
86,8;1,52924;4709,25756
86,88001;1,53049;4714,38058
86,96001;1,53175;4719,30951
87,04;1,5333;4726,87073
87,12;1,53462;4733,54198
87,20001;1,53593;4738,22951
87,28001;1,53725;4743,58015
87,36;1,53856;4749,06303
87,44;1,53994;4754,31196
87,52001;1,54107;4758,70185
87,60001;1,54245;4763,07645
87,68001;1,54388;4769,14681
87,76;1,5452;4775,01154
87,84001;1,54657;4780,61624
87,92001;1,54783;4785,49972
88,00001;1,54921;4790,62051
88,08;1,55052;4796,14772
88,16;1,55172;4800,55138
88,24001;1,55309;4805,3015
88,32001;1,55453;4811,66542
88,4;1,55584;4817,47314
88,48;1,55722;4823,15943
88,56001;1,55859;4828,28766
88,64001;1,55997;4833,77948
88,72;1,56122;4838,87829
88,8;1,56236;4842,50337
88,88001;1,56379;4847,65619
88,96001;1,56523;4853,36781
89,04;1,56654;4858,82461
89,12;1,56786;4863,83885
89,20001;1,56923;4869,05128
89,28001;1,57061;4874,55241
89,36;1,57181;4879,27198
89,44;1,573;4882,83299
89,52001;1,5745;4888,13706
89,60001;1,57581;4894,19065
89,68001;1,57713;4898,79996
89,76;1,5785;4903,7084
89,84001;1,57988;4908,55388
89,92001;1,58131;4914,33181
90,00001;1,58245;4918,46502
90,08;1,5837;4922,06253
90,16;1,58526;4928,47823
90,24001;1,58657;4933,21605
90,32001;1,58789;4937,85813
90,4;1,58926;4942,99307
90,48;1,59058;4948,04829
90,56001;1,59196;4952,70565
90,64001;1,59309;4957,73442
90,72;1,59441;4962,20589
90,8;1,5959;4967,83517
90,88001;1,59716;4973,54455
90,96001;1,59853;4978,58897
91,04;1,59985;4985,05011
91,12;1,60122;4989,41354
91,20001;1,60254;4995,26039
91,28001;1,60373;4997,92136
91,36;1,60511;5003,19079
91,44;1,60648;5009,16876
91,52001;1,60786;5013,71995
91,60001;1,60923;5018,58927
91,68001;1,61049;5023,09985
91,76;1,61192;5028,20797
91,82401;1,61294;5032,3911