File: SU - Suspension/test en traction/Courbes/triangles/Specimen_RawData_5.csv
Temps;Déplacement;Charge
(sec);(mm);(N)
0,00000;0,00012;25,70541
0,08000;0,00036;25,14469
0,16000;0,00155;28,73023
0,24000;0,00329;35,45957
0,32000;0,00496;38,60762
0,40000;0,00664;38,27768
0,48000;0,00795;39,45315
0,56000;0,00927;39,79230
0,64000;0,01076;43,12235
0,72000;0,01220;43,94410
0,80000;0,01351;44,78371
0,88000;0,01483;45,49008
0,96000;0,01620;46,52269
1,04000;0,01752;47,06519
1,12000;0,01871;47,85024
1,20000;0,02009;48,66677
1,28000;0,02146;50,50600
1,36000;0,02278;51,49178
1,44000;0,02410;52,64503
1,52000;0,02541;53,45566
1,60000;0,02679;54,61826
1,68000;0,02816;56,05227
1,76000;0,02930;56,55430
1,84000;0,03073;57,59830
1,92000;0,03217;59,02002
2,00000;0,03354;60,63159
2,08000;0,03486;60,64203
2,16000;0,03617;62,46183
2,24000;0,03761;62,68623
2,32000;0,03886;63,97454
2,40000;0,04000;64,92272
2,48000;0,04143;66,69720
2,56000;0,04281;68,43322
2,64000;0,04412;69,23173
2,72000;0,04550;70,57350
2,80000;0,04687;71,33375
2,88000;0,04825;73,06766
2,96000;0,04945;74,54425
3,04000;0,05064;73,96718
3,12000;0,05220;76,59334
3,20000;0,05351;78,16331
3,28000;0,05483;78,47447
3,36000;0,05620;80,27642
3,44000;0,05752;80,83135
3,52000;0,05889;82,06686
3,60000;0,06015;83,22013
3,68000;0,06140;83,82530
3,76000;0,06290;85,82484
3,84000;0,06415;86,03454
3,92000;0,06547;87,11612
4,00000;0,06684;89,31716
4,08000;0,06816;89,72856
4,16000;0,06954;91,61198
4,24000;0,07073;91,63641
4,32000;0,07211;93,22349
4,40000;0,07348;94,59371
4,48000;0,07480;94,80974
4,56000;0,07617;96,50824
4,64000;0,07749;97,50082
4,72000;0,07886;99,23376
4,80000;0,08018;99,79592
4,88000;0,08137;100,29597
4,96000;0,08281;101,90400
5,04000;0,08418;102,76480
5,12000;0,08556;103,85176
5,20000;0,08687;104,64943
5,28000;0,08819;105,14755
5,36000;0,08956;106,64002
5,44000;0,09082;107,85621
5,52000;0,09202;107,67635
5,60000;0,09351;108,83110
5,68000;0,09489;109,85659
5,76000;0,09620;110,60714
5,84000;0,09746;111,70898
5,92000;0,09877;112,47660
6,00000;0,10021;113,41869
6,08000;0,10146;114,72094
6,16000;0,10272;115,26410
6,24000;0,10415;116,68571
6,32000;0,10547;117,71487
6,40000;0,10690;119,98006
6,48000;0,10822;120,39478
6,56000;0,10953;121,60465
6,64000;0,11097;122,92073
6,72000;0,11205;123,06229
6,80000;0,11336;123,59368
6,88000;0,11486;126,04740
6,96000;0,11617;126,78108
7,04000;0,11755;128,64711
7,12000;0,11880;129,52372
7,20000;0,12018;130,73208
7,28000;0,12155;132,83569
7,36000;0,12269;133,96987
7,44000;0,12400;134,93065
7,52000;0,12550;136,67424
7,60000;0,12681;138,26402
7,68000;0,12813;139,40975
7,76000;0,12950;140,50802
7,84000;0,13088;141,99601
7,92000;0,13225;143,24522
8,00000;0,13339;143,89110
8,08000;0,13477;144,82178
8,16000;0,13626;146,96204
8,24000;0,13752;148,51593
8,32000;0,13883;149,90558
8,40000;0,14015;150,73828
8,48000;0,14152;152,34780
8,56000;0,14290;154,17458
8,64000;0,14403;155,09285
8,72000;0,14541;156,01236
8,80000;0,14684;157,85773
8,88000;0,14816;159,27067
8,96000;0,14953;160,38623
9,04000;0,15085;161,77472
9,12000;0,15222;162,93955
9,20000;0,15354;165,01922
9,28000;0,15474;166,06750
9,36000;0,15617;166,80538
9,44000;0,15761;168,73009
9,52000;0,15886;169,50867
9,60000;0,16024;170,60249
9,68000;0,16155;172,01671
9,76000;0,16293;173,57301
9,84000;0,16418;174,97287
9,92000;0,16538;175,09414
10,00000;0,16687;178,01234
10,08000;0,16819;179,53047
10,16000;0,16950;180,22305
10,24000;0,17088;181,73733
10,32000;0,17219;183,35271
10,40000;0,17357;184,76553
10,48000;0,17476;186,00764
10,56000;0,17608;186,73072
10,64000;0,17757;188,43018
10,72000;0,17883;190,14933
10,80000;0,18021;191,70579
10,88000;0,18158;193,13295
10,96000;0,18290;194,63626
11,04000;0,18421;196,36438
11,12000;0,18541;197,51308
11,20000;0,18672;198,34435
11,28000;0,18822;200,28667
11,36000;0,18947;201,78792
11,44000;0,19085;203,45272
11,52000;0,19216;205,04259
11,60000;0,19354;206,84123
11,68000;0,19491;208,22329
11,76000;0,19611;209,52183
11,84000;0,19742;210,78782
11,92000;0,19886;212,68546
12,00000;0,20018;214,42957
12,08000;0,20155;215,97999
12,16000;0,20293;217,29483
12,24000;0,20430;218,74977
12,32000;0,20562;220,89693
12,40000;0,20669;221,97571
12,48000;0,20807;222,60582
12,56000;0,20950;225,06565
12,64000;0,21082;226,33513
12,72000;0,21219;228,01580
12,80000;0,21351;229,31700
12,88000;0,21488;230,53703
12,96000;0,21620;232,50815
13,04000;0,21739;233,23535
13,12000;0,21877;235,15115
13,20000;0,22020;236,76874
13,28000;0,22152;238,55772
13,36000;0,22290;239,75417
13,44000;0,22421;241,59423
13,52000;0,22559;243,56819
13,60000;0,22690;244,18773
13,68000;0,22810;245,45616
13,76000;0,22947;247,16149
13,84000;0,23085;249,46681
13,92000;0,23216;250,31574
14,00000;0,23354;252,51065
14,08000;0,23485;254,01518
14,16000;0,23623;255,73187
14,24000;0,23748;257,51053
14,32000;0,23868;258,95990
14,40000;0,24011;260,96813
14,48000;0,24149;262,66661
14,56000;0,24286;265,67290
14,64000;0,24424;270,66900
14,72000;0,24556;274,06809
14,80000;0,24693;278,02903
14,88000;0,24813;282,12792
14,96000;0,24932;286,14879
15,04000;0,25088;291,49819
15,12000;0,25219;296,65185
15,20000;0,25357;301,20967
15,28000;0,25488;305,65348
15,36000;0,25620;310,03794
15,44000;0,25757;314,75932
15,52000;0,25877;318,76131
15,60000;0,25996;322,14993
15,68000;0,26146;327,24822
15,76000;0,26277;331,18846
15,84000;0,26415;336,62349
15,92000;0,26553;340,46392
16,00000;0,26690;345,23888
16,08000;0,26828;350,52160
16,16000;0,26941;354,28749
16,24000;0,27073;357,47178
16,32000;0,27222;362,71906
16,40000;0,27354;368,09354
16,48000;0,27491;372,29729
16,56000;0,27623;377,69873
16,64000;0,27754;381,74111
16,72000;0,27892;386,66481
16,80000;0,28005;389,60020
16,88000;0,28143;394,06056
16,96000;0,28286;399,60719
17,04000;0,28412;403,42407
17,12000;0,28549;408,23799
17,20000;0,28681;412,85879
17,28000;0,28819;418,01338
17,36000;0,28956;423,87629
17,44000;0,29070;426,66122
17,52000;0,29225;434,69504
17,60000;0,29357;440,48969
17,68000;0,29488;444,51957
17,76000;0,29620;448,93487
17,84000;0,29757;453,42078
17,92000;0,29895;458,85942
18,00000;0,30008;463,50453
18,08000;0,30134;466,45086
18,16000;0,30283;472,41524
18,24000;0,30415;476,89267
18,32000;0,30552;480,81027
18,40000;0,30684;486,34759
18,48000;0,30816;490,64979
18,56000;0,30953;495,95423
18,64000;0,31073;499,76436
18,72000;0,31198;503,65687
18,80000;0,31354;509,43717
18,88000;0,31479;514,20932
18,96000;0,31617;517,92571
19,04000;0,31748;523,14121
19,12000;0,31880;526,33071
19,20000;0,32023;532,33984
19,28000;0,32143;535,55872
19,36000;0,32268;539,13025
19,44000;0,32418;543,75334
19,52000;0,32549;548,24897
19,60000;0,32687;552,77366
19,68000;0,32818;557,33495
19,76000;0,32956;561,49191
19,84000;0,33093;565,96505
19,92000;0,33207;569,46655
20,00000;0,33333;573,03221
20,08000;0,33488;577,66358
20,16000;0,33620;582,14874
20,24000;0,33757;585,71752
20,32000;0,33883;590,00081
20,40000;0,34026;593,99363
20,48000;0,34158;598,50267
20,56000;0,34271;601,16113
20,64000;0,34409;603,92898
20,72000;0,34552;608,84976
20,80000;0,34684;613,48462
20,88000;0,34821;617,61499
20,96000;0,34953;620,90009
21,04000;0,35090;626,01366
21,12000;0,35222;630,31674
21,20000;0,35336;632,99336
21,28000;0,35473;636,23446
21,36000;0,35623;642,05118
21,44000;0,35748;645,03709
21,52000;0,35880;649,07479
21,60000;0,36011;652,51179
21,68000;0,36155;657,71709
21,76000;0,36292;662,80970
21,84000;0,36406;665,16744
21,92000;0,36543;669,15755
22,00000;0,36687;674,16783
22,08000;0,36818;678,21457
22,16000;0,36950;682,57316
22,24000;0,37087;685,61942
22,32000;0,37219;690,42211
22,40000;0,37350;695,24995
22,48000;0,37470;697,55344
22,56000;0,37614;702,13918
22,64000;0,37757;706,60338
22,72000;0,37883;710,55503
22,80000;0,38020;714,00972
22,88000;0,38152;718,61711
22,96000;0,38295;723,56160
23,04000;0,38421;726,98058
23,12000;0,38540;730,10623
23,20000;0,38684;734,12312
23,28000;0,38821;738,84754
23,36000;0,38953;742,52295
23,44000;0,39084;746,94748
23,52000;0,39222;750,50746
23,60000;0,39359;755,17735
23,68000;0,39485;759,39437
23,76000;0,39605;761,34284
23,84000;0,39748;766,44458
23,92000;0,39886;770,83521
24,00000;0,40017;773,68096
24,08000;0,40155;778,28835
24,16000;0,40286;782,16540
24,24000;0,40424;786,14559
24,32000;0,40549;790,86367
24,40000;0,40669;794,03976
24,48000;0,40818;797,88882
24,56000;0,40950;802,68662
24,64000;0,41081;805,93284
24,72000;0,41219;809,94787
24,80000;0,41213;813,90776
24,88000;0,41500;828,06256
24,96000;0,41613;828,58037
25,04000;0,41751;830,99557
25,12000;0,41883;834,05748
25,20000;0,42014;837,84191
25,28000;0,42152;842,01097
25,36000;0,42283;845,94265
25,44000;0,42427;850,66827
25,52000;0,42552;854,00855
25,60000;0,42666;857,23894
25,68000;0,42815;860,91217
25,76000;0,42947;865,30177
25,84000;0,43084;869,27647
25,92000;0,43222;873,33648
26,00000;0,43353;877,41418
26,08000;0,43491;881,69063
26,16000;0,43616;885,49461
26,24000;0,43736;888,35508
26,32000;0,43885;893,51572
26,40000;0,44017;897,79058
26,48000;0,44155;900,58707
26,56000;0,44286;904,83697
26,64000;0,44418;908,77162
26,72000;0,44561;913,88831
26,80000;0,44681;919,41124
26,88000;0,44806;921,29558
26,96000;0,44956;925,44826
27,04000;0,45081;929,48871
27,12000;0,45219;932,90042
27,20000;0,45350;937,59056
27,28000;0,45482;940,27705
27,36000;0,45619;945,13521
27,44000;0,45739;948,27209
27,52000;0,45870;951,48711
27,60000;0,46020;955,85426
27,68000;0,46152;961,04378
27,76000;0,46283;964,55077
27,84000;0,46415;968,16858
27,92000;0,46552;969,22303
28,00000;0,46690;973,38622
28,08000;0,46809;977,07519
28,16000;0,46911;980,19885
28,24000;0,47090;989,25671
28,32000;0,47222;992,36323
28,40000;0,47353;995,93364
28,48000;0,47485;1000,09441
28,56000;0,47622;1003,96043
28,64000;0,47754;1009,85011
28,72000;0,47867;1011,31499
28,80000;0,48011;1016,47917
28,88000;0,48148;1021,67642
28,96000;0,48280;1024,84478
29,04000;0,48424;1030,73409
29,12000;0,48555;1034,26538
29,20000;0,48699;1038,53783
29,28000;0,48818;1042,71518
29,36000;0,48932;1046,41719
29,44000;0,49087;1051,84084
29,52000;0,49219;1057,30323
29,60000;0,49350;1060,96566
29,68000;0,49488;1065,34483
29,76000;0,49619;1069,39739
29,84000;0,49757;1073,28361
29,92000;0,49876;1077,64835
30,00000;0,50002;1080,99841
30,08000;0,50151;1086,98606
30,16000;0,50277;1091,39802
30,24000;0,50414;1095,19968
30,32000;0,50552;1100,53625
30,40000;0,50690;1104,78792
30,48000;0,50821;1109,65241
30,56000;0,50941;1113,33812
30,64000;0,51078;1117,29261
30,72000;0,51216;1123,08580
30,80000;0,51347;1127,10586
30,88000;0,51485;1130,71455
30,96000;0,51616;1135,57335
31,04000;0,51754;1140,54028
31,12000;0,51885;1144,66138
31,20000;0,52005;1147,87426
31,28000;0,52148;1152,76230
31,36000;0,52286;1157,92304
31,44000;0,52417;1162,05458
31,52000;0,52549;1166,52055
31,60000;0,52681;1170,51862
31,68000;0,52818;1174,97742
31,76000;0,52956;1179,84731
31,84000;0,53069;1183,73968
31,92000;0,53213;1188,37673
32,00000;0,53350;1193,18459
32,08000;0,53482;1198,10794
32,16000;0,53619;1203,48176
32,24000;0,53751;1208,33525
32,32000;0,53894;1213,90149
32,40000;0,54020;1217,44303
32,48000;0,54139;1221,18304
32,56000;0,54283;1226,23900
32,64000;0,54420;1231,66023
32,72000;0,54552;1235,36009
32,80000;0,54683;1240,72535
32,88000;0,54815;1244,77996
32,96000;0,54958;1250,90741
33,04000;0,55078;1254,66222
33,12000;0,55198;1257,94690
33,20000;0,55347;1263,97125
33,28000;0,55485;1269,39043
33,36000;0,55622;1273,13230
33,44000;0,55754;1277,16269
33,52000;0,55885;1282,41768
33,60000;0,56029;1287,75518
33,68000;0,56142;1291,96001
33,76000;0,56268;1295,38188
33,84000;0,56423;1301,08679
33,92000;0,56555;1305,75504
34,00000;0,56686;1310,35503
34,08000;0,56818;1315,21914
34,16000;0,56955;1319,62309
34,24000;0,57093;1324,43411
34,32000;0,57207;1328,89450
34,40000;0,57332;1333,14570
34,48000;0,57494;1338,52111
34,56000;0,57619;1344,64102
34,64000;0,57751;1348,36249
34,72000;0,57882;1353,11494
34,80000;0,58026;1357,78002
34,88000;0,58157;1362,80749
34,96000;0,58271;1365,13282
35,04000;0,58408;1369,63204
35,12000;0,58558;1374,94337
35,20000;0,58683;1379,79733
35,28000;0,58821;1383,99499
35,36000;0,58952;1388,24191
35,44000;0,59090;1393,60949
35,52000;0,59221;1397,56054
35,60000;0,59335;1401,19614
35,68000;0,59479;1404,76944
35,76000;0,59622;1411,17936
35,84000;0,59748;1415,27345
35,92000;0,59885;1419,62273
36,00000;0,60023;1423,62649
36,08000;0,60160;1429,16581
36,16000;0,60286;1433,00481
36,24000;0,60399;1436,54123
36,32000;0,60549;1441,15556
36,40000;0,60686;1446,28426
36,48000;0,60818;1449,89928
36,56000;0,60949;1454,86947
36,64000;0,61087;1458,86391
36,72000;0,61230;1463,51494
36,80000;0,61356;1467,26165
36,88000;0,61470;1470,50340
36,96000;0,61613;1474,96583
37,04000;0,61751;1480,66534
37,12000;0,61882;1484,26974
37,20000;0,62020;1488,54349
37,28000;0,62151;1493,03200
37,36000;0,62289;1497,51240
37,44000;0,62414;1500,91117
37,52000;0,62540;1504,64699
37,60000;0,62683;1509,39301
37,68000;0,62815;1513,66936
37,76000;0,62952;1517,96881
37,84000;0,63084;1523,01621
37,92000;0,63233;1527,61238
38,00000;0,63359;1533,39375
38,08000;0,63479;1536,01132
38,16000;0,63604;1539,57307
38,24000;0,63754;1544,19607
38,32000;0,63879;1548,66744
38,40000;0,64017;1552,12972
38,48000;0,64148;1556,74247
38,56000;0,64286;1560,05826
38,64000;0,64423;1564,06164
38,72000;0,64537;1567,28644
38,80000;0,64668;1570,34975
38,88000;0,64818;1575,24813
38,96000;0,64949;1579,40611
39,04000;0,65087;1583,19920
39,12000;0,65218;1586,71774
39,20000;0,65350;1590,32345
39,28000;0,65487;1594,93685
39,36000;0,65607;1598,07820
39,44000;0,65745;1600,66951
39,52000;0,65888;1606,32469
39,60000;0,66020;1609,41519
39,68000;0,66157;1613,34220
39,76000;0,66283;1617,26531
39,84000;0,66420;1620,32600
39,92000;0,66558;1624,30517
40,00000;0,66677;1627,65775
40,08000;0,66803;1630,77060
40,16000;0,66952;1637,31910
40,24000;0,67084;1639,85454
40,32000;0,67221;1643,92479
40,40000;0,67353;1647,27177
40,48000;0,67490;1651,55232
40,56000;0,67616;1655,17740
40,64000;0,67736;1656,84503
40,72000;0,67879;1661,49754
40,80000;0,68022;1665,91071
40,88000;0,68154;1668,92875
40,96000;0,68286;1672,43592
41,04000;0,68423;1675,95465
41,12000;0,68561;1680,29275
41,20000;0,68686;1683,03642
41,28000;0,68800;1684,83574
41,36000;0,68949;1688,65286
41,44000;0,69087;1693,56260
41,52000;0,69218;1696,47671
41,60000;0,69350;1699,86114
41,68000;0,69487;1703,41432
41,76000;0,69625;1707,40262
41,84000;0,69750;1710,11873
41,92000;0,69864;1712,72885
42,00000;0,70013;1716,94141
42,08000;0,70151;1721,14465
42,16000;0,70289;1724,84852
42,24000;0,70420;1728,30243
42,32000;0,70558;1731,65854
42,40000;0,70695;1735,27189
42,48000;0,70809;1738,23647
42,56000;0,70934;1740,22801
42,64000;0,71090;1744,49757
42,72000;0,71215;1748,22770
42,80000;0,71353;1751,32081
42,88000;0,71484;1754,79781
42,96000;0,71622;1758,18093
43,04000;0,71753;1762,09472
43,12000;0,71873;1764,17977
43,20000;0,72004;1767,75474
43,28000;0,72154;1772,31338
43,36000;0,72285;1775,18036
43,44000;0,72417;1778,54877
43,52000;0,72555;1782,31522
43,60000;0,72686;1784,91771
43,68000;0,72824;1789,11313
43,76000;0,72937;1791,34291
43,84000;0,73081;1794,13892
43,92000;0,73224;1798,76741
44,00000;0,73356;1801,46396
44,08000;0,73493;1805,30790
44,16000;0,73619;1807,41847
44,24000;0,73756;1811,03908
44,32000;0,73900;1815,47105
44,40000;0,74013;1820,55421
44,48000;0,74151;1823,15856
44,56000;0,74276;1826,75365
44,64000;0,74414;1829,44275
44,72000;0,74546;1833,09279
44,80000;0,74683;1836,22576
44,88000;0,74821;1839,06741
44,96000;0,74940;1842,00834
45,04000;0,75072;1844,47002
45,12000;0,75221;1848,70921
45,20000;0,75353;1852,25792
45,28000;0,75490;1855,34339
45,36000;0,75622;1857,67040
45,44000;0,75759;1861,04793
45,52000;0,75897;1864,96153
45,60000;0,76004;1867,40495
45,68000;0,76142;1869,22140
45,76000;0,76285;1873,69380
45,84000;0,76417;1876,69490
45,92000;0,76554;1879,59354
46,00000;0,76686;1882,46295
46,08000;0,76824;1886,04221
46,16000;0,76955;1890,65002
46,24000;0,77069;1892,23457
46,32000;0,77206;1894,52693
46,40000;0,77356;1898,81213
46,48000;0,77487;1902,38170
46,56000;0,77625;1905,03486
46,64000;0,77750;1907,73867
46,72000;0,77894;1910,97017
46,80000;0,78025;1914,18063
46,88000;0,78139;1916,66707
46,96000;0,78276;1919,24553
47,04000;0,78420;1923,31970
47,12000;0,78551;1926,32917
47,20000;0,78683;1929,07434
47,28000;0,78815;1932,35483
47,36000;0,78958;1935,91155
47,44000;0,79084;1938,73588
47,52000;0,79197;1940,80677
47,60000;0,79347;1943,26006
47,68000;0,79490;1948,34545
47,76000;0,79616;1950,84456
47,84000;0,79747;1953,30977
47,92000;0,79885;1957,25560
48,00000;0,80028;1960,12668
48,08000;0,80154;1964,62609
48,16000;0,80273;1966,68413
48,24000;0,80423;1971,65087
48,32000;0,80554;1974,30756
48,40000;0,80686;1976,90483
48,48000;0,80817;1980,32819
48,56000;0,80949;1982,87778
48,64000;0,81087;1985,64325
48,72000;0,81206;1987,47776
48,80000;0,81338;1989,89287
48,88000;0,81493;1994,68788
48,96000;0,81619;1998,09335
49,04000;0,81750;2000,52224
49,12000;0,81888;2004,40511
49,20000;0,82031;2007,26483
49,28000;0,82163;2010,41028
49,36000;0,82276;2011,94361
49,44000;0,82408;2014,44943
49,52000;0,82557;2019,14664
49,60000;0,82683;2020,62875
49,68000;0,82820;2024,64536
49,76000;0,82958;2028,02978
49,84000;0,83089;2030,20182
49,92000;0,83221;2033,52422
50,00000;0,83335;2035,55208
50,08000;0,83466;2038,58539
50,16000;0,83616;2043,09709
50,24000;0,83747;2045,64054
50,32000;0,83885;2049,28555
50,40000;0,84016;2052,73684
50,48000;0,84154;2056,19298
50,56000;0,84285;2058,92511
50,64000;0,84405;2061,39814
50,72000;0,84542;2063,39899
50,80000;0,84686;2068,60751
50,88000;0,84817;2070,28463
50,96000;0,84955;2074,14329
51,04000;0,85086;2078,14295
51,12000;0,85224;2080,80728
51,20000;0,85355;2084,62439
51,28000;0,85469;2086,90986
51,36000;0,85613;2089,44436
51,44000;0,85750;2093,45203
51,52000;0,85882;2096,12902
51,60000;0,86013;2098,38450
51,68000;0,86151;2101,94010
51,76000;0,86288;2104,70390
51,84000;0,86420;2108,71398
51,92000;0,86539;2110,54068
52,00000;0,86683;2113,32049
52,08000;0,86820;2117,20373
52,16000;0,86958;2120,76418
52,24000;0,87089;2124,21585
52,32000;0,87221;2126,95785
52,40000;0,87329;2131,62154
52,48000;0,87484;2138,63719
52,56000;0,87610;2140,18375
52,64000;0,87753;2145,91362
52,72000;0,87885;2150,99081
52,80000;0,88016;2155,51872
52,88000;0,88154;2160,37426
52,96000;0,88285;2164,79767
53,04000;0,88423;2170,05387
53,12000;0,88542;2175,77964
53,20000;0,88674;2179,81394
53,28000;0,88817;2185,88822
53,36000;0,88949;2191,64100
53,44000;0,89086;2197,19168
53,52000;0,89224;2201,92727
53,60000;0,89355;2207,21103
53,68000;0,89493;2212,62630
53,76000;0,89612;2218,96339
53,84000;0,89738;2222,40537
53,92000;0,89888;2229,59295
54,00000;0,90019;2234,64593
54,08000;0,90157;2244,51274
54,16000;0,90288;2248,43379
54,24000;0,90426;2254,06252
54,32000;0,90551;2259,32393
54,40000;0,90665;2262,51781
54,48000;0,90808;2268,16181
54,56000;0,90952;2274,66244
54,64000;0,91083;2280,22654
54,72000;0,91221;2285,62504
54,80000;0,91352;2291,88837
54,88000;0,91496;2296,82568
54,96000;0,91621;2302,48943
55,04000;0,91735;2306,22757
55,12000;0,91884;2309,43356
55,20000;0,92016;2296,07392
55,28000;0,92148;2303,18271
55,36000;0,92285;2310,46714
55,44000;0,92423;2316,57885
55,52000;0,92560;2322,68423
55,60000;0,92680;2327,96669
55,68000;0,92799;2333,41623
55,76000;0,92955;2339,56501
55,84000;0,93086;2345,62326
55,92000;0,93218;2350,49613
56,00000;0,93313;2355,93151
56,08000;0,93493;2365,26821
56,16000;0,93624;2370,54359
56,24000;0,93738;2374,25528
56,32000;0,93875;2378,60270
56,40000;0,94019;2386,65212
56,48000;0,94145;2390,92559
56,56000;0,94282;2397,63316
56,64000;0,94420;2402,66547
56,72000;0,94557;2408,38267
56,80000;0,94689;2413,75323
56,88000;0,94796;2417,74134
56,96000;0,94940;2422,98078
57,04000;0,95083;2429,37170
57,12000;0,95215;2435,21146
57,20000;0,95352;2416,20541
57,28000;0,95484;2420,96744
57,36000;0,95621;2427,04265
57,44000;0,95753;2434,02645
57,52000;0,95866;2437,20207
57,60000;0,96016;2444,21177
57,68000;0,96153;2450,94001
57,76000;0,96285;2456,63431
57,84000;0,96423;2463,39887
57,92000;0,96554;2467,83737
58,00000;0,96692;2473,86415
58,08000;0,96817;2479,57949
58,16000;0,96925;2483,05071
58,24000;0,97086;2491,15545
58,32000;0,97218;2496,67652
58,40000;0,97349;2502,38851
58,48000;0,97481;2507,70748
58,56000;0,97618;2513,12070
58,64000;0,97762;2519,73420
58,72000;0,97881;2524,61955
58,80000;0,98001;2528,40258
58,88000;0,98150;2534,06875
58,96000;0,98282;2539,97948
59,04000;0,98419;2545,84309
59,12000;0,98551;2552,01776
59,20000;0,98689;2557,02659
59,28000;0,98826;2562,97179
59,36000;0,98946;2567,13927
59,44000;0,99065;2571,55914
59,52000;0,99221;2579,39007
59,60000;0,99352;2586,29695
59,68000;0,99490;2591,40842
59,76000;0,99615;2597,09246
59,84000;0,99753;2602,46452
59,92000;0,99890;2607,82018
60,00000;1,00004;2611,75632
60,08000;1,00141;2617,16060
60,16000;1,00285;2623,60815
60,24000;1,00410;2628,14108
60,32000;1,00548;2633,54797
60,40000;1,00680;2637,89129
60,48000;1,00823;2644,46512
60,56000;1,00955;2650,75117
60,64000;1,01068;2654,25462
60,72000;1,01206;2659,62109
60,80000;1,01355;2666,42664
60,88000;1,01481;2671,81005
60,96000;1,01612;2677,29107
61,04000;1,01750;2682,92036
61,12000;1,01887;2689,31314
61,20000;1,02019;2694,95603
61,28000;1,02132;2699,42172
61,36000;1,02282;2703,77640
61,44000;1,02425;2711,21524
61,52000;1,02551;2715,72024
61,60000;1,02688;2722,29444
61,68000;1,02814;2727,37704
61,76000;1,02952;2732,97001
61,84000;1,03083;2739,01131
61,92000;1,03203;2742,57828
62,00000;1,03352;2749,59970
62,08000;1,03490;2755,62201
62,16000;1,03615;2760,35909
62,24000;1,03753;2766,60379
62,32000;1,03884;2772,18316
62,40000;1,04034;2782,08479
62,48000;1,04147;2786,36534
62,56000;1,04273;2789,87437
62,64000;1,04422;2796,69296
62,72000;1,04548;2802,23023
62,80000;1,04679;2807,09080
62,88000;1,04817;2812,59976
62,96000;1,04954;2818,36018
63,04000;1,05092;2823,53014
63,12000;1,05206;2828,41977
63,20000;1,05337;2832,89049
63,28000;1,05487;2840,39825
63,36000;1,05618;2846,39094
63,44000;1,05756;2850,37942
63,52000;1,05887;2856,03497
63,60000;1,06025;2862,07628
63,68000;1,06156;2867,43697
63,76000;1,06276;2871,48990
63,84000;1,06407;2876,37506
63,92000;1,06551;2882,40612
64,00000;1,06682;2888,12853
64,08000;1,06820;2893,85971
64,16000;1,06951;2899,38543
64,24000;1,07089;2904,69248
64,32000;1,07220;2910,42384
64,40000;1,07340;2915,20357
64,48000;1,07472;2920,31206
64,56000;1,07615;2926,72459
64,64000;1,07747;2932,10354
64,72000;1,07884;2937,60840
64,80000;1,08022;2943,61115
64,88000;1,08159;2949,79829
64,96001;1,08291;2954,18613
65,04000;1,08404;2958,92805
65,12000;1,08542;2964,16134
65,20000;1,08685;2969,88394
65,28001;1,08817;2975,71979
65,36000;1,08954;2981,88850
65,44000;1,09086;2987,33748
65,52000;1,09223;2993,13813
65,60001;1,09355;2999,23811
65,68000;1,09475;3003,06678
65,76000;1,09612;3008,95106
65,84001;1,09750;3015,07283
65,92001;1,09881;3019,75291
66,00000;1,10013;3025,65787
66,08000;1,10156;3032,09759
66,16000;1,10294;3038,99366
66,24001;1,10419;3044,30667
66,32000;1,10539;3048,61907
66,40000;1,10688;3054,62424
66,48000;1,10820;3059,91042
66,56001;1,10951;3064,97645
66,64000;1,11083;3070,90227
66,72000;1,11220;3075,72447
66,80000;1,11358;3081,91422
66,88001;1,11478;3087,13485
66,96001;1,11603;3091,19113
67,04000;1,11753;3098,27607
67,12000;1,11884;3103,61274
67,20001;1,12016;3109,24035
67,28001;1,12147;3113,88951
67,36000;1,12279;3120,18022
67,44000;1,12416;3125,97379
67,52001;1,12536;3130,68926
67,60001;1,12667;3136,03207
67,68000;1,12817;3143,60224
67,76000;1,12948;3148,96367
67,84001;1,13086;3154,29829
67,92001;1,13217;3160,11310
68,00000;1,13355;3164,72650
68,08000;1,13486;3170,79127
68,16000;1,13600;3175,62222
68,24001;1,13744;3179,84745
68,32000;1,13887;3187,89519
68,40000;1,14013;3192,12601
68,48000;1,14150;3198,26119
68,56001;1,14288;3203,56525
68,64001;1,14425;3209,97648
68,72000;1,14551;3214,59174
68,80000;1,14664;3219,18279
68,88001;1,14814;3225,38577
68,96001;1,14951;3231,37529
69,04000;1,15089;3237,33017
69,12000;1,15220;3243,22507
69,20001;1,15358;3249,42805
69,28001;1,15489;3254,30371
69,36000;1,15609;3259,90506
69,44000;1,15735;3263,93470
69,52001;1,15890;3270,85331
69,60001;1,16016;3276,76125
69,68000;1,16147;3281,42382
69,76000;1,16285;3287,19802
69,84001;1,16422;3291,74474
69,92001;1,16560;3297,96672
70,00000;1,16679;3303,85715
70,08000;1,16805;3307,36637
70,16000;1,16948;3314,66049
70,24001;1,17080;3320,54161
70,32000;1,17217;3326,93420
70,40000;1,17349;3331,89145
70,48000;1,17480;3337,59598
70,56001;1,17618;3343,17796
70,64001;1,17737;3348,52189
70,72000;1,17869;3353,09058
70,80000;1,18018;3360,12468
70,88001;1,18144;3365,23615
70,96001;1,18270;3371,91746
71,04000;1,18419;3378,29217
71,12000;1,18557;3383,22297
71,20001;1,18688;3388,50580
71,28001;1,18802;3393,54537
71,36000;1,18945;3398,06266
71,44000;1,19083;3404,92241
71,52001;1,19214;3409,79695
71,60001;1,19346;3415,79914
71,68000;1,19477;3420,08844
71,76000;1,19615;3426,32905
71,84001;1,19752;3432,03545
71,92001;1,19872;3436,80456
72,00000;1,20015;3442,10342
72,08000;1,20153;3448,69159
72,16000;1,20285;3453,24986
72,24001;1,20422;3458,94843
72,32000;1,20554;3464,70736
72,40000;1,20697;3469,49548
72,48000;1,20823;3475,46339
72,56001;1,20936;3478,56209
72,64001;1,21086;3484,84367
72,72000;1,21223;3491,64456
72,80000;1,21355;3496,21996
72,88001;1,21486;3502,23817
72,96001;1,21618;3507,28929
73,04000;1,21755;3512,83140
73,12000;1,21881;3518,58102
73,20001;1,22000;3521,91702
73,28001;1,22150;3529,01928
73,36000;1,22281;3535,43013
73,44000;1,22413;3539,95487
73,52001;1,22545;3546,00176
73,60001;1,22682;3550,48738
73,68000;1,22820;3557,09270
73,76000;1,22945;3562,50368
73,84001;1,23071;3566,74045
73,92001;1,23226;3574,21450
74,00000;1,23352;3579,68621
74,08000;1,23489;3584,66394
74,16000;1,23615;3590,38785
74,24001;1,23752;3595,73141
74,32001;1,23896;3602,25588
74,40000;1,24009;3607,08609
74,48000;1,24135;3611,06023
74,56001;1,24290;3620,25090
74,64001;1,24422;3625,30202
74,72000;1,24553;3630,94620
74,80000;1,24685;3635,96380
74,88001;1,24823;3641,52156
74,96001;1,24954;3647,83108
75,04000;1,25074;3651,43009
75,12000;1,25211;3656,18169
75,20001;1,25355;3663,27651
75,28001;1,25486;3669,10212
75,36000;1,25624;3673,57656
75,44000;1,25755;3679,58769
75,52001;1,25893;3685,34550
75,60001;1,26024;3690,53558
75,68000;1,26138;3695,06516
75,76000;1,26281;3700,44522
75,84001;1,26419;3707,04345
75,92001;1,26544;3711,08577
76,00000;1,26682;3718,05690
76,08000;1,26814;3723,47832
76,16000;1,26951;3728,72762
76,24001;1,27083;3734,86914
76,32001;1,27202;3739,41474
76,40000;1,27346;3744,37086
76,48000;1,27483;3750,91396
76,56001;1,27615;3756,43596
76,64001;1,27752;3762,14981
76,72000;1,27890;3767,33728
76,80000;1,28027;3773,27576
76,88001;1,28153;3778,42672
76,96001;1,28272;3782,55211
77,04000;1,28416;3788,68878
77,12000;1,28547;3794,77739
77,20001;1,28685;3800,06954
77,28001;1,28816;3804,79433
77,36000;1,28960;3811,94428
77,44000;1,29091;3818,15992
77,52001;1,29211;3823,09519
77,60001;1,29337;3827,02313
77,68000;1,29486;3833,53084
77,76000;1,29618;3839,15268
77,84001;1,29749;3845,19063
77,92001;1,29887;3850,50364
78,00000;1,30024;3856,05730
78,08000;1,30162;3861,57818
78,16000;1,30275;3866,15582
78,24001;1,30407;3870,55911
78,32001;1,30556;3877,78021
78,40000;1,30688;3882,69350
78,48000;1,30825;3888,69792
78,56001;1,30957;3894,09512
78,64001;1,31088;3899,61042
78,72000;1,31226;3905,21027
78,80000;1,31340;3909,46791
78,88001;1,31471;3913,93788
78,96001;1,31621;3921,39442
79,04000;1,31746;3926,57705
79,12000;1,31884;3931,93848
79,20001;1,32015;3938,00549
79,28001;1,32153;3943,55394
79,36000;1,32290;3949,69545
79,44000;1,32404;3955,10830
79,52001;1,32547;3959,81148
79,60001;1,32691;3966,78895
79,68000;1,32822;3971,92314
79,76000;1,32960;3977,93688
79,84001;1,33085;3982,52346
79,92001;1,33223;3988,45412
80,00000;1,33348;3994,63102
80,08000;1,33468;3997,99570
80,16000;1,33612;4004,07724
80,24001;1,33755;4012,13840
80,32001;1,33887;4016,61098
80,40000;1,34018;4022,52823
80,48000;1,34150;4028,48013
80,56001;1,34287;4033,75141
80,64001;1,34413;4038,68593
80,72000;1,34532;4043,02850
80,80000;1,34682;4049,86665
80,88001;1,34819;4056,01226
80,96001;1,34951;4061,51190
81,04000;1,35088;4065,82169
81,12000;1,35226;4072,22733
81,20001;1,35363;4077,63496
81,28001;1,35477;4082,64361
81,36000;1,35603;4086,43931
81,44000;1,35752;4092,77938
81,52001;1,35884;4098,60574
81,60001;1,36015;4104,18473
81,68000;1,36153;4110,63619
81,76000;1,36284;4116,29528
81,84001;1,36422;4122,06799
81,92001;1,36535;4126,99133
82,00001;1,36673;4131,62336
82,08000;1,36822;4139,66328
82,16000;1,36948;4145,29853
82,24001;1,37085;4151,42104
82,32001;1,37223;4156,88232
82,40000;1,37360;4162,12715
82,48000;1,37486;4167,78885
82,56001;1,37606;4172,55536
82,64001;1,37755;4179,26945
82,72000;1,37893;4185,51713
82,80000;1,38018;4190,84579
82,88001;1,38150;4196,03698
82,96001;1,38287;4201,89314
83,04000;1,38425;4208,37328
83,12000;1,38550;4213,79134
83,20001;1,38664;4217,06736
83,28001;1,38813;4223,10308
83,36000;1,38951;4229,93824
83,44000;1,39082;4234,63248
83,52001;1,39220;4241,46466
83,60001;1,39351;4246,59513
83,68000;1,39489;4251,67345
83,76000;1,39614;4258,07163
83,84001;1,39734;4261,83827
83,92001;1,39884;4268,24056
84,00001;1,40015;4274,00433
84,08000;1,40159;4279,48013
84,16000;1,40290;4285,84404
84,24001;1,40422;4290,90261
84,32001;1,40559;4297,24753
84,40000;1,40679;4302,11760
84,48000;1,40804;4306,65091
84,56001;1,40954;4312,65607
84,64001;1,41079;4319,23345
84,72000;1,41217;4324,53975
84,80000;1,41342;4330,06212
84,88001;1,41480;4335,56736
84,96001;1,41623;4343,03470
85,04000;1,41743;4348,01914
85,12000;1,41874;4352,75026
85,20001;1,42024;4359,47329
85,28001;1,42155;4365,94151
85,36000;1,42293;4371,29475
85,44000;1,42419;4376,52878
85,52001;1,42556;4383,07598
85,60001;1,42694;4388,60133
85,68000;1,42801;4393,09441
85,76000;1,42939;4398,92970
85,84001;1,43088;4405,85762
85,92001;1,43220;4410,66772
86,00001;1,43351;4417,84672
86,08000;1,43483;4422,24555
86,16000;1,43620;4427,90352
86,24001;1,43758;4436,18633
86,32001;1,43865;4441,11638
86,40000;1,44009;4445,50589
86,48000;1,44152;4452,61337
86,56001;1,44284;4457,60973
86,64001;1,44422;4463,59217
86,72000;1,44553;4468,83664
86,80000;1,44697;4475,16255
86,88001;1,44822;4481,44786
86,96001;1,44936;4485,79155
87,04000;1,45079;4491,69278
87,12000;1,45223;4498,93139
87,20001;1,45348;4504,29805
87,28001;1,45480;4510,43695
87,36000;1,45611;4515,71122
87,44000;1,45755;4522,12766
87,52001;1,45880;4527,54386
87,60001;1,46000;4531,80782
87,68001;1,46149;4538,97193
87,76000;1,46287;4545,95871
87,84001;1,46418;4551,53733
87,92001;1,46550;4557,91801
88,00001;1,46688;4563,22581
88,08000;1,46825;4568,87931
88,16000;1,46951;4574,98096
88,24001;1,47070;4579,02029
88,32001;1,47226;4586,33788
88,40000;1,47357;4592,71446
88,48000;1,47483;4598,39553
88,56001;1,47620;4604,27254
88,64001;1,47758;4610,90170
88,72000;1,47895;4616,37788
88,80000;1,48009;4621,36380
88,88001;1,48134;4626,33818
88,96001;1,48284;4632,84142
89,04000;1,48415;4639,66914
89,12000;1,48547;4644,88119
89,20001;1,48684;4650,84538
89,28001;1,48822;4656,37930
89,36000;1,48960;4663,20179
89,44000;1,49079;4669,05236
89,52001;1,49205;4673,20532
89,60001;1,49354;4680,00807
89,68001;1,49486;4685,60606
89,76000;1,49617;4691,38920
89,84001;1,49755;4697,44131
89,92001;1,49892;4703,51800
90,00001;1,50024;4709,66548
90,08000;1,50143;4714,65290
90,16000;1,50269;4718,84646
90,24001;1,50418;4726,15883
90,32001;1,50550;4732,07608
90,40000;1,50681;4738,22616
90,48000;1,50819;4745,09075
90,56001;1,50951;4750,00478
90,64001;1,51088;4756,16120
90,72000;1,51208;4762,16078
90,80000;1,51339;4766,46982
90,88001;1,51501;4781,17131
90,96001;1,51626;4785,46582
91,04000;1,51758;4790,64398
91,12000;1,51889;4796,50162
91,20001;1,52027;4802,15102
91,28001;1,52146;4807,01588
91,36000;1,52266;4811,94630
91,44000;1,52415;4818,03678
91,52001;1,52553;4824,80600
91,60001;1,52684;4830,61709
91,68001;1,52822;4835,37242
91,76000;1,52953;4841,80748
91,84001;1,53085;4847,30490
91,92001;1,53211;4852,55830
92,00001;1,53336;4857,54274
92,08000;1,53486;4864,90466
92,16000;1,53617;4870,70307
92,24001;1,53755;4876,99024
92,32001;1,53886;4881,91657
92,40000;1,54018;4887,51717
92,48000;1,54155;4893,66800
92,56001;1,54281;4898,53397
92,64001;1,54406;4903,14923
92,72000;1,54550;4910,38039
92,80000;1,54681;4916,36097
92,88001;1,54819;4921,97052
92,96001;1,54956;4927,70709
93,04000;1,55088;4933,04543
93,12000;1,55225;4939,13777
93,20001;1,55345;4943,89012
93,28001;1,55471;4948,97589
93,36001;1,55614;4956,43541
93,44000;1,55752;4962,53446
93,52001;1,55883;4968,55415
93,60001;1,56015;4974,15625
93,68001;1,56152;4980,42442
93,76000;1,56290;4986,29734
93,84001;1,56409;4991,91582
93,92001;1,56535;4997,20052
94,00001;1,56684;5004,19922
94,08000;1,56816;5010,03861
94,16000;1,56953;5015,65300
94,24001;1,57085;5021,58217
94,32001;1,57222;5026,97900