File: SU - Suspension/test en traction/Courbes/triangles/Specimen_RawData_6.csv
Temps;Déplacement;Charge
(sec);(mm);(N)
0,00000;0,05369;38,52086
0,06000;0,05375;37,93026
0,12000;0,05381;39,01477
0,18000;0,05387;37,70732
0,24000;0,05411;38,51799
0,30000;0,05495;40,94822
0,36000;0,05602;47,11310
0,42000;0,05716;53,56618
0,48000;0,05829;59,30983
0,54000;0,05943;65,20818
0,60000;0,06045;70,36953
0,66000;0,06134;75,89272
0,72000;0,06242;80,13137
0,78000;0,06356;86,18818
0,84000;0,06451;92,21933
0,90000;0,06547;97,05925
0,96000;0,06655;102,31666
1,02000;0,06750;107,87892
1,08000;0,06846;111,71924
1,14000;0,06954;116,95322
1,20000;0,07055;122,94559
1,26000;0,07151;127,83600
1,32000;0,07241;133,03478
1,38000;0,07354;137,64641
1,44000;0,07456;143,49112
1,50000;0,07551;148,00632
1,56000;0,07653;153,14237
1,62000;0,07749;159,08069
1,68000;0,07850;164,21961
1,74000;0,07952;169,53171
1,80000;0,08060;175,11502
1,86000;0,08155;180,37392
1,92000;0,08239;185,06624
1,98000;0,08335;189,13463
2,04000;0,08454;195,48947
2,10000;0,08556;201,45001
2,16000;0,08658;205,64774
2,22000;0,08759;212,58544
2,28000;0,08855;217,60745
2,34000;0,08950;222,48141
2,40000;0,09058;227,52883
2,46000;0,09160;233,05365
2,52000;0,09249;237,13568
2,58000;0,09339;241,32268
2,64000;0,09447;246,97159
2,70000;0,09560;252,27065
2,76000;0,09656;257,45193
2,82000;0,09758;262,79581
2,88000;0,09853;267,85375
2,94000;0,09955;272,17241
3,00000;0,10051;277,23971
3,06000;0,10158;282,89037
3,12000;0,10254;288,38348
3,18000;0,10338;291,87382
3,24000;0,10439;296,75227
3,30000;0,10559;301,09619
3,36000;0,10660;307,35845
3,42000;0,10750;310,95035
3,48000;0,10858;315,33921
3,54000;0,10953;319,39044
3,60000;0,11055;323,78333
3,66000;0,11175;327,62261
3,72000;0,11264;275,88769
3,78000;0,11348;220,94625
3,84000;0,11456;226,85416
3,90000;0,11563;233,83750
3,96000;0,11659;239,31684
4,02000;0,11755;244,79232
4,08000;0,11856;250,92973
4,14000;0,11958;256,91837
4,20000;0,12054;262,51678
4,26000;0,12161;267,92588
4,32000;0,12257;273,60185
4,38000;0,12341;279,09754
4,44000;0,12442;284,15979
4,50000;0,12562;291,27346
4,56000;0,12657;298,59762
4,62000;0,12759;303,31104
4,68000;0,12855;309,33977
4,74000;0,12956;314,61876
4,80000;0,13058;320,44963
4,86000;0,13166;326,26123
4,92000;0,13261;332,22146
4,98000;0,13345;336,52023
5,04000;0,13441;339,81989
5,10000;0,13554;345,03588
5,16000;0,13662;350,58088
5,22000;0,13752;354,81842
5,28000;0,13853;359,29496
5,34000;0,13961;365,48267
5,40000;0,14062;369,97613
5,46000;0,14164;375,44717
5,52000;0,14266;380,13281
5,58000;0,14355;384,50020
5,64000;0,14445;387,44533
5,70000;0,14547;392,35302
5,76000;0,14660;397,62692
5,82000;0,14756;402,14439
5,88000;0,14852;407,02620
5,94000;0,14953;410,73030
6,00000;0,15055;416,33411
6,06000;0,15157;420,64423
6,12000;0,15258;425,39868
6,18000;0,15360;429,81408
6,24000;0,15450;433,99683
6,30000;0,15545;438,26285
6,36000;0,15653;442,78740
6,42000;0,15761;448,05999
6,48000;0,15832;452,03832
6,54000;0,15964;459,75675
6,60000;0,16059;463,90356
6,66000;0,16161;467,87830
6,72000;0,16263;472,75540
6,78000;0,16364;477,78850
6,84000;0,16454;481,95291
6,90000;0,16544;484,33682
6,96000;0,16651;488,35073
7,02000;0,16759;494,63152
7,08000;0,16855;498,92031
7,14000;0,16956;502,97580
7,20000;0,17052;507,42510
7,26000;0,17154;511,71402
7,32000;0,17255;515,50986
7,38000;0,17363;519,91590
7,44000;0,17459;523,76296
7,50000;0,17542;528,45976
7,56000;0,17638;532,59595
7,62000;0,17751;537,99064
7,68000;0,17859;541,90112
7,74000;0,17961;546,76030
7,80000;0,18062;550,86827
7,86000;0,18158;555,39957
7,92000;0,18260;559,52612
7,98000;0,18361;563,34357
8,04000;0,18463;567,75683
8,10000;0,18559;572,26080
8,16000;0,18642;575,96071
8,22000;0,18750;580,45452
8,28000;0,18858;585,17433
8,34000;0,18959;589,51997
8,40000;0,19055;593,35218
8,46000;0,19157;598,33894
8,52000;0,19258;602,30205
8,58000;0,19354;606,47265
8,64000;0,19461;610,89955
8,70000;0,19563;615,27118
8,76000;0,19647;619,45193
8,82000;0,19742;623,26845
8,88000;0,19850;627,74280
8,94000;0,19958;633,21218
9,00000;0,20059;636,88275
9,06000;0,20155;641,39976
9,12000;0,20257;645,59984
9,18000;0,20352;649,68104
9,24000;0,20460;653,95883
9,30000;0,20562;658,69740
9,36000;0,20657;662,36625
9,42000;0,20747;668,21165
9,48000;0,20849;671,65862
9,54000;0,20962;676,70397
9,60000;0,21058;681,28514
9,66000;0,21154;685,46706
9,72000;0,21255;689,69270
9,78000;0,21357;693,75541
9,84000;0,21458;697,92168
9,90000;0,21560;702,97583
9,96000;0,21662;706,64478
10,02000;0,21739;710,07763
10,08000;0,21835;713,94960
10,14000;0,21949;717,75340
10,20000;0,22056;723,42851
10,26000;0,22158;727,92508
10,32000;0,22254;732,32581
10,38000;0,22355;735,96244
10,44000;0,22451;740,42780
10,50000;0,22559;744,35095
10,56000;0,22666;749,79695
10,62000;0,22756;753,91466
10,68000;0,22840;756,86644
10,74000;0,22941;760,26758
10,80000;0,23055;765,92630
10,86000;0,23156;769,85569
10,92000;0,23252;773,14964
10,98000;0,23360;778,07363
11,04000;0,23461;782,63218
11,10000;0,23563;786,93554
11,16000;0,23671;791,86819
11,22000;0,23766;795,90343
11,28000;0,23850;799,49275
11,34000;0,23940;801,89444
11,40000;0,24053;806,92377
11,46000;0,24161;812,69536
11,52000;0,24257;816,23616
11,58000;0,24358;820,16401
11,64000;0,24460;825,62491
11,70000;0,24556;829,24385
11,76000;0,24657;833,45985
11,82000;0,24759;838,28298
11,88000;0,24854;842,64036
11,94000;0,24944;845,67098
12,00000;0,25046;849,82179
12,06000;0,25159;855,34798
12,12000;0,25255;860,23444
12,18000;0,25357;863,42730
12,24000;0,25458;867,80349
12,30000;0,25560;871,83155
12,36000;0,25656;875,97314
12,42000;0,25763;881,11451
12,48000;0,25865;885,70705
12,54000;0,25949;889,08812
12,60000;0,26044;892,86072
12,66000;0,26152;897,10327
12,72000;0,26260;901,44128
12,78000;0,26355;905,82278
12,84000;0,26475;911,28293
12,90000;0,26564;918,94232
12,96000;0,26654;921,68879
13,02000;0,26756;925,20341
13,08000;0,26857;928,92973
13,14000;0,26947;933,63812
13,20000;0,27037;937,47303
13,26000;0,27150;941,35730
13,32000;0,27252;946,23473
13,38000;0,27354;950,46209
13,44000;0,27455;954,28918
13,50000;0,27557;958,25810
13,56000;0,27653;962,88025
13,62000;0,27754;966,03893
13,68000;0,27862;970,87231
13,74000;0,27958;975,11318
13,80000;0,28041;978,37057
13,86000;0,28143;982,54597
13,92000;0,28262;987,26610
13,98000;0,28358;991,46124
14,04000;0,28460;994,62187
14,10000;0,28555;999,12928
14,16000;0,28657;1002,87935
14,22000;0,28753;1006,64366
14,28000;0,28860;1011,68044
14,34000;0,28968;1016,61226
14,40000;0,29052;1020,83599
14,46000;0,29141;1024,28757
14,52000;0,29249;1027,70114
14,58000;0,29357;1033,38724
14,64000;0,29452;1038,37354
14,70000;0,29554;1041,27768
14,76000;0,29656;1045,93467
14,82000;0,29751;1050,29605
14,88000;0,29859;1054,32244
14,94000;0,29966;1058,93286
15,00000;0,30056;1062,84404
15,06000;0,30140;1066,70121
15,12000;0,30242;1070,01020
15,18000;0,30355;1074,71030
15,24000;0,30463;1079,83379
15,30000;0,30558;1083,96998
15,36000;0,30660;1088,33434
15,42000;0,30762;1091,93074
15,48000;0,30857;1095,27968
15,54000;0,30965;1099,80237
15,60000;0,31061;1104,09725
15,66000;0,31144;1108,61678
15,72000;0,31240;1110,87374
15,78000;0,31348;1114,71573
15,84000;0,31461;1121,30987
15,90000;0,31557;1125,18771
15,96000;0,31653;1129,40194
16,02000;0,31754;1132,71149
16,08000;0,31856;1137,53565
16,14000;0,31957;1140,90778
16,20000;0,32059;1145,30735
16,26000;0,32155;1149,87567
16,32000;0,32238;1152,86540
16,38000;0,32340;1156,19162
16,44000;0,32460;1161,58603
16,50000;0,32555;1166,41838
16,56000;0,32657;1169,55973
16,62000;0,32759;1173,96628
16,68000;0,32860;1178,97699
16,74000;0,32956;1182,47196
16,80000;0,33070;1186,95190
16,86000;0,33165;1191,02197
16,92000;0,33249;1194,35368
16,98000;0,33339;1196,66215
17,04000;0,33458;1201,81693
17,10000;0,33560;1206,74418
17,16000;0,33656;1210,81639
17,22000;0,33757;1214,69768
17,28000;0,33859;1219,02162
17,34000;0,33954;1223,79912
17,40000;0,34056;1227,48949
17,46000;0,34164;1232,03751
17,52000;0,34253;1235,04242
17,58000;0,34337;1232,16230
17,64000;0,34451;1235,99637
17,70000;0,34564;1241,32596
17,76000;0,34660;1245,88860
17,82000;0,34756;1249,20458
17,88000;0,34857;1254,50334
17,94000;0,34959;1258,19258
18,00000;0,35067;1262,31490
18,06000;0,35168;1267,33687
18,12000;0,35264;1271,04539
18,18000;0,35348;1275,01562
18,24000;0,35449;1278,50939
18,30000;0,35563;1284,58152
18,36000;0,35658;1288,67310
18,42000;0,35754;1292,11256
18,48000;0,35856;1295,97364
18,54000;0,35957;1300,10275
18,60000;0,36059;1303,90245
18,66000;0,36161;1308,01946
18,72000;0,36262;1312,75672
18,78000;0,36346;1315,84890
18,84000;0,36436;1318,77130
18,90000;0,36543;1322,89343
18,96000;0,36651;1328,05277
19,02000;0,36753;1331,31184
19,08000;0,36854;1336,07397
19,14000;0,36956;1339,47041
19,20000;0,37052;1343,87352
19,26000;0,37153;1347,78656
19,32000;0,37261;1352,33849
19,38000;0,37356;1356,92554
19,44000;0,37446;1359,32239
19,50000;0,37548;1364,06375
19,56000;0,37661;1368,32269
19,62000;0,37763;1372,64365
19,68000;0,37859;1376,68587
19,74000;0,37966;1379,75812
19,80000;0,38062;1384,80086
19,86000;0,38158;1388,64163
19,92000;0,38259;1392,14937
19,98000;0,38361;1396,41808
20,04000;0,38451;1400,41374
20,10000;0,38540;1403,08701
20,16000;0,38660;1407,85854
20,22000;0,38762;1415,28957
20,28000;0,38857;1418,53075
20,34000;0,38959;1422,09800
20,40000;0,39054;1426,02930
20,46000;0,39156;1430,51101
20,52000;0,39258;1434,48599
20,58000;0,39365;1437,89630
20,64000;0,39455;1441,64376
20,70000;0,39539;1445,50018
20,76000;0,39646;1449,25620
20,82000;0,39760;1454,03743
20,88000;0,39862;1459,01171
20,94000;0,39963;1462,08704
21,00000;0,40065;1465,98490
21,06000;0,40167;1470,51532
21,12000;0,40262;1474,23195
21,18000;0,40364;1477,78485
21,24000;0,40460;1482,91672
21,30000;0,40549;1485,68153
21,36000;0,40639;1488,02828
21,42000;0,40753;1493,00303
21,48000;0,40860;1499,31628
21,54000;0,40956;1503,00274
21,60000;0,41057;1506,35354
21,66000;0,41159;1509,95525
21,72000;0,41255;1514,24240
21,78000;0,41356;1518,92193
21,84000;0,41464;1522,67581
21,90000;0,41554;1526,84618
21,96000;0,41643;1529,01672
22,02000;0,41745;1533,09312
22,08000;0,41853;1537,74135
22,14000;0,41954;1541,95838
22,20000;0,42056;1546,24376
22,26000;0,42164;1549,96701
22,32000;0,42259;1553,96350
22,38000;0,42361;1557,45596
22,44000;0,42468;1562,16454
22,50000;0,42564;1566,64904
22,56000;0,42654;1569,49814
22,62000;0,42744;1573,18637
22,68000;0,42851;1577,32517
22,74000;0,42959;1582,29563
22,80000;0,43054;1586,01496
22,86000;0,43156;1589,62887
22,92000;0,43258;1593,54135
22,98000;0,43353;1598,17245
23,04000;0,43461;1601,16740
23,10000;0,43563;1605,96948
23,16000;0,43652;1609,66162
23,22000;0,43736;1612,98476
23,28000;0,43838;1616,20360
23,34000;0,43951;1620,92000
23,40000;0,44059;1626,12908
23,46000;0,44155;1629,82084
23,52000;0,44256;1633,23898
23,58000;0,44358;1637,34499
23,64000;0,44459;1641,02614
23,70000;0,44561;1645,19679
23,76000;0,44663;1649,76884
23,82000;0,44752;1653,94470
23,88000;0,44842;1656,19347
23,94000;0,44956;1660,07709
24,00000;0,45004;1665,48826
24,06000;0,45171;1673,23221
24,12000;0,45267;1677,06255
24,18000;0,45362;1680,92791
24,24000;0,45458;1684,12104
24,30000;0,45560;1687,16330
24,36000;0,45655;1691,59900
24,42000;0,45739;1694,59991
24,48000;0,45835;1697,95770
24,54000;0,45948;1702,22297
24,60000;0,46056;1707,72262
24,66000;0,46152;1711,34342
24,72000;0,46253;1715,20486
24,78000;0,46355;1718,64778
24,84000;0,46456;1723,48488
24,90000;0,46558;1726,22465
24,96000;0,46660;1730,23101
25,02000;0,46749;1733,79891
25,08000;0,46839;1735,96572
25,14000;0,46947;1739,59173
25,20000;0,47060;1745,48589
25,26000;0,47156;1748,75818
25,32000;0,47258;1752,82620
25,38000;0,47359;1756,18753
25,44000;0,47461;1759,58257
25,50000;0,47563;1763,46321
25,56000;0,47664;1767,93635
25,62000;0,47760;1771,49493
25,68000;0,47844;1774,25295
25,74000;0,47939;1776,51681
25,80000;0,48053;1781,13692
25,86000;0,48154;1785,05145
25,92000;0,48250;1788,26824
25,98000;0,48352;1791,90245
26,04000;0,48453;1795,27700
26,10000;0,48555;1799,72816
26,16000;0,48651;1802,62234
26,22000;0,48758;1805,90041
26,28000;0,48854;1810,52797
26,34000;0,48938;1813,18782
26,40000;0,49045;1816,64452
26,46000;0,49159;1821,40395
26,52000;0,49255;1824,93515
26,58000;0,49356;1828,97206
26,64000;0,49458;1833,01102
26,70000;0,49560;1836,68546
26,76000;0,49661;1840,91758
26,82000;0,49769;1844,43519
26,88000;0,49864;1848,66600
26,94000;0,49954;1853,67726
27,00000;0,50044;1856,72324
27,06000;0,50157;1861,49888
27,12000;0,50253;1866,17710
27,18000;0,50355;1869,86346
27,24000;0,50450;1873,29035
27,30000;0,50552;1878,93361
27,36000;0,50648;1882,23608
27,42000;0,50749;1886,49893
27,48000;0,50857;1891,39768
27,54000;0,50953;1896,37206
27,60000;0,51042;1898,97399
27,66000;0,51144;1903,07200
27,72000;0,51258;1908,28219
27,78000;0,51353;1913,27762
27,84000;0,51461;1917,19197
27,90000;0,51556;1921,36765
27,96000;0,51658;1926,24051
28,02000;0,51760;1930,08836
28,08000;0,51861;1933,87195
28,14000;0,51963;1939,85030
28,20000;0,52047;1942,95105
28,26000;0,52142;1945,85416
28,32000;0,52262;1950,79204
28,38000;0,52358;1955,65652
28,44000;0,52459;1960,85609
28,50000;0,52561;1964,56071
28,56000;0,52657;1968,09806
28,62000;0,52752;1972,34042
28,68000;0,52860;1976,02119
28,74000;0,52962;1980,20134
28,80000;0,53051;1984,67709
28,86000;0,53135;1986,29554
28,92000;0,53243;1991,74490
28,98000;0,53356;1996,31546
29,04000;0,53458;2000,30170
29,10000;0,53553;2004,74709
29,16000;0,53655;2009,33199
29,22000;0,53757;2012,61826
29,28000;0,53858;2016,81647
29,34000;0,53966;2021,60813
29,40000;0,54062;2025,64895
29,46000;0,54145;2028,42522
29,52000;0,54241;2032,12071
29,58000;0,54355;2037,88597
29,64000;0,54462;2042,91884
29,70000;0,54558;2046,45488
29,76000;0,54654;2050,82726
29,82000;0,54755;2054,61252
29,88000;0,54857;2058,55202
29,94000;0,54964;2063,92296
30,00000;0,55066;2068,98339
30,06000;0,55150;2071,54807
30,12000;0,55240;2074,78106
30,18000;0,55347;2078,37280
30,24000;0,55449;2084,32432
30,30000;0,55562;2091,06933
30,36000;0,55658;2095,13400
30,42000;0,55760;2098,26007
30,48000;0,55855;2102,69541
30,54000;0,55963;2107,26764
30,60000;0,56059;2111,47927
30,66000;0,56148;2115,54673
30,72000;0,56238;2118,70652
30,78000;0,56352;2123,00420
30,84000;0,56465;2128,56755
30,90000;0,56555;2133,62407
30,96000;0,56657;2136,68030
31,02000;0,56758;2140,08838
31,08000;0,56860;2145,39692
31,14000;0,56961;2148,78768
31,20000;0,57069;2153,77659
31,26000;0,57159;2157,20106
31,32000;0,57242;2160,05929
31,38000;0,57350;2163,59831
31,44000;0,57464;2168,74219
31,50000;0,57553;2173,58954
31,56000;0,57655;2154,23778
31,62000;0,57751;2152,97751
31,68000;0,57852;2158,99739
31,74000;0,57954;2164,30426
31,80000;0,58062;2169,80241
31,86000;0,58163;2174,60748
31,92000;0,58253;2179,77017
31,98000;0,58343;2182,71445
32,04000;0,58450;2187,47258
32,10000;0,58558;2193,59566
32,16000;0,58653;2197,56141
32,22000;0,58755;2201,42938
32,28000;0,58863;2206,30039
32,34000;0,58958;2210,09497
32,40000;0,59060;2214,53030
32,46000;0,59162;2218,75422
32,52000;0,59257;2224,33396
32,58000;0,59347;2226,95488
32,64000;0,59443;2231,15012
32,70000;0,59568;2239,87568
32,76000;0,59658;2244,88359
32,82000;0,59760;2248,89796
32,88000;0,59861;2252,76481
32,94000;0,59957;2256,96396
33,00000;0,60059;2261,72190
33,06000;0,60160;2265,45818
33,12000;0,60256;2270,11144
33,18000;0,60346;2273,82705
33,24000;0,60447;2276,87582
33,30000;0,60561;2281,44787
33,36000;0,60656;2286,72381
33,42000;0,60752;2290,85423
33,48000;0,60860;2294,78627
33,54000;0,60961;2298,51920
33,60000;0,61063;2303,23654
33,66000;0,61165;2307,29394
33,72000;0,61266;2311,16284
33,78000;0,61350;2315,86806
33,84000;0,61440;2318,61398
33,90000;0,61547;2322,98523
33,96000;0,61661;2327,63737
34,02000;0,61757;2332,71532
34,08000;0,61858;2337,96872
34,14000;0,61960;2341,04786
34,20000;0,62061;2345,60668
34,26000;0,62163;2350,82880
34,32000;0,62265;2354,53881
34,38000;0,62360;2357,82638
34,44000;0,62444;2361,31568
34,50000;0,62540;2364,91673
34,56000;0,62653;2369,00877
34,62000;0,62755;2374,02450
34,68000;0,62851;2378,77835
34,74000;0,62958;2382,27937
34,80000;0,63054;2386,77301
34,86000;0,63156;2391,26105
34,92000;0,63263;2395,69675
34,98000;0,63365;2400,92296
35,04000;0,63455;2404,33533
35,10000;0,63538;2407,55156
35,16000;0,63646;2411,97273
35,22000;0,63760;2417,26618
35,28000;0,63855;2421,16433
35,34000;0,63957;2425,07197
35,40000;0,64052;2429,57324
35,46000;0,64154;2434,20303
35,52000;0,64256;2438,25093
35,58000;0,64363;2442,98056
35,64000;0,64459;2447,08341
35,70000;0,64549;2450,64516
35,76000;0,64644;2453,63954
35,82000;0,64752;2458,55972
35,88000;0,64854;2463,75203
35,94000;0,64955;2467,81707
36,00000;0,65051;2471,81542
36,06000;0,65153;2475,42486
36,12000;0,65254;2480,13791
36,18000;0,65356;2484,85673
36,24000;0,65458;2489,14473
36,30000;0,65553;2493,98630
36,36000;0,65637;2496,23768
36,42000;0,65745;2500,56069
36,48000;0,65858;2505,71221
36,54000;0,65954;2510,93619
36,60000;0,66055;2514,97645
36,66000;0,66157;2518,26588
36,72000;0,66259;2524,01903
36,78000;0,66360;2530,94770
36,84000;0,66468;2534,91234
36,90000;0,66558;2538,78087
36,96000;0,66641;2541,63444
37,02000;0,66743;2545,08052
37,08000;0,66857;2551,55936
37,14000;0,66958;2555,34127
37,20000;0,67054;2559,56817
37,26000;0,67156;2564,25031
37,32000;0,67257;2567,82267
37,38000;0,67359;2571,41031
37,44000;0,67460;2575,81733
37,50000;0,67562;2580,69243
37,56000;0,67646;2583,71197
37,62000;0,67741;2587,03753
37,68000;0,67855;2591,71072
37,74000;0,67963;2595,81283
37,80000;0,68058;2600,06767
37,86000;0,68160;2603,93117
37,92000;0,68262;2609,15924
37,98000;0,68357;2611,85095
38,04000;0,68459;2616,37904
38,10000;0,68561;2621,42587
38,16000;0,68656;2624,35526
38,22000;0,68746;2628,47785
38,28000;0,68848;2631,42698
38,34000;0,68961;2636,98846
38,40000;0,69057;2641,34482
38,46000;0,69153;2644,31257
38,52000;0,69254;2649,09808
38,58000;0,69356;2652,80120
38,64000;0,69457;2657,03164
38,70000;0,69559;2661,49193
38,76000;0,69661;2665,16767
38,82000;0,69750;2669,17497
38,88000;0,69840;2672,64694
38,94000;0,69948;2676,61493
39,00000;0,70061;2684,09941
39,06000;0,70157;2688,21921
39,12000;0,70259;2693,39401
39,18000;0,70360;2697,43484
39,24000;0,70456;2701,70420
39,30000;0,70558;2705,36356
39,36000;0,70659;2709,54706
39,42000;0,70755;2713,01214
39,48000;0,70839;2716,47461
39,54000;0,70946;2720,16395
39,60000;0,71054;2725,31118
39,66000;0,71149;2729,57198
39,72000;0,71251;2733,59958
39,78000;0,71359;2737,02815
39,84000;0,71454;2742,31993
39,90000;0,71556;2745,23813
39,96000;0,71664;2750,30565
40,02000;0,71759;2754,18852
40,08000;0,71843;2757,06779
40,14000;0,71939;2759,60248
40,20000;0,72052;2764,23953
40,26000;0,72154;2769,39981
40,32000;0,72250;2773,15099
40,38000;0,72351;2776,51139
40,44000;0,72453;2781,19892
40,50000;0,72549;2784,58036
40,56000;0,72656;2788,98831
40,62000;0,72764;2792,87044
40,68000;0,72853;2796,55457
40,74000;0,72943;2799,96023
40,80000;0,73051;2802,71620
40,86000;0,73158;2807,99512
40,92000;0,73254;2811,05712
40,98000;0,73356;2814,73752
41,04000;0,73451;2818,59264
41,10000;0,73559;2823,92167
41,16000;0,73661;2827,58959
41,22000;0,73768;2830,93508
41,28000;0,73858;2834,25879
41,34000;0,73942;2836,06909
41,40000;0,74043;2839,40509
41,46000;0,74157;2844,29267
41,52000;0,74259;2848,06173
41,58000;0,74360;2852,37301
41,64000;0,74456;2854,72963
41,70000;0,74552;2858,34726
41,76000;0,74653;2861,95520
41,82000;0,74761;2865,10438
41,88000;0,74862;2869,51922
41,94000;0,74946;2873,00777
42,00000;0,75036;2875,01309
42,06000;0,75149;2878,55417
42,12000;0,75257;2883,39444
42,18000;0,75359;2886,91968
42,24000;0,75454;2890,07518
42,30000;0,75556;2893,51791
42,36000;0,75652;2896,03285
42,42000;0,75759;2899,68438
42,48000;0,75867;2903,93811
42,54000;0,75957;2907,55555
42,60000;0,76040;2909,90360
42,66000;0,76142;2912,49603
42,72000;0,76261;2917,53709
42,78000;0,76357;2921,66807
42,84000;0,76459;2924,60378
42,90000;0,76554;2927,75650
42,96000;0,76656;2931,64756
43,02000;0,76758;2934,72670
43,08000;0,76859;2937,53669
43,14000;0,76961;2942,26184
43,20000;0,77045;2945,34080
43,26000;0,77134;2948,06194
43,32000;0,77254;2952,36986
43,38000;0,77362;2957,56478
43,44000;0,77457;2960,91735
43,50000;0,77559;2963,62191
43,56000;0,77661;2967,70725
43,62000;0,77756;2970,97359
43,68000;0,77864;2974,59643
43,74000;0,77965;2978,60820
43,80000;0,78049;2981,27010
43,86000;0,78139;2983,97262
43,92000;0,78252;2987,41385
43,98000;0,78366;2991,76089
44,04000;0,78456;2994,97303
44,10000;0,78557;2998,54036
44,16000;0,78659;3002,45695
44,22000;0,78761;3006,17628
44,28000;0,78862;3010,14762
44,34000;0,78964;3013,10867
44,40000;0,79060;3015,78026
44,46000;0,79143;3018,49898
44,52000;0,79239;3021,52969
44,58000;0,79353;3026,49252
44,64000;0,79454;3030,47150
44,70000;0,79550;3033,84140
44,76000;0,79652;3036,35802
44,82000;0,79753;3040,64378
44,88000;0,79855;3044,38379
44,94000;0,79962;3048,00831
45,00000;0,80058;3052,11190
45,06000;0,80148;3054,91518
45,12000;0,80237;3057,63073
45,18000;0,80351;3060,58936
45,24000;0,80459;3065,34581
45,30000;0,80554;3070,12890
45,36000;0,80656;3073,04058
45,42000;0,80758;3076,44345
45,48000;0,80859;3080,45577
45,54000;0,80961;3084,26265
45,60000;0,81063;3087,63292
45,66000;0,81158;3090,88975
45,72000;0,81242;3093,37322
45,78000;0,81344;3096,52556
45,84000;0,81457;3100,84354
45,90000;0,81553;3104,99482
45,96000;0,81655;3107,95829
46,02000;0,81756;3110,98993
46,08000;0,81846;3114,60551
46,14000;0,81959;3120,05617
46,20000;0,82061;3123,64511
46,26000;0,82163;3126,56797
46,32000;0,82246;3130,02393
46,38000;0,82342;3131,79828
46,44000;0,82456;3135,57088
46,50000;0,82557;3140,41898
46,56000;0,82653;3142,96484
46,62000;0,82761;3146,43905
46,68000;0,82862;3149,81304
46,74000;0,82958;3153,46047
46,80000;0,83066;3156,39004
46,86000;0,83167;3160,00096
46,92000;0,83257;3163,31387
46,98000;0,83341;3164,92766
47,04000;0,83442;3167,74882
47,10000;0,83556;3172,36520
47,16000;0,83657;3176,21343
47,22000;0,83759;3180,30305
47,28000;0,83861;3182,77366
47,34000;0,83962;3186,85994
47,40000;0,84058;3189,57791
47,46000;0,84160;3193,36057
47,52000;0,84261;3196,69098
47,58000;0,84351;3199,35344
47,64000;0,84441;3201,97530
47,70000;0,84548;3205,04382
47,76000;0,84656;3208,99412
47,82000;0,84758;3212,68775
47,88000;0,84859;3216,45848
47,94000;0,84955;3219,36123
48,00000;0,85057;3222,96992
48,06000;0,85158;3225,69609
48,12000;0,85266;3229,40648
48,18000;0,85361;3233,66858
48,24000;0,85451;3236,34893
48,30000;0,85547;3238,43993
48,36000;0,85654;3242,61114
48,42000;0,85762;3246,65867
48,48000;0,85858;3249,35094
48,54000;0,85959;3253,65737
48,60000;0,86055;3256,65735
48,66000;0,86157;3259,82347
48,72000;0,86246;3263,58713
48,78000;0,86366;3269,57293
48,84000;0,86444;3271,65835
48,90000;0,86539;3274,54023
48,96000;0,86653;3277,85537
49,02000;0,86761;3282,97354
49,08000;0,86856;3285,94372
49,14000;0,86958;3289,59078
49,20000;0,87059;3293,00165
49,26000;0,87155;3296,76531
49,32000;0,87263;3301,18686
49,38000;0,87364;3303,68504
49,44000;0,87454;3306,68129
49,50000;0,87538;3308,58342
49,56000;0,87645;3311,98871
49,62000;0,87759;3316,76006
49,68000;0,87861;3321,38352
49,74000;0,87962;3323,54568
49,80000;0,88058;3326,79935
49,86000;0,88160;3330,72655
49,92000;0,88261;3333,76452
49,98000;0,88363;3338,27548
50,04000;0,88465;3340,91410
50,10000;0,88548;3344,77946
50,16000;0,88638;3346,58846
50,22000;0,88752;3349,75012
50,28000;0,88859;3355,07952
50,34000;0,88955;3358,74632
50,40000;0,89056;3361,99589
50,46000;0,89158;3365,31103
50,52000;0,89254;3369,21960
50,58000;0,89361;3372,86666
50,64000;0,89463;3376,10617
50,70000;0,89547;3379,66830
50,76000;0,89636;3380,41149
50,82000;0,89744;3384,50521
50,88000;0,89864;3389,73664
50,94000;0,89959;3393,43362
51,00000;0,90061;3396,91043
51,06000;0,90163;3399,77145
51,12000;0,90264;3403,39877
51,18000;0,90360;3406,37602
51,24000;0,90462;3410,04841
51,30000;0,90557;3412,82748
51,36000;0,90641;3415,66019
51,42000;0,90737;3418,32265
51,48000;0,90856;3421,82219
51,54000;0,90958;3427,18028
51,60000;0,91053;3429,62928
51,66000;0,91155;3432,39196
51,72000;0,91257;3435,85499
51,78000;0,91358;3439,85371
51,84000;0,91460;3443,65053
51,90000;0,91562;3447,41568
51,96000;0,91651;3450,52108
52,02000;0,91735;3451,82121
52,08000;0,91849;3454,99553
52,14000;0,91956;3459,91515
52,20000;0,92052;3463,29175
52,26000;0,92154;3466,65382
52,32000;0,92255;3469,91792
52,38000;0,92357;3472,98831
52,44000;0,92458;3476,81195
52,50000;0,92566;3479,90394
52,56000;0,92662;3483,26415
52,62000;0,92745;3485,93183
52,68000;0,92841;3487,31168
52,74000;0,92955;3491,24111
52,80000;0,93056;3495,14224
52,86000;0,93152;3497,95669
52,92000;0,93254;3500,84864
52,98000;0,93355;3504,95987
53,04000;0,93451;3507,42415
53,10000;0,93559;3511,05444
53,16000;0,93660;3515,29494
53,22000;0,93750;3518,38917
53,28000;0,93840;3520,73014
53,34000;0,93947;3523,62096
53,40000;0,94055;3527,60181
53,46000;0,94151;3531,57446
53,52000;0,94252;3534,98571
53,58000;0,94354;3538,12799
53,64000;0,94449;3540,85900
53,70000;0,94551;3544,14806
53,76000;0,94659;3547,55372
53,82000;0,94760;3551,69214
53,88000;0,94850;3554,12252
53,94000;0,94946;3556,32603
54,00000;0,95059;3561,00909
54,06000;0,95161;3564,52651
54,12000;0,95257;3567,67885
54,18000;0,95358;3571,17802
54,24000;0,95454;3573,90717
54,30000;0,95556;3576,10770
54,36000;0,95663;3579,85795
54,42000;0,95765;3582,47161
54,48000;0,95849;3586,35560
54,54000;0,95938;3587,44450
54,60000;0,96040;3590,60541
54,66000;0,96159;3596,22687
54,72000;0,96261;3599,81507
54,78000;0,96363;3602,70552
54,84000;0,96458;3605,57772
54,90000;0,96554;3609,26576
54,96000;0,96656;3611,62201
55,02000;0,96763;3615,46502
55,08000;0,96853;3618,25228
55,14000;0,96943;3620,29560
55,20000;0,97044;3622,36798
55,26000;0,97158;3627,16541
55,32000;0,97260;3629,80925
55,38000;0,97361;3632,84163
55,44000;0,97457;3636,80162
55,50000;0,97559;3638,80321
55,56000;0,97660;3641,96412
55,62000;0,97768;3645,64545
55,68000;0,97857;3648,40850
55,74000;0,97941;3650,43245
55,80000;0,98037;3652,04997
55,86000;0,98150;3655,70895
55,92000;0,98258;3660,32124
55,98000;0,98354;3662,75609
56,04000;0,98455;3664,99908
56,10000;0,98551;3668,59809
56,16000;0,98653;3671,12644
56,22000;0,98760;3674,49746
56,28000;0,98862;3677,93329
56,34000;0,98952;3680,26234
56,40000;0,99035;3682,41072
56,46000;0,99149;3685,00873
56,52000;0,99257;3689,41128
56,58000;0,99358;3692,02085
56,64000;0,99460;3695,50027
56,70000;0,99561;3697,55812
56,76000;0,99657;3700,53016
56,82000;0,99765;3703,28985
56,88000;0,99866;3706,29281
56,94000;0,99956;3708,78503
57,00000;1,00040;3710,62309
57,06000;1,00141;3712,15567
57,12000;1,00261;3717,34649
57,18000;1,00363;3720,21683
57,24000;1,00458;3722,76641
57,30000;1,00554;3725,34879
57,36000;1,00656;3727,81418
57,42000;1,00763;3730,80894
57,48000;1,00865;3734,03467
57,54000;1,00967;3736,34808
57,60000;1,01044;3739,71201
57,66000;1,01140;3740,36953
57,72000;1,01253;3743,90222
57,78000;1,01361;3747,35408
57,84000;1,01451;3750,55932
57,90000;1,01552;3752,79635
57,96000;1,01660;3755,94795
58,02000;1,01762;3758,89018
58,08000;1,01869;3762,07680
58,14000;1,01965;3764,55262
58,20000;1,02055;3767,00088
58,26000;1,02144;3768,31219
58,32000;1,02252;3770,95565
58,38000;1,02360;3777,14485
58,44000;1,02455;3779,08461
58,50000;1,02557;3781,41254
58,56000;1,02659;3783,75128
58,62000;1,02760;3788,04691
58,68000;1,02862;3789,37982
58,74000;1,02963;3792,51018
58,80000;1,03059;3795,24454
58,86000;1,03149;3796,06783
58,92000;1,03244;3797,72559
58,98000;1,03352;3801,67961
59,04000;1,03454;3805,04206
59,10000;1,03549;3806,96878
59,16000;1,03651;3810,03544
59,22000;1,03753;3812,70349
59,28000;1,03854;3815,53546
59,34000;1,03956;3817,75685
59,40000;1,04058;3820,98667
59,46000;1,04153;3823,37496
59,52000;1,04243;3824,39010
59,58000;1,04351;3827,05107
59,64000;1,04464;3830,99169
59,70000;1,04560;3833,21680
59,76000;1,04662;3836,09012
59,82000;1,04763;3839,17131
59,88000;1,04865;3841,34836
59,94000;1,04966;3844,81065
60,00000;1,05062;3847,97752
60,06000;1,05158;3849,89046
60,12000;1,05241;3851,23044
60,18000;1,05337;3852,51418
60,24000;1,05451;3856,75691
60,30000;1,05558;3859,88355
60,36000;1,05660;3862,14256
60,42000;1,05762;3865,99004
60,48000;1,05863;3867,97152
60,54000;1,05959;3870,08637
60,60000;1,06061;3872,69966
60,66000;1,06162;3875,86690
60,72000;1,06252;3878,72197
60,78000;1,06342;3880,00533
60,84000;1,06449;3882,02816
60,90000;1,06563;3886,39830
60,96000;1,06658;3889,42808
61,02000;1,06760;3891,61333
61,08000;1,06862;3893,64511
61,14000;1,06957;3897,06977
61,20000;1,07059;3899,04156
61,26000;1,07167;3902,54483
61,32000;1,07268;3905,06759
61,38000;1,07352;3906,98761
61,44000;1,07442;3909,32746
61,50000;1,07555;3911,52538
61,56000;1,07657;3915,59377
61,62000;1,07753;3918,23351
61,68000;1,07854;3920,79316
61,74000;1,07956;3923,00524
61,80000;1,08052;3926,66794
61,86000;1,08159;3929,42503
61,92000;1,08261;3932,15902
61,98000;1,08351;3935,43653
62,04000;1,08440;3936,22033
62,10000;1,08548;3938,85262
62,16000;1,08655;3943,15198
62,22000;1,08757;3945,82003
62,28000;1,08859;3948,13679
62,34000;1,08954;3950,83204
62,40000;1,09056;3953,36114
62,46000;1,09158;3955,70993
62,52000;1,09265;3958,68719
62,58000;1,09361;3961,94011
62,64000;1,09445;3964,07992
62,70000;1,09540;3965,81702
62,76000;1,09654;3968,57597
62,82000;1,09756;3972,66001
62,88000;1,09857;3974,78826
62,94000;1,09953;3977,86498
63,00000;1,10055;3980,36353
63,06000;1,10162;3984,14433
63,12000;1,10264;3988,10543
63,18000;1,10365;3991,05400
63,24000;1,10449;3992,80488
63,30000;1,10539;3994,43135
63,36000;1,10646;3996,60654
63,42000;1,10754;4000,74087
63,48000;1,10856;4003,01106
63,54000;1,10957;4005,98869
63,60000;1,11059;4008,86834
63,66000;1,11161;4011,96703
63,72000;1,11262;4013,70041
63,78000;1,11364;4017,13699
63,84000;1,11460;4019,43736
63,90000;1,11543;4020,90214
63,96000;1,11639;4022,35873
64,02000;1,11759;4026,00430
64,08000;1,11860;4029,48149
64,14000;1,11962;4032,66363
64,20000;1,12063;4035,20092
64,26000;1,12159;4038,39722
64,32000;1,12261;4041,29550
64,38000;1,12362;4043,61822
64,44000;1,12464;4045,66750
64,50000;1,12548;4047,72647
64,56000;1,12637;4050,08867
64,62000;1,12745;4052,01614
64,68000;1,12859;4055,75112
64,74000;1,12954;4059,87650
64,80000;1,13056;4061,74958
64,86000;1,13158;4064,55435
64,92000;1,13253;4067,47907
64,98000;1,13355;4069,55928
65,04000;1,13463;4073,07893
65,10001;1,13558;4075,78982
65,16000;1,13642;4077,09479
65,22000;1,13744;4079,41863
65,28001;1,13827;4082,29791
65,34000;1,13965;4089,31151
65,40000;1,14060;4090,87203
65,46001;1,14162;4093,73119
65,52000;1,14258;4096,66710
65,58000;1,14359;4098,87880
65,64000;1,14461;4101,67798
65,70001;1,14563;4105,55601
65,76000;1,14646;4107,05246
65,82000;1,14736;4107,83663
65,88001;1,14850;4111,44421
65,94000;1,14957;4115,46230
66,00000;1,15047;4117,55294
66,06001;1,15155;4120,54621
66,12000;1,15256;4124,36686
66,18000;1,15352;4127,85597
66,24001;1,15459;4131,85246
66,30000;1,15567;4135,46599
66,36000;1,15657;4140,79279
66,42001;1,15740;4143,77749
66,48000;1,15848;4146,90934
66,54000;1,15962;4153,40699
66,60001;1,16057;4157,50258
66,66000;1,16159;4162,10480
66,72000;1,16255;4167,02293
66,78001;1,16356;4171,49290
66,84001;1,16452;4175,98337
66,90000;1,16560;4181,66704
66,96001;1,16661;4186,20594
67,02001;1,16751;4190,16480
67,08000;1,16841;4194,14863
67,14000;1,16954;4199,13158
67,20001;1,17056;4204,69977
67,26000;1,17158;4209,95019
67,32000;1,17259;4214,23949
67,38001;1,17355;4218,84209
67,44000;1,17433;4224,30262
67,50000;1,17570;4231,54421
67,56001;1,17666;4236,46122
67,62000;1,17749;4240,73599
67,68000;1,17833;4244,20871
67,74001;1,17947;4248,87650
67,80000;1,18060;4254,45400
67,86000;1,18156;4260,05200
67,92001;1,18264;4264,96156
67,98000;1,18359;4269,67591
68,04000;1,18455;4273,79645
68,10001;1,18557;4278,77866
68,16000;1,18664;4283,57534
68,22000;1,18760;4288,30236
68,28001;1,18844;4291,58732
68,34001;1,18939;4295,92840
68,40000;1,19059;4301,93394
68,46001;1,19160;4307,26707
68,52001;1,19256;4311,52247
68,58000;1,19358;4316,87199
68,64001;1,19453;4321,04990
68,70001;1,19555;4326,14498
68,76000;1,19663;4330,93980
68,82000;1,19764;4336,55530
68,88001;1,19848;4340,79915
68,94000;1,19932;4343,77007
69,00000;1,20045;4349,37812
69,06001;1,20159;4355,55875
69,12000;1,20255;4360,73020
69,18000;1,20356;4365,72917
69,24001;1,20458;4371,21391
69,30000;1,20560;4376,31309
69,36000;1,20661;4380,86987
69,42001;1,20769;4386,65152
69,48000;1,20858;4391,45640
69,54000;1,20942;4394,86243
69,60001;1,21044;4399,30856
69,66000;1,21163;4405,44598
69,72000;1,21259;4410,75079
69,78001;1,21355;4414,15757
69,84001;1,21456;4419,56930
69,90000;1,21558;4423,65706
69,96001;1,21660;4428,83708
70,02001;1,21761;4434,51665
70,08000;1,21863;4439,59646
70,14001;1,21947;4443,18764
70,20001;1,22036;4446,39325
70,26000;1,22156;4451,50398
70,32000;1,22264;4456,85126
70,38001;1,22353;4462,34532
70,44000;1,22455;4465,99796
70,50000;1,22556;4470,58603
70,56001;1,22652;4475,61182
70,62000;1,22760;4481,08427
70,68000;1,22861;4486,46098
70,74001;1,22957;4491,82130
70,80000;1,23047;4494,09671
70,86000;1,23142;4498,25339
70,92001;1,23262;4504,58229
70,98000;1,23358;4509,98023
71,04000;1,23453;4513,82473
71,10001;1,23555;4518,53760
71,16000;1,23657;4524,09238
71,22000;1,23758;4529,32566
71,28001;1,23866;4533,99643
71,34001;1,23962;4539,32211
71,40000;1,24051;4543,70603
71,46001;1,24141;4547,14112
71,52001;1,24249;4551,73142
71,58000;1,24356;4558,00369
71,64001;1,24452;4562,65397
71,70001;1,24553;4567,29904
71,76000;1,24655;4572,60460
71,82000;1,24745;4576,93003
71,88001;1,24870;4589,51853
71,94000;1,24960;4593,03744
72,00000;1,25044;4597,02387
72,06001;1,25139;4599,60401
72,12000;1,25253;4605,93514
72,18000;1,25361;4611,11069
72,24001;1,25456;4615,38993
72,30000;1,25558;4620,78862
72,36000;1,25660;4625,32602
72,42001;1,25755;4629,93085
72,48000;1,25857;4634,40940
72,54000;1,25964;4638,76501
72,60001;1,26054;4643,01445
72,66000;1,26144;4646,72409
72,72000;1,26246;4650,69748
72,78001;1,26359;4656,47615
72,84001;1,26455;4661,39540
72,90000;1,26556;4665,85942
72,96001;1,26658;4670,44227
73,02001;1,26760;4675,64128
73,08000;1,26861;4679,98013
73,14001;1,26963;4684,85206
73,20001;1,27065;4688,51551
73,26000;1,27148;4693,46419
73,32000;1,27238;4696,35911
73,38001;1,27340;4700,64208
73,44000;1,27453;4706,63831
73,50000;1,27555;4712,39276
73,56001;1,27657;4716,98381
73,62000;1,27764;4721,43926
73,68000;1,27860;4726,58277
73,74001;1,27961;4731,26210
73,80000;1,28063;4735,55662
73,86000;1,28165;4740,67368
73,92001;1,28248;4744,64446
73,98000;1,28344;4747,92533
74,04000;1,28452;4753,33445
74,10001;1,28559;4759,03638
74,16000;1,28655;4763,69634
74,22000;1,28757;4768,64576
74,28001;1,28858;4772,59718
74,34001;1,28954;4777,71498
74,40000;1,29062;4782,32242
74,46001;1,29163;4787,98524
74,52001;1,29259;4792,33079
74,58000;1,29343;4795,81617
74,64001;1,29444;4799,44758
74,70001;1,29558;4805,11785
74,76000;1,29654;4810,34778
74,82001;1,29755;4814,44113
74,88001;1,29857;4819,33877
74,94000;1,29958;4824,76316
75,00000;1,30054;4828,44189
75,06001;1,30162;4833,26726
75,12000;1,30263;4838,19731
75,18000;1,30347;4842,73732
75,24001;1,30443;4846,21301
75,30000;1,30544;4850,44681
75,36000;1,30670;4860,32031
75,42001;1,30766;4866,16269
75,48000;1,30861;4870,61553
75,54000;1,30957;4874,65188
75,60001;1,31059;4879,24702
75,66000;1,31160;4883,97889
75,72000;1,31262;4888,26148
75,78001;1,31346;4891,61946
75,84001;1,31435;4895,35443
75,90000;1,31549;4900,16490
75,96001;1,31656;4906,27103
76,02001;1,31752;4910,51488
76,08000;1,31854;4914,93493
76,14001;1,31949;4918,81855
76,20001;1,32051;4923,38277
76,26000;1,32153;4928,79897
76,32001;1,32260;4933,57554
76,38001;1,32350;4938,27984
76,44000;1,32440;4941,55474
76,50000;1,32541;4945,98411
76,56001;1,32655;4951,66816
76,62000;1,32757;4956,49837
76,68000;1,32852;4960,94860
76,74001;1,32954;4965,44316
76,80000;1,33056;4970,48236
76,86000;1,33157;4975,31295
76,92001;1,33265;4980,18116
76,98000;1,33360;4984,81356
77,04000;1,33444;4989,14085
77,10001;1,33540;4991,97915
77,16000;1,33653;4997,78315
77,22000;1,33767;5005,07280
77,28001;1,33857;5010,70321
77,34001;1,33958;5014,54100
77,40000;1,34060;5018,45181
77,46001;1,34156;5023,12668
77,47801;1,34186;5024,41563