File: SU - Suspension/test en traction/Courbes/triangles/Specimen_RawData_7.csv
Temps;Déplacement;Charge
(sec);(mm);(N)
0,00000;21,97993;432,76446
0,06000;21,98005;433,21578
0,12000;21,98035;433,52200
0,18000;21,98107;435,21812
0,24000;21,98208;439,23925
0,30000;21,98334;444,95757
0,36000;21,98484;452,09141
0,42000;21,98621;462,21362
0,48000;21,98747;470,67236
0,54000;21,98866;477,63204
0,60000;21,98980;484,40313
0,66000;21,99093;490,00573
0,72000;21,99201;495,77295
0,78000;21,99297;500,62803
0,84000;21,99386;505,35835
0,90000;21,99500;509,92803
0,96000;21,99607;515,28430
1,02000;21,99709;519,87427
1,08000;21,99811;523,78718
1,14000;21,99912;528,40090
1,20000;22,00014;532,19185
1,26000;22,00116;536,03384
1,32000;22,00217;539,40495
1,38000;22,00307;542,83226
1,44000;22,00385;545,12429
1,50000;22,00492;548,44287
1,56000;22,00606;552,37203
1,62000;22,00702;556,34310
1,68000;22,00803;559,65404
1,74000;22,00905;563,66408
1,80000;22,01007;567,23407
1,86000;22,01102;571,00756
1,92000;22,01210;570,90120
1,98000;22,01312;573,96595
2,04000;22,01395;576,04937
2,10000;22,01491;579,01395
2,16000;22,01598;582,68500
2,22000;22,01706;586,97388
2,28000;22,01808;590,09055
2,34000;22,01909;593,93016
2,40000;22,02011;598,36097
2,46000;22,02107;601,76020
2,52000;22,02208;605,57975
2,58000;22,02316;610,74928
2,64000;22,02406;614,64193
2,70000;22,02489;617,84638
2,76000;22,02591;620,21636
2,82000;22,02705;626,40123
2,88000;22,02806;630,90464
2,94000;22,02902;635,38528
3,00000;22,03004;639,36682
3,06000;22,03099;644,07252
3,12000;22,03195;647,97360
3,18000;22,03303;652,03286
3,24000;22,03410;657,76007
3,30000;22,03494;661,60206
3,36000;22,03583;665,17596
3,42000;22,03697;670,21293
3,48000;22,03811;675,73041
3,54000;22,03912;680,27517
3,60000;22,04008;684,00553
3,66000;22,04110;688,12356
3,72000;22,04205;691,91949
3,78000;22,04307;695,78644
3,84000;22,04415;701,11309
3,90000;22,04504;705,79317
3,96000;22,04594;708,62579
4,02000;22,04702;713,29353
4,08000;22,04815;716,41817
4,14000;22,04905;720,27189
4,20000;22,05000;723,65031
4,26000;22,05102;727,86142
4,32000;22,05198;732,95278
4,38000;22,05299;737,01497
4,44000;22,05407;741,81538
4,50000;22,05509;746,16489
4,56000;22,05598;749,47774
4,62000;22,05688;753,51642
4,68000;22,05802;758,24712
4,74000;22,05909;764,06365
4,80000;22,06005;767,05581
4,86000;22,06107;771,80089
4,92000;22,06208;775,91715
4,98000;22,06310;780,12124
5,04000;22,06411;785,11415
5,10000;22,06513;789,47786
5,16000;22,06609;793,92325
5,22000;22,06693;796,43587
5,28000;22,06788;800,74510
5,34000;22,06908;806,12693
5,40000;22,07009;810,55956
5,46000;22,07105;814,60085
5,52000;22,07207;819,01550
5,58000;22,07308;823,68208
5,64000;22,07410;827,56430
5,70000;22,07512;832,04219
5,76000;22,07607;836,68726
5,82000;22,07697;839,83662
5,88000;22,07787;843,65299
5,94000;22,07894;848,27617
6,00000;22,08008;853,08217
6,06000;22,08104;856,95935
6,12000;22,08205;861,48316
6,18000;22,08307;865,67430
6,24000;22,08408;870,08737
6,30000;22,08510;874,93127
6,36000;22,08612;878,72762
6,42000;22,08707;882,65417
6,48000;22,08791;886,31585
6,54000;22,08893;888,99974
6,60000;22,09006;893,74986
6,66000;22,09108;897,98057
6,72000;22,09210;901,39303
6,78000;22,09311;904,95488
6,84000;22,09413;909,44134
6,90000;22,09515;913,38092
6,96000;22,09616;917,64778
7,02000;22,09712;921,60329
7,08000;22,09796;924,46571
7,14000;22,09885;927,61889
7,20000;22,09999;932,40179
7,26000;22,10107;936,16862
7,32000;22,10202;940,03873
7,38000;22,10304;942,75745
7,44000;22,10405;947,50961
7,50000;22,10507;951,38168
7,56000;22,10609;955,94581
7,62000;22,10716;959,70603
7,68000;22,10812;964,46294
7,74000;22,10902;969,76329
7,80000;22,11003;973,27465
7,86000;22,11111;977,52260
7,92000;22,11207;981,57218
7,98000;22,11308;985,60387
8,04000;22,11410;989,46234
8,10000;22,11506;992,81706
8,16000;22,11607;996,99590
8,22000;22,11715;1001,12800
8,28000;22,11811;1005,96901
8,34000;22,11900;1008,77872
8,40000;22,11996;1012,99407
8,46000;22,12110;1017,49245
8,52000;22,12205;1022,42725
8,58000;22,12307;1025,58648
8,64000;22,12408;1029,56640
8,70000;22,12510;1034,27600
8,76000;22,12606;1038,21028
8,82000;22,12707;1041,63634
8,88000;22,12809;1046,19693
8,94000;22,12905;1049,63109
9,00000;22,12988;1053,29966
9,06000;22,13096;1056,47314
9,12000;22,13210;1060,97851
9,18000;22,13305;1065,56443
9,24000;22,13407;1070,03981
9,30000;22,13509;1073,59746
9,36000;22,13604;1077,42818
9,42000;22,13706;1080,90127
9,48000;22,13814;1085,95397
9,54000;22,13915;1091,18596
9,60000;22,13993;1095,76741
9,66000;22,14089;1098,36515
9,72000;22,14202;1103,51164
9,78000;22,14304;1107,38650
9,84000;22,14405;1111,73578
9,90000;22,14507;1115,80342
9,96000;22,14609;1118,83376
10,02000;22,14710;1122,79626
10,08000;22,14812;1127,03638
10,14000;22,14913;1130,99283
10,20000;22,14997;1133,70959
10,26000;22,15087;1135,91449
10,32000;22,15195;1139,15075
10,38000;22,15308;1145,18264
10,44000;22,15410;1149,23250
10,50000;22,15506;1152,18097
10,56000;22,15613;1157,24290
10,62000;22,15709;1160,01647
10,68000;22,15810;1164,00514
10,74000;22,15918;1168,29220
10,80000;22,16008;1171,47146
10,86000;22,16092;1175,36029
10,92000;22,16193;1177,78899
10,98000;22,16307;1181,03391
11,04000;22,16408;1186,14901
11,10000;22,16510;1190,33372
11,16000;22,16612;1194,34493
11,22000;22,16713;1198,16680
11,28000;22,16809;1201,37762
11,34000;22,16910;1205,29821
11,40000;22,17012;1208,64660
11,46000;22,17102;1212,11251
11,52000;22,17192;1214,93889
11,58000;22,17299;1218,41654
11,64000;22,17407;1223,66389
11,70000;22,17508;1226,06065
11,76000;22,17604;1229,91204
11,82000;22,17706;1234,06965
11,88000;22,17807;1238,26368
11,94000;22,17909;1241,94166
12,00000;22,18011;1246,58262
12,06000;22,18112;1249,83471
12,12000;22,18196;1253,11343
12,18000;22,18292;1255,32262
12,24000;22,18405;1259,38300
12,30000;22,18507;1263,93829
12,36000;22,18603;1267,03270
12,42000;22,18680;1271,25634
12,48000;22,18812;1277,41387
12,54000;22,18908;1280,54302
12,60000;22,19015;1284,52275
12,66000;22,19111;1288,45116
12,72000;22,19195;1290,18491
12,78000;22,19290;1293,20603
12,84000;22,19404;1297,84113
12,90000;22,19506;1302,57839
12,96000;22,19601;1305,55658
13,02000;22,19709;1309,21751
13,08000;22,19805;1312,78438
13,14000;22,19906;1316,68355
13,20000;22,20008;1320,17266
13,26000;22,20115;1324,43747
13,32000;22,20205;1328,47987
13,38000;22,20295;1330,22070
13,44000;22,20396;1333,19208
13,50000;22,20510;1338,59906
13,56000;22,20612;1342,56408
13,62000;22,20707;1345,81486
13,68000;22,20809;1348,59178
13,74000;22,20905;1352,68895
13,80000;22,21006;1356,30975
13,86000;22,21108;1360,30996
13,92000;22,21216;1363,93048
13,98000;22,21305;1368,37382
14,04000;22,21395;1370,16894
14,10000;22,21503;1373,53549
14,16000;22,21610;1378,72770
14,22000;22,21706;1382,04340
14,28000;22,21813;1385,44319
14,34000;22,21909;1389,04853
14,40000;22,22011;1392,35761
14,46000;22,22112;1395,08490
14,52000;22,22214;1400,06095
14,58000;22,22310;1403,52091
14,64000;22,22393;1406,80177
14,70000;22,22489;1408,94856
14,76000;22,22579;1413,87573
14,82000;22,22716;1421,60496
14,88000;22,22812;1425,18235
14,94000;22,22907;1428,61065
15,00000;22,23009;1432,02627
15,06000;22,23105;1435,68618
15,12000;22,23213;1438,17458
15,18000;22,23314;1442,68414
15,24000;22,23392;1445,22293
15,30000;22,23487;1448,84950
15,36000;22,23601;1452,45120
15,42000;22,23709;1457,16807
15,48000;22,23804;1460,98984
15,54000;22,23906;1464,17618
15,60000;22,24008;1469,51340
15,66000;22,24109;1472,04269
15,72000;22,24217;1475,39619
15,78000;22,24318;1480,23954
15,84000;22,24402;1483,27388
15,90000;22,24486;1485,60125
15,96000;22,24594;1488,65441
16,02000;22,24707;1494,18563
16,08000;22,24809;1498,19357
16,14000;22,24904;1501,12621
16,20000;22,25006;1505,27488
16,26000;22,25108;1509,79543
16,32000;22,25209;1513,46177
16,38000;22,25317;1517,11376
16,44000;22,25413;1521,27752
16,50000;22,25496;1523,50329
16,56000;22,25586;1525,43681
16,62000;22,25706;1529,49868
16,68000;22,25807;1534,52838
16,74000;22,25909;1538,15206
16,80000;22,26005;1541,21891
16,86000;22,26106;1544,80645
16,92000;22,26208;1548,78888
16,98000;22,26309;1552,56698
17,04000;22,26411;1556,28407
17,10000;22,26501;1559,46231
17,16000;22,26590;1562,12086
17,22000;22,26698;1565,34687
17,28000;22,26812;1570,36372
17,34000;22,26907;1574,28030
17,40000;22,27009;1577,29890
17,46000;22,27111;1581,92627
17,52000;22,27212;1585,14138
17,58000;22,27314;1589,02295
17,64000;22,27416;1593,57134
17,70000;22,27511;1596,18352
17,76000;22,27595;1598,72323
17,82000;22,27697;1601,64032
17,88000;22,27810;1606,46178
17,94000;22,27906;1610,18819
18,00000;22,28008;1613,21945
18,06000;22,28103;1616,39731
18,12000;22,28205;1620,34351
18,18000;22,28312;1624,09022
18,24000;22,28414;1628,09063
18,30000;22,28516;1632,40116
18,36000;22,28599;1635,03550
18,42000;22,28689;1637,12222
18,48000;22,28803;1640,72495
18,54000;22,28910;1645,62725
18,60000;22,29006;1648,81982
18,66000;22,29108;1652,27894
18,72000;22,29209;1656,33932
18,78000;22,29311;1660,07746
18,84000;22,29413;1663,49653
18,90000;22,29514;1668,52027
18,96000;22,29604;1671,11028
19,02000;22,29694;1674,18998
19,08000;22,29801;1677,52896
19,14000;22,29909;1681,47087
19,20000;22,30005;1685,38895
19,26000;22,30106;1688,12145
19,32000;22,30208;1692,82407
19,38000;22,30309;1696,70936
19,44000;22,30411;1700,18263
19,50000;22,30513;1702,77748
19,56000;22,30608;1706,81607
19,62000;22,30698;1709,65977
19,68000;22,30794;1711,98230
19,74000;22,30902;1715,12123
19,80000;22,31009;1720,05128
19,86000;22,31105;1722,75007
19,92000;22,31206;1726,20900
19,98000;22,31308;1730,50612
20,04000;22,31410;1733,70987
20,10000;22,31511;1737,08573
20,16000;22,31613;1740,99728
20,22000;22,31702;1744,14124
20,28000;22,31786;1746,52822
20,34000;22,31882;1748,38267
20,40000;22,32007;1755,69169
20,46000;22,32109;1758,34503
20,52000;22,32211;1762,10646
20,58000;22,32312;1765,31170
20,64000;22,32408;1769,04220
20,70000;22,32510;1772,67846
20,76000;22,32611;1775,54674
20,82000;22,32713;1778,87678
20,88000;22,32797;1782,01906
20,94000;22,32892;1783,80366
21,00000;22,33006;1788,16672
21,06000;22,33108;1792,18873
21,12000;22,33209;1794,80184
21,18000;22,33311;1799,17086
21,24000;22,33412;1802,48749
21,30000;22,33508;1805,06930
21,36000;22,33616;1808,40828
21,42000;22,33717;1811,46208
21,48000;22,33807;1814,67943
21,54000;22,33891;1817,59372
21,60000;22,33998;1820,06266
21,66000;22,34106;1824,29869
21,72000;22,34202;1827,88037
21,78000;22,34309;1831,50526
21,84000;22,34411;1834,84461
21,90000;22,34507;1838,13125
21,96000;22,34614;1841,54715
22,02000;22,34716;1845,12381
22,08000;22,34812;1847,58604
22,14000;22,34895;1850,75887
22,20000;22,34991;1853,14026
22,26000;22,35105;1857,10043
22,32000;22,35206;1860,92146
22,38000;22,35308;1864,26435
22,44000;22,35404;1866,95624
22,50000;22,35505;1869,92362
22,56000;22,35607;1874,12892
22,62000;22,35715;1876,46747
22,68000;22,35816;1880,61502
22,74000;22,35900;1883,89681
22,80000;22,35989;1884,60555
22,86000;22,36097;1888,17009
22,92000;22,36211;1893,22252
22,98000;22,36306;1896,35195
23,04000;22,36408;1899,16063
23,10000;22,36504;1902,94050
23,16000;22,36605;1906,14648
23,22000;22,36707;1909,49049
23,28000;22,36809;1912,38429
23,34000;22,36904;1915,53961
23,40000;22,36994;1918,20059
23,46000;22,37089;1920,57919
23,52000;22,37203;1924,33633
23,58000;22,37305;1928,57031
23,64000;22,37401;1931,62691
23,70000;22,37502;1934,29552
23,76000;22,37610;1937,92265
23,82000;22,37711;1942,59975
23,88000;22,37819;1945,08675
23,94000;22,37921;1948,08226
24,00000;22,38004;1951,59856
24,06000;22,38094;1954,13064
24,12000;22,38202;1956,77597
24,18000;22,38315;1961,82169
24,24000;22,38411;1965,33706
24,30000;22,38507;1968,28768
24,36000;22,38602;1971,46889
24,42000;22,38716;1977,09724
24,48000;22,38811;1980,31608
24,54000;22,38913;1983,99555
24,60000;22,39003;1987,53718
24,66000;22,39092;1989,78800
24,72000;22,39200;1993,23576
24,78000;22,39314;1997,88455
24,84000;22,39409;2001,87955
24,90000;22,39505;2004,27268
24,96000;22,39607;2008,52901
25,02000;22,39708;2011,78342
25,08000;22,39810;2014,59490
25,14000;22,39912;2018,45355
25,20000;22,40013;2021,79942
25,26000;22,40097;2025,28778
25,32000;22,40193;2027,84482
25,38000;22,40306;2031,38459
25,44000;22,40408;2036,44950
25,50000;22,40503;2039,62587
25,56000;22,40611;2043,22170
25,62000;22,40707;2047,10085
25,68000;22,40808;2050,93343
25,74000;22,40910;2054,15096
25,80000;22,41012;2057,99453
25,86000;22,41107;2061,11763
25,92000;22,41191;2064,62815
25,98000;22,41293;2067,65905
26,04000;22,41406;2071,37223
26,10000;22,41502;2076,60086
26,16000;22,41604;2080,01528
26,22000;22,41705;2084,45545
26,28000;22,41801;2087,72141
26,34000;22,41903;2091,88238
26,40000;22,42010;2095,00138
26,46000;22,42112;2099,72970
26,52000;22,42196;2101,85442
26,58000;22,42285;2105,31056
26,64000;22,42405;2109,40838
26,70000;22,42512;2114,34681
26,76000;22,42608;2117,70721
26,82000;22,42710;2120,77443
26,88000;22,42805;2124,49506
26,94000;22,42907;2128,28554
27,00000;22,43009;2132,91645
27,06000;22,43116;2136,53967
27,12000;22,43206;2139,99562
27,18000;22,43290;2142,42525
27,24000;22,43397;2146,89076
27,30000;22,43505;2150,33796
27,36000;22,43607;2155,01655
27,42000;22,43708;2158,43339
27,48000;22,43810;2161,89977
27,54000;22,43906;2166,19000
27,60000;22,44007;2169,16539
27,66000;22,44115;2173,82293
27,72000;22,44211;2177,50128
27,78000;22,44294;2180,63425
27,84000;22,44390;2183,62622
27,90000;22,44503;2186,98643
27,96000;22,44611;2191,83676
28,02000;22,44707;2195,67008
28,08000;22,44815;2199,66043
28,14000;22,44910;2204,90899
28,20000;22,45012;2208,13509
28,26000;22,45113;2211,59700
28,32000;22,45215;2215,35750
28,38000;22,45299;2218,42304
28,44000;22,45388;2221,33640
28,50000;22,45502;2224,15011
28,56000;22,45610;2228,85031
28,62000;22,45705;2233,18525
28,68000;22,45807;2236,94388
28,74000;22,45909;2240,17408
28,80000;22,46004;2243,74011
28,86000;22,46112;2247,11876
28,92000;22,46213;2251,30823
28,98000;22,46309;2255,04003
29,04000;22,46393;2257,82637
29,10000;22,46488;2260,45530
29,16000;22,46608;2265,03517
29,22000;22,46710;2270,07978
29,28000;22,46805;2273,53368
29,34000;22,46907;2276,86763
29,40000;22,47009;2281,61030
29,46000;22,47110;2284,86694
29,52000;22,47218;2288,53710
29,58000;22,47320;2292,45760
29,64000;22,47403;2295,53133
29,70000;22,47493;2297,91980
29,76000;22,47607;2301,13398
29,82000;22,47714;2307,02572
29,88000;22,47810;2310,05363
29,94000;22,47911;2313,81319
30,00000;22,48013;2316,97839
30,06000;22,48109;2320,35089
30,12000;22,48210;2323,90054
30,18000;22,48312;2328,33251
30,24000;22,48408;2332,24258
30,30000;22,48497;2334,66737
30,36000;22,48581;2337,83647
30,42000;22,48713;2344,14171
30,48000;22,48808;2347,52018
30,54000;22,48904;2351,02195
30,60000;22,49005;2354,78394
30,66000;22,49107;2359,04623
30,72000;22,49209;2362,19056
30,78000;22,49317;2366,11348
30,84000;22,49412;2369,42694
30,90000;22,49502;2373,12578
30,96000;22,49598;2375,32351
31,02000;22,49711;2379,28964
31,08000;22,49813;2384,80531
31,14000;22,49908;2387,54507
31,20000;22,50010;2391,24559
31,26000;22,50112;2395,06699
31,32000;22,50213;2399,23578
31,38000;22,50315;2402,30784
31,44000;22,50417;2406,58429
31,50000;22,50500;2409,31194
31,56000;22,50590;2412,79248
31,62000;22,50692;2415,30668
31,68000;22,50811;2420,12274
31,74000;22,50907;2425,05893
31,80000;22,51002;2427,94659
31,86000;22,51104;2430,96557
31,92000;22,51206;2435,77510
31,98000;22,51307;2439,15822
32,04000;22,51409;2442,86153
32,10000;22,51505;2446,77756
32,16000;22,51595;2449,80827
32,22000;22,51690;2453,33817
32,28000;22,51810;2457,16106
32,34000;22,51911;2461,82662
32,40000;22,52007;2465,79293
32,46000;22,52115;2469,82649
32,52000;22,52216;2472,51596
32,58000;22,52312;2476,06207
32,64000;22,52414;2480,33293
32,70000;22,52515;2483,64769
32,76000;22,52605;2487,19696
32,82000;22,52694;2490,29174
32,88000;22,52796;2492,95589
32,94000;22,52910;2497,98112
33,00000;22,53006;2501,87721
33,06000;22,53107;2505,37787
33,12000;22,53203;2509,58502
33,18000;22,53317;2514,83209
33,24000;22,53412;2518,31636
33,30000;22,53514;2522,08989
33,36000;22,53603;2525,41918
33,42000;22,53687;2527,89240
33,48000;22,53789;2531,43627
33,54000;22,53902;2536,47454
33,60000;22,54004;2540,64333
33,66000;22,54112;2543,52633
33,72000;22,54213;2547,96762
33,78000;22,54315;2552,01031
33,84000;22,54411;2554,45223
33,90000;22,54518;2558,41464
33,96000;22,54614;2561,92721
34,02000;22,54704;2565,27774
34,08000;22,54793;2567,84055
34,14000;22,54907;2571,94713
34,20000;22,55009;2576,38730
34,26000;22,55110;2579,04902
34,32000;22,55212;2583,01273
34,38000;22,55308;2586,64638
34,44000;22,55409;2590,76562
34,50000;22,55511;2593,85128
34,56000;22,55612;2597,30909
34,62000;22,55708;2600,92653
34,68000;22,55792;2603,18052
34,74000;22,55894;2606,21775
34,80000;22,56007;2610,86784
34,86000;22,56103;2614,17050
34,92000;22,56204;2618,03269
34,98000;22,56306;2622,28753
35,04000;22,56408;2626,01264
35,10000;22,56503;2629,18249
35,16000;22,56611;2632,39089
35,22000;22,56712;2636,88378
35,28000;22,56796;2639,71630
35,34000;22,56892;2642,15749
35,40000;22,57006;2646,57252
35,46000;22,57113;2650,78302
35,52000;22,57209;2654,23916
35,58000;22,57310;2658,71882
35,64000;22,57412;2661,71135
35,70000;22,57508;2665,53722
35,76000;22,57615;2669,15075
35,82000;22,57717;2673,23311
35,88000;22,57806;2676,47561
35,94000;22,57890;2678,52433
36,00000;22,57992;2681,71448
36,06000;22,58105;2686,74158
36,12000;22,58207;2690,06770
36,18000;22,58309;2694,13870
36,24000;22,58410;2697,68909
36,30000;22,58506;2701,88358
36,36000;22,58608;2706,18275
36,42000;22,58715;2710,20122
36,48000;22,58811;2713,86877
36,54000;22,58895;2715,99106
36,60000;22,58990;2718,43038
36,66000;22,59104;2723,63443
36,72000;22,59212;2727,76261
36,78000;22,59307;2731,65163
36,84000;22,59409;2734,76224
36,90000;22,59511;2739,02360
36,96000;22,59612;2743,68003
37,02000;22,59720;2747,19559
37,08000;22,59816;2750,96316
37,14000;22,59899;2754,89390
37,20000;22,59989;2756,85117
37,26000;22,60097;2759,99531
37,32000;22,60210;2765,03842
37,38000;22,60306;2769,46016
37,44000;22,60407;2772,67210
37,50000;22,60509;2775,84791
37,56000;22,60611;2779,31038
37,62000;22,60706;2783,29067
37,68000;22,60814;2787,30001
37,74000;22,60910;2790,49426
37,80000;22,60993;2794,14319
37,86000;22,61089;2796,18725
37,92000;22,61209;2800,88838
37,98000;22,61310;2805,39524
38,04000;22,61406;2807,86585
38,10000;22,61508;2811,23426
38,16000;22,61609;2815,55392
38,22000;22,61711;2818,55501
38,28000;22,61813;2822,19462
38,34000;22,61914;2826,81994
38,40000;22,62004;2829,96260
38,46000;22,62088;2832,40676
38,52000;22,62195;2835,40599
38,58000;22,62309;2840,23378
38,64000;22,62404;2843,24531
38,70000;22,62506;2847,50313
38,76000;22,62608;2850,63367
38,82000;22,62703;2853,85381
38,88000;22,62805;2857,42283
38,94000;22,62907;2861,45620
39,00000;22,63008;2864,58675
39,06000;22,63098;2868,13136
39,12000;22,63188;2870,11191
39,18000;22,63301;2875,00210
39,24000;22,63409;2879,50132
39,30000;22,63505;2882,86358
39,36000;22,63612;2886,73006
39,42000;22,63714;2890,39537
39,48000;22,63810;2893,36536
39,54000;22,63911;2897,18695
39,60000;22,64019;2900,84220
39,66000;22,64109;2904,20279
39,72000;22,64192;2907,07983
39,78000;22,64300;2909,87007
39,84000;22,64377;2914,97428
39,90000;22,64515;2922,13522
39,96000;22,64611;2924,47023
40,02000;22,64706;2927,74905
40,08000;22,64802;2931,55722
40,14000;22,64904;2934,49592
40,20000;22,65011;2938,54401
40,26000;22,65107;2942,11451
40,32000;22,65197;2944,23979
40,38000;22,65292;2947,30682
40,44000;22,65406;2952,52092
40,50000;22,65508;2955,88933
40,56000;22,65609;2959,55390
40,62000;22,65711;2963,67053
40,68000;22,65807;2967,18311
40,74000;22,65908;2970,10988
40,80000;22,66016;2973,80537
40,86000;22,66117;2977,36842
40,92000;22,66201;2981,07676
40,98000;22,66291;2982,30331
41,04000;22,66398;2985,72928
41,10000;22,66512;2990,84261
41,16000;22,66607;2994,54834
41,22000;22,66709;2998,73520
41,28000;22,66811;3002,40722
41,34000;22,66906;3005,56943
41,40000;22,67008;3009,21164
41,46000;22,67116;3013,30909
41,52000;22,67205;3016,78684
41,58000;22,67289;3020,28414
41,64000;22,67391;3021,82473
41,70000;22,67504;3026,62440
41,76000;22,67606;3030,57060
41,82000;22,67708;3034,75335
41,88000;22,67809;3038,10406
41,94000;22,67905;3042,08044
42,00000;22,68007;3046,05458
42,06000;22,68114;3049,37400
42,12000;22,68216;3053,86502
42,18000;22,68300;3056,09405
42,24000;22,68389;3059,51219
42,30000;22,68497;3063,05848
42,36000;22,68611;3068,16101
42,42000;22,68712;3071,45454
42,48000;22,68808;3075,14817
42,54000;22,68910;3078,32640
42,60000;22,69005;3082,40335
42,66000;22,69107;3085,58811
42,72000;22,69221;3089,65910
42,78000;22,69310;3093,35962
42,84000;22,69394;3096,09007
42,90000;22,69489;3098,52902
42,96000;22,69603;3103,30316
43,02000;22,69711;3108,50646
43,08000;22,69806;3111,97191
43,14000;22,69920;3115,61208
43,20000;22,70010;3123,26159
43,26000;22,70111;3126,27554
43,32000;22,70213;3129,77061
43,38000;22,70303;3133,05706
43,44000;22,70386;3135,69233
43,50000;22,70494;3138,76271
43,56000;22,70614;3143,35674
43,62000;22,70715;3147,57526
43,68000;22,70811;3150,98241
43,74000;22,70906;3154,33890
43,80000;22,71008;3158,08728
43,86000;22,71116;3161,56261
43,92000;22,71218;3164,56631
43,98000;22,71313;3168,31358
44,04000;22,71403;3170,75886
44,10000;22,71486;3174,08405
44,16000;22,71600;3177,65735
44,22000;22,71714;3181,97906
44,28000;22,71809;3186,55111
44,34000;22,71905;3188,81832
44,40000;22,72007;3193,36466
44,46000;22,72108;3196,68837
44,52000;22,72216;3199,96402
44,58000;22,72312;3204,03799
44,64000;22,72407;3206,79843
44,70000;22,72485;3209,44600
44,76000;22,72587;3211,96876
44,82000;22,72706;3216,83325
44,88000;22,72808;3220,96013
44,94000;22,72910;3225,44016
45,00000;22,73005;3229,36364
45,06000;22,73113;3232,39118
45,12000;22,73214;3236,02967
45,18000;22,73316;3239,86895
45,24000;22,73412;3243,12299
45,30000;22,73496;3245,40623
45,36000;22,73591;3247,82617
45,42000;22,73699;3251,68334
45,48000;22,73806;3256,30382
45,54000;22,73902;3259,06463
45,60000;22,74004;3263,37852
45,66000;22,74105;3266,66608
45,72000;22,74207;3270,09521
45,78000;22,74309;3272,75805
45,84000;22,74416;3277,04661
45,90000;22,74506;3279,43265
45,96000;22,74590;3282,46616
46,02000;22,74691;3285,73063
46,08000;22,74805;3288,93550
46,14000;22,74906;3293,66177
46,20000;22,75002;3296,28475
46,26000;22,75104;3299,29329
46,32000;22,75205;3303,71968
46,38000;22,75307;3307,19128
46,44000;22,75415;3311,46307
46,50000;22,75516;3314,29616
46,56000;22,75600;3318,28818
46,62000;22,75690;3319,72092
46,68000;22,75797;3322,72761
46,74000;22,75911;3326,92079
46,80000;22,76006;3331,16204
46,86000;22,76108;3334,48239
46,92000;22,76210;3338,54854
46,98000;22,76311;3341,74298
47,04000;22,76413;3344,35478
47,10000;22,76515;3348,69437
47,16000;22,76610;3351,82920
47,22000;22,76694;3354,48682
47,28000;22,76790;3356,12968
47,34000;22,76903;3360,62424
47,40000;22,77011;3365,00667
47,46000;22,77107;3367,55067
47,52000;22,77148;3370,78013
47,58000;22,77322;3380,00543
47,64000;22,77418;3383,48150
47,70000;22,77513;3385,57586
47,76000;22,77609;3389,09961
47,82000;22,77693;3390,91755
47,88000;22,77794;3394,01215
47,94000;22,77908;3397,57912
48,00000;22,78004;3400,63460
48,06000;22,78105;3403,51239
48,12000;22,78213;3406,68075
48,18000;22,78309;3409,20500
48,24000;22,78410;3412,31376
48,30000;22,78512;3414,99075
48,36000;22,78613;3418,15874
48,42000;22,78703;3421,33008
48,48000;22,78793;3423,01950
48,54000;22,78900;3426,16886
48,60000;22,79008;3430,36242
48,66000;22,79110;3433,99905
48,72000;22,79211;3437,13239
48,78000;22,79307;3439,09226
48,84000;22,79409;3442,12577
48,90000;22,79510;3445,16560
48,96000;22,79612;3447,86830
49,02000;22,79714;3451,31718
49,08000;22,79797;3453,56129
49,14000;22,79887;3455,48019
49,20000;22,80001;3459,64655
49,26000;22,80108;3463,50223
49,32000;22,80210;3466,54616
49,38000;22,80311;3469,34646
49,44000;22,80413;3473,23641
49,50000;22,80509;3475,76849
49,56000;22,80610;3478,23873
49,62000;22,80718;3481,79899
49,68000;22,80808;3485,16665
49,74000;22,80891;3487,50129
49,80000;22,80993;3488,82601
49,86000;22,81107;3493,21291
49,92000;22,81208;3496,68004
49,98000;22,81304;3499,90539
50,04000;22,81412;3503,01601
50,10000;22,81513;3506,21566
50,16000;22,81615;3508,79170
50,22000;22,81716;3511,38227
50,28000;22,81812;3514,82257
50,34000;22,81896;3516,87372
50,40000;22,81985;3519,14838
50,46000;22,82099;3522,21504
50,52000;22,82207;3526,95622
50,58000;22,82308;3530,28588
50,64000;22,82380;3533,27915
50,70000;22,82524;3541,44126
50,76000;22,82619;3543,22009
50,82000;22,82715;3545,96674
50,88000;22,82811;3548,01789
50,94000;22,82900;3550,58759
51,00000;22,82990;3551,82700
51,06000;22,83104;3555,28519
51,12000;22,83211;3559,66575
51,18000;22,83307;3562,22540
51,24000;22,83409;3564,97318
51,30000;22,83510;3568,37772
51,36000;22,83612;3571,33299
51,42000;22,83713;3573,99210
51,48000;22,83815;3577,14109
51,54000;22,83905;3580,01776
51,60000;22,83989;3581,95752
51,66000;22,84090;3583,71213
51,72000;22,84204;3587,18447
51,78000;22,84305;3590,55549
51,84000;22,84401;3593,15500
51,90000;22,84503;3596,26822
51,96000;22,84604;3598,23816
52,02000;22,84706;3601,60321
52,08000;22,84807;3604,81218
52,14000;22,84909;3607,86133
52,20000;22,84999;3610,71154
52,26000;22,85089;3612,71352
52,32000;22,85196;3615,64048
52,38000;22,85310;3619,50062
52,44000;22,85405;3621,94590
52,50000;22,85507;3624,35691
52,56000;22,85609;3627,43959
52,62000;22,85716;3632,58086
52,68000;22,85818;3636,16012
52,74000;22,85914;3638,80396
52,80000;22,86003;3641,07378
52,86000;22,86087;3642,60375
52,92000;22,86195;3644,87097
52,98000;22,86308;3648,26024
53,04000;22,86404;3651,37421
53,10000;22,86506;3653,96738
53,16000;22,86607;3656,86007
53,22000;22,86703;3658,59009
53,28000;22,86805;3661,68432
53,34000;22,86906;3664,02082
53,40000;22,87014;3667,51924
53,46000;22,87098;3669,59609
53,52000;22,87193;3671,26092
53,58000;22,87307;3674,89941
53,64000;22,87409;3678,05026
53,70000;22,87510;3680,59762
53,76000;22,87612;3683,41580
53,82000;22,87713;3685,82010
53,88000;22,87809;3688,32797
53,94000;22,87911;3690,08966
54,00000;22,88018;3693,62682
54,06000;22,88108;3696,08849
54,12000;22,88192;3697,68515
54,18000;22,88269;3699,94640
54,24000;22,88413;3706,01416
54,30000;22,88508;3707,34558
54,36000;22,88610;3710,53480
54,42000;22,88712;3712,63735
54,48000;22,88807;3715,00365
54,54000;22,88909;3717,21275
54,60000;22,89011;3720,38372
54,66000;22,89106;3722,54066
54,72000;22,89190;3724,16787
54,78000;22,89286;3725,64159
54,84000;22,89405;3728,74476
54,90000;22,89507;3732,33370
54,96000;22,89609;3734,69815
55,02000;22,89710;3737,18254
55,08000;22,89806;3739,96869
55,14000;22,89908;3742,22547
55,20000;22,90015;3745,50559
55,26000;22,90117;3747,21885
55,32000;22,90201;3749,13365
55,38000;22,90290;3751,16430
55,44000;22,90398;3753,91245
55,50000;22,90512;3757,62880
55,56000;22,90607;3760,00293
55,62000;22,90709;3762,01086
55,68000;22,90810;3764,70275
55,74000;22,90906;3767,27395
55,80000;22,91014;3770,23444
55,86000;22,91115;3772,83506
55,92000;22,91211;3774,95028
55,98000;22,91295;3775,87527
56,04000;22,91390;3778,08884
56,10000;22,91504;3781,44756
56,16000;22,91606;3784,28623
56,22000;22,91707;3785,25071
56,28000;22,91809;3788,88696
56,34000;22,91911;3790,17331
56,40000;22,92012;3793,63224
56,46000;22,92114;3795,63235
56,52000;22,92215;3798,51982
56,58000;22,92299;3800,51397
56,64000;22,92389;3801,06270
56,70000;22,92502;3803,93229
56,76000;22,92616;3807,95337
56,82000;22,92712;3811,23722
56,88000;22,92807;3813,04957
56,94000;22,92909;3815,70272
57,00000;22,93011;3818,45385
57,06000;22,93118;3820,21219
57,12000;22,93220;3822,45444
57,18000;22,93310;3824,58121
57,24000;22,93393;3826,03221
57,30000;22,93495;3827,52866
57,36000;22,93609;3830,92239
57,42000;22,93704;3833,77969
57,48000;22,93800;3835,10813
57,54000;22,93902;3838,13456
57,60000;22,94003;3840,24121
57,66000;22,94105;3842,22567
57,72000;22,94213;3845,34299
57,78000;22,94308;3847,61393
57,84000;22,94398;3849,55369
57,90000;22,94488;3850,88995
57,96000;22,94601;3854,15889
58,02000;22,94709;3856,15565
58,08000;22,94804;3858,82445
58,14000;22,94906;3861,12444
58,20000;22,95008;3864,25331
58,26000;22,95109;3865,99302
58,32000;22,95211;3867,87690
58,38000;22,95313;3870,74314
58,44000;22,95408;3872,90679
58,50000;22,95498;3874,14433
58,56000;22,95600;3875,41093
58,62000;22,95713;3878,43773
58,68000;22,95809;3880,75672
58,74000;22,95911;3882,91851
58,80000;22,96012;3885,01547
58,86000;22,96108;3887,91114
58,92000;22,96210;3889,21127
58,98000;22,96311;3892,37627
59,04000;22,96389;3894,31193
59,10000;22,96496;3898,15308
59,16000;22,96592;3898,95365
59,22000;22,96706;3901,55986
59,28000;22,96807;3904,75169
59,34000;22,96909;3906,62886
59,40000;22,97011;3908,56527
59,46000;22,97106;3910,87271
59,52000;22,97214;3911,87631
59,58000;22,97316;3914,62632
59,64000;22,97417;3916,56421
59,70000;22,97501;3918,44921
59,76000;22,97591;3919,29857
59,82000;22,97698;3921,63247
59,88000;22,97812;3925,14914
59,94000;22,97913;3927,14888
60,00000;22,98015;3928,49483
60,06000;22,98111;3930,82537
60,12000;22,98212;3933,27810
60,18000;22,98308;3934,97944
60,24000;22,98416;3937,49736
60,30000;22,98511;3939,33542
60,36000;22,98595;3940,55508
60,42000;22,98691;3941,81050
60,48000;22,98804;3944,34370
60,54000;22,98906;3946,67871
60,60000;22,99007;3949,44660
60,66000;22,99109;3951,77864
60,72000;22,99205;3953,13874
60,78000;22,99306;3955,19696
60,84000;22,99408;3956,79288
60,90000;22,99516;3958,91964
60,96000;22,99605;3961,25764
61,02000;22,99695;3960,98569
61,08000;22,99797;3963,42054
61,14000;22,99910;3966,81130
61,20000;23,00006;3968,27236
61,26000;23,00108;3970,97059
61,32000;23,00209;3972,39253
61,38000;23,00311;3974,32484
61,44000;23,00407;3976,52164
61,50000;23,00514;3978,21553
61,56000;23,00610;3980,03198
61,62000;23,00694;3981,70315
61,68000;23,00789;3982,46720
61,74000;23,00903;3985,15984
61,80000;23,01011;3988,11698
61,86000;23,01100;3989,98857
61,92000;23,01208;3993,79656
61,98000;23,01309;3995,34889
62,04000;23,01411;3996,46498
62,10000;23,01513;3997,92083
62,16000;23,01614;4000,93384
62,22000;23,01698;4001,69566
62,28000;23,01788;4001,87783
62,34000;23,01895;4004,26164
62,40000;23,02009;4007,30446
62,46000;23,02111;4008,81134
62,52000;23,02212;4010,81443
62,58000;23,02308;4012,90096
62,64000;23,02410;4014,86047
62,70000;23,02511;4016,84530
62,76000;23,02619;4019,24439
62,82000;23,02709;4020,61306
62,88000;23,02792;4020,56910
62,94000;23,02894;4022,79645
63,00000;23,03008;4024,44415
63,06000;23,03109;4027,59314
63,12000;23,03205;4029,23934
63,18000;23,03306;4031,06995
63,24000;23,03408;4033,32077
63,30000;23,03510;4035,06234
63,36000;23,03611;4036,84452
63,42000;23,03713;4038,75113
63,48000;23,03797;4040,37982
63,54000;23,03886;4040,61787
63,60000;23,04000;4042,64368
63,66000;23,04114;4045,53711
63,72000;23,04203;4047,92801
63,78000;23,04305;4049,26650
63,84000;23,04413;4050,80840
63,90000;23,04508;4053,59827
63,96000;23,04610;4055,33426
64,02000;23,04712;4057,35224
64,08000;23,04807;4058,45046
64,14000;23,04897;4059,75021
64,20000;23,04998;4061,78273
64,26000;23,05112;4064,53237
64,32000;23,05208;4067,29802
64,38000;23,05303;4067,75065
64,44000;23,05405;4070,03053
64,50000;23,05507;4072,28023
64,56000;23,05608;4073,66455
64,62000;23,05710;4075,98875
64,68000;23,05812;4078,14234
64,74000;23,05901;4080,00834
64,80000;23,05991;4080,59135
64,86000;23,06110;4086,35549
64,92000;23,06212;4089,65573
64,98000;23,06308;4090,20521
65,04000;23,06409;4092,86991
65,10001;23,06511;4095,28129
65,16000;23,06607;4096,51436
65,22000;23,06714;4098,35875
65,28001;23,06816;4100,58945
65,34000;23,06906;4102,50314
65,40000;23,06995;4103,28917
65,46001;23,07097;4105,00877
65,52000;23,07211;4107,97596
65,58000;23,07306;4109,78384
65,64000;23,07408;4112,60799
65,70001;23,07510;4114,08357
65,76000;23,07605;4116,48192
65,82000;23,07707;4117,79135
65,88001;23,07815;4120,25005
65,94000;23,07910;4122,50459
66,00000;23,07994;4124,00514
66,06001;23,08090;4124,85972
66,12000;23,08203;4127,02002
66,18000;23,08311;4130,08891
66,24001;23,08406;4131,62299
66,30000;23,08508;4134,18338
66,36000;23,08604;4135,19293
66,42001;23,08700;4137,29623
66,48000;23,08801;4139,75790
66,54000;23,08909;4142,99481
66,60001;23,09004;4144,84702
66,66000;23,09088;4146,07748
66,72000;23,09196;4147,29342
66,78001;23,09309;4150,57763
66,84001;23,09411;4153,01695
66,90000;23,09513;4155,01595
66,96001;23,09608;4157,73243
67,02001;23,09710;4160,44965
67,08000;23,09812;4162,29479
67,14000;23,09919;4164,93528
67,20001;23,10015;4167,04006
67,26000;23,10093;4167,83430
67,32000;23,10188;4169,14970
67,38001;23,10302;4171,91051
67,44000;23,10409;4174,80767
67,50000;23,10505;4176,56675
67,56001;23,10613;4178,37873
67,62000;23,10714;4184,09146
67,68000;23,10810;4184,91401
67,74001;23,10912;4187,00241
67,80000;23,11013;4189,41826
67,86000;23,11097;4191,39490
67,92001;23,11187;4191,42470
67,98000;23,11300;4193,92772
68,04000;23,11408;4197,40789
68,10001;23,11510;4200,05806
68,16000;23,11611;4201,91251
68,22000;23,11713;4203,11838
68,28001;23,11809;4206,23869
68,34001;23,11916;4207,68075
68,40000;23,12018;4210,35364
68,46001;23,12107;4211,90113
68,52001;23,12191;4213,49406
68,58000;23,12299;4215,04192
68,64001;23,12412;4217,32403
68,70001;23,12508;4219,90640
68,76000;23,12604;4222,29320
68,82000;23,12705;4223,72743
68,88001;23,12807;4226,39064
68,94000;23,12909;4228,30209
69,00000;23,13016;4231,03496
69,06001;23,13112;4234,61795
69,12000;23,13196;4235,52059
69,18000;23,13291;4236,57931
69,24001;23,13405;4240,00248
69,30000;23,13507;4242,80949
69,36000;23,13608;4244,51232
69,42001;23,13704;4246,38167
69,48000;23,13812;4248,37619
69,54000;23,13907;4250,61472
69,60001;23,14009;4253,17325
69,66000;23,14116;4255,27915
69,72000;23,14206;4256,42468
69,78001;23,14296;4258,22809
69,84001;23,14403;4259,60533
69,90000;23,14517;4263,35931
69,96001;23,14613;4264,96454
70,02001;23,14708;4266,75268
70,08000;23,14810;4268,44805
70,14001;23,14911;4271,44244
70,20001;23,15013;4273,10318
70,26000;23,15115;4275,73845
70,32000;23,15210;4278,24073
70,38001;23,15294;4278,97051
70,44000;23,15396;4280,38314
70,50000;23,15504;4283,71131
70,56001;23,15605;4286,15957
70,62000;23,15707;4288,11535
70,68000;23,15808;4292,45457
70,74001;23,15910;4294,16560
70,80000;23,16012;4297,32986
70,86000;23,16113;4298,84829
70,92001;23,16209;4301,47760
70,98000;23,16299;4302,45362
71,04000;23,16394;4303,70085
71,10001;23,16502;4306,42776
71,16000;23,16609;4309,79580
71,22000;23,16711;4311,47516
71,28001;23,16813;4313,79937
71,34001;23,16914;4316,53373
71,40000;23,17010;4317,85434
71,46001;23,17112;4320,17520
71,52001;23,17213;4322,34667
71,58000;23,17303;4324,08303
71,64001;23,17393;4325,18683
71,70001;23,17494;4327,42424
71,76000;23,17608;4331,25421
71,82000;23,17710;4333,41041
71,88001;23,17805;4334,46690
71,94000;23,17907;4337,44341
72,00000;23,18009;4339,61526
72,06001;23,18110;4341,64591
72,12000;23,18212;4344,12770
72,18000;23,18308;4346,66127
72,24001;23,18397;4347,35119
72,30000;23,18493;4349,36769
72,36000;23,18600;4351,45125
72,42001;23,18708;4355,31326
72,48000;23,18804;4357,11928
72,54000;23,18911;4359,37233
72,60001;23,19013;4361,69356
72,66000;23,19115;4363,61209
72,72000;23,19216;4366,83223
72,78001;23,19318;4368,32048
72,84001;23,19396;4371,05969
72,90000;23,19497;4373,10040
72,96001;23,19599;4375,04835
73,02001;23,19707;4378,48233
73,08000;23,19808;4380,37068
73,14001;23,19910;4382,29665
73,20001;23,20012;4384,85071
73,26000;23,20107;4387,26135
73,32000;23,20209;4389,04278
73,38001;23,20311;4390,89462
73,44000;23,20406;4392,93049
73,50000;23,20496;4395,35975
73,56001;23,20592;4396,47548
73,62000;23,20705;4399,04332
73,68000;23,20807;4401,73112
73,74001;23,20908;4403,14971
73,80000;23,21010;4405,78498
73,86000;23,21106;4408,89336
73,92001;23,21207;4409,59781
73,98000;23,21315;4412,11723
74,04000;23,21417;4414,67613
74,10001;23,21506;4416,58013
74,16000;23,21596;4417,42986
74,22000;23,21698;4419,43333
74,28001;23,21811;4422,97384
74,34001;23,21907;4425,04548
74,40000;23,22009;4427,03627
74,46001;23,22110;4430,01129
74,52001;23,22206;4432,14215
74,58000;23,22308;4433,55478
74,64001;23,22415;4435,04192
74,70001;23,22511;4438,03333
74,76000;23,22595;4439,86207
74,82001;23,22690;4441,16145
74,88001;23,22804;4443,33814
74,94000;23,22905;4446,23679
75,00000;23,23007;4448,22758
75,06001;23,23103;4450,70490
75,12000;23,23204;4452,90469
75,18000;23,23306;4455,70722
75,24001;23,23414;4457,97853
75,30000;23,23515;4459,26711
75,36000;23,23605;4461,53581
75,42001;23,23689;4462,45261
75,48000;23,23790;4464,07385
75,54000;23,23916;4469,39729
75,60001;23,24011;4473,33381
75,66000;23,24113;4475,09289
75,72000;23,24215;4477,38506
75,78001;23,24310;4479,36170
75,84001;23,24412;4481,40427
75,90000;23,24514;4483,55228
75,96001;23,24603;4485,71630
76,02001;23,24693;4486,77316
76,08000;23,24795;4487,70784
76,14001;23,24902;4490,78344
76,20001;23,25004;4494,01885
76,26000;23,25106;4495,43670
76,32001;23,25207;4497,80263
76,38001;23,25309;4499,90630
76,44000;23,25410;4501,58007
76,50000;23,25512;4504,64003
76,56001;23,25614;4506,56302
76,62000;23,25698;4509,32309
76,68000;23,25787;4508,94311
76,74001;23,25901;4511,73708
76,80000;23,26014;4514,61598
76,86000;23,26110;4516,82024
76,92001;23,26212;4519,09676
76,98000;23,26313;4521,63480
77,04000;23,26409;4524,37103
77,10001;23,26511;4526,01500
77,16000;23,26612;4527,71783
77,22000;23,26708;4530,73159
77,28001;23,26792;4531,06910
77,34001;23,26893;4532,93249
77,40000;23,26983;4536,25843
77,46001;23,27115;4541,14601
77,52001;23,27210;4542,96134
77,58000;23,27306;4545,07843
77,64001;23,27408;4546,29660
77,70001;23,27509;4549,06076
77,76000;23,27611;4551,72174
77,82001;23,27712;4554,44753
77,88001;23,27796;4555,04246
77,94000;23,27892;4556,21518
78,00000;23,28006;4558,67276
78,06001;23,28107;4562,03073
78,12000;23,28203;4563,20271
78,18000;23,28310;4566,10546
78,24001;23,28406;4568,34547
78,30000;23,28508;4570,05352
78,36000;23,28609;4571,98545
78,42001;23,28717;4574,13904
78,48000;23,28807;4576,51243
78,54000;23,28890;4577,26195
78,60001;23,28998;4579,48558
78,66000;23,29106;4582,60588
78,72000;23,29207;4585,20800
78,78001;23,29309;4587,01588
78,84001;23,29411;4589,57329
78,90000;23,29506;4590,46774
78,96001;23,29608;4593,53924
79,02001;23,29709;4595,19960
79,08000;23,29811;4596,61148
79,14001;23,29895;4598,19064
79,20001;23,29991;4598,30761
79,26000;23,30098;4601,02968
79,32001;23,30212;4604,78663
79,38001;23,30307;4606,52001
79,44000;23,30409;4608,91686
79,50000;23,30511;4610,13131
79,56001;23,30606;4611,85127
79,62000;23,30708;4613,64202
79,68000;23,30816;4616,71390
79,74001;23,30911;4618,48937
79,80000;23,30995;4619,09920
79,86000;23,31097;4620,61241
79,92001;23,31222;4627,02066
79,98000;23,31318;4631,35242
80,04000;23,31414;4632,68347
80,10001;23,31509;4633,71202
80,16000;23,31605;4635,29192
80,22000;23,31713;4637,42949
80,28001;23,31814;4640,01745
80,34001;23,31898;4641,52358
80,40000;23,31987;4641,57909
80,46001;23,32095;4642,95447
80,52001;23,32203;4646,15338
80,58000;23,32304;4648,01490
80,64001;23,32412;4649,73636
80,70001;23,32508;4651,86350
80,76000;23,32609;4653,53802
80,82001;23,32705;4654,99796
80,88001;23,32812;4656,95299
80,94000;23,32914;4659,49140
81,00001;23,32998;4660,16792
81,06001;23,33088;4660,81761
81,12000;23,33201;4662,60873
81,18000;23,33309;4665,58263
81,24001;23,33404;4667,01090
81,30000;23,33512;4669,42489
81,36000;23,33608;4671,17652
81,42001;23,33709;4674,21077
81,48000;23,33817;4676,00785
81,54000;23,33919;4679,05924
81,60001;23,34002;4681,66061
81,66000;23,34092;4683,78589
81,72000;23,34200;4685,78897
81,78001;23,34313;4690,99209
81,84001;23,34409;4694,48827
81,90000;23,34505;4697,42604
81,96001;23,34606;4701,00082
82,02001;23,34702;4704,59051
82,08000;23,34804;4708,05205
82,14001;23,34911;4711,49497
82,20001;23,35013;4716,43582
82,26000;23,35096;4720,29261
82,32001;23,35186;4723,29818
82,38001;23,35306;4727,35018
82,44000;23,35413;4733,18882
82,50001;23,35509;4736,76957
82,56001;23,35611;4740,69603
82,62000;23,35712;4744,15384
82,68000;23,35808;4748,53814
82,74001;23,35910;4752,97607
82,80000;23,36011;4756,70025
82,86000;23,36101;4760,31825
82,92001;23,36191;4762,92893
82,98000;23,36298;4766,85986
83,04000;23,36418;4773,62275
83,10001;23,36513;4777,98954
83,16000;23,36609;4782,49900
83,22000;23,36711;4785,01804
83,28001;23,36807;4788,97877
83,34001;23,36914;4792,48278
83,40000;23,37016;4797,36477
83,46001;23,37106;4800,14347
83,52001;23,37195;4803,04919
83,58000;23,37291;4806,27790
83,64001;23,37405;4811,45456
83,70001;23,37506;4817,20939
83,76000;23,37602;4819,70869
83,82001;23,37703;4823,99613
83,88001;23,37805;4828,27462
83,94000;23,37913;4832,50022
84,00001;23,38014;4837,33192
84,06001;23,38110;4841,39696
84,12000;23,38200;4844,69980
84,18000;23,38289;4846,42610
84,24001;23,38397;4850,21360
84,30000;23,38510;4856,08056
84,36000;23,38606;4860,18248
84,42001;23,38708;4864,14172
84,48000;23,38815;4868,57742
84,54000;23,38911;4873,10737
84,60001;23,39013;4875,93301
84,66000;23,39114;4879,69816
84,72000;23,39204;4883,58624
84,78001;23,39294;4886,22598
84,84001;23,39395;4889,60370
84,90000;23,39503;4893,76560
84,96001;23,39605;4898,36708
85,02001;23,39706;4901,82266
85,08000;23,39814;4906,37869
85,14001;23,39910;4910,79092
85,20001;23,40011;4914,25805
85,26000;23,40113;4918,26087
85,32001;23,40215;4923,63125
85,38001;23,40298;4927,22690
85,44000;23,40394;4930,09053
85,50001;23,40507;4934,29527
85,56001;23,40609;4939,03197
85,62000;23,40705;4941,88592
85,68000;23,40806;4946,47473
85,74001;23,40908;4950,57516
85,80000;23,41015;4954,71768
85,86000;23,41117;4958,19114
85,92001;23,41213;4962,15783
85,98000;23,41303;4965,65364
86,04000;23,41386;4969,45605
86,10001;23,41494;4972,19376
86,16000;23,41608;4977,27580
86,22000;23,41709;4981,11211
86,28001;23,41811;4985,07060
86,34001;23,41912;4988,58504
86,40000;23,42008;4993,27779
86,46001;23,42110;4996,41337
86,52001;23,42211;5000,24073
86,58000;23,42313;5004,49985
86,64001;23,42397;5007,94873
86,70001;23,42493;5010,91294
86,76000;23,42606;5015,07334
86,82001;23,42708;5020,61807
86,88001;23,42809;5023,63518
86,94000;23,42911;5027,14291
87,00001;23,43007;5031,24781
87,01801;23,43036;5032,28046