File: SU - Suspension/test en traction/Courbes/triangles/Specimen_RawData_4.csv
Temps;Déplacement;Charge
(sec);(mm);(N)
0;0,00001;190,58214
0,06;0,00006;190,79903
0,12;0,00036;191,4568
0,18;0,00132;194,5832
0,24;0,00275;203,83724
0,3;0,00413;215,01386
0,36;0,00532;224,92495
0,42;0,00658;232,86822
0,48;0,00777;241,9058
0,54;0,00885;249,57091
0,6;0,00987;255,47903
0,66;0,01094;262,97139
0,72;0,01196;268,64891
0,78;0,01297;276,30772
0,84;0,01405;283,06504
0,9;0,01495;289,88281
0,96;0,01584;295,00038
1,02;0,01692;301,11617
1,08;0,018;308,22961
1,14;0,01895;314,22405
1,2;0,01997;319,39989
1,26;0,02099;324,32261
1,32;0,022;330,33607
1,38;0,02296;336,81763
1,44;0,02398;341,98402
1,5;0,02499;348,13711
1,56;0,02589;352,96252
1,62;0,02685;357,87909
1,68;0,02792;364,22336
1,74;0,02894;369,50237
1,8;0,02995;374,60467
1,86;0,03097;379,44675
1,92;0,03199;382,79849
1,98;0,03294;381,37122
2,04;0,03396;350,24581
2,1;0,03504;350,17149
2,16;0,03593;355,03618
2,22;0,03683;359,34437
2,28;0,03791;364,88995
2,34;0,03904;372,3576
2,4;0,04;379,4678
2,46;0,04102;385,26391
2,52;0,04203;390,76493
2,58;0,04305;396,5186
2,64;0,04401;402,55273
2,7;0,04502;408,68293
2,76;0,04604;414,34905
2,82;0,04687;419,8906
2,88;0,04783;425,31095
2,94;0,04897;431,18112
3;0,05004;438,1848
3,06;0,051;444,59491
3,12;0,05202;450,24832
3,18;0,05297;456,02969
3,24;0,05399;461,36561
3,3;0,05501;467,04784
3,36;0,05602;473,10409
3,42;0,05698;479,62759
3,48;0,05782;483,87758
3,54;0,05877;489,94138
3,6;0,06003;496,55545
3,66;0,06105;503,85389
3,72;0,06206;509,40569
3,78;0,06308;515,42968
3,84;0,06403;520,94487
3,9;0,06499;526,28815
3,96;0,06607;532,10924
4,02;0,06708;538,46687
4,08;0,06792;543,12823
4,14;0,06882;548,04818
4,2;0,06989;553,46699
4,26;0,07103;560,53125
4,32;0,07199;567,25079
4,38;0,073;572,70448
4,44;0,07396;576,84281
4,5;0,07498;583,11657
4,56;0,07599;588,59028
4,62;0,07707;594,42846
4,68;0,07803;599,87013
4,74;0,07886;604,35403
4,8;0,07982;609,36725
4,86;0,08101;615,88394
4,92;0,08203;621,29032
4,98;0,08299;625,60458
5,04;0,08394;630,9737
5,1;0,08496;636,05355
5,16;0,08598;641,61164
5,22;0,08699;646,76753
5,28;0,08807;652,55594
5,34;0,08897;657,29525
5,4;0,08986;661,80439
5,46;0,09094;666,59166
5,52;0,09202;668,77324
5,58;0,09297;667,81901
5,64;0,09399;672,73076
5,7;0,09501;678,3966
5,76;0,09602;682,97228
5,82;0,09704;689,45955
5,88;0,09805;694,77749
5,94;0,09901;699,26889
6;0,09985;703,5424
6,06;0,10081;709,11176
6,12;0,102;714,08991
6,18;0,10302;719,61405
6,24;0,10397;724,94452
6,3;0,10499;729,16015
6,36;0,10601;734,50003
6,42;0,10714;743,86653
6,48;0,1081;751,59073
6,54;0,109;755,39206
6,6;0,10983;758,54128
6,66;0,11091;763,37252
6,72;0,11205;768,73414
6,78;0,113;773,54433
6,84;0,11402;778,06972
6,9;0,11503;782,73984
6,96;0,11599;786,89139
7,02;0,11701;791,23462
7,08;0,11802;795,54021
7,14;0,11904;800,56656
7,2;0,11994;804,23178
7,26;0,12083;808,37524
7,32;0,12197;812,80638
7,38;0,12305;818,23934
7,44;0,124;821,90121
7,5;0,12502;826,07931
7,56;0,12604;830,65946
7,62;0,12699;834,19178
7,68;0,12795;838,79912
7,74;0,12903;842,06527
7,8;0,12998;846,24859
7,86;0,13082;849,51483
7,92;0,13184;852,9529
7,98;0,13297;857,1784
8,04;0,13405;862,28857
8,1;0,13506;866,45344
8,16;0,13602;870,31703
8,22;0,13704;873,57173
8,28;0,13799;876,80453
8,34;0,13901;880,62715
8,4;0,14009;885,28246
8,46;0,14092;887,6211
8,52;0,14176;890,92376
8,58;0,14302;895,30954
8,64;0,14409;900,11964
8,7;0,14499;903,14327
8,76;0,14601;905,35972
8,82;0,14702;908,66918
8,88;0,14798;911,36489
8,94;0,14906;914,31607
9;0,15013;917,77379
9,06;0,15103;920,13199
9,12;0,15187;921,15737
9,18;0,15288;923,10542
9,24;0,15402;925,247
9,3;0,15497;928,09265
9,36;0,15593;929,07986
9,42;0,15695;931,8864
9,48;0,15796;933,15849
9,54;0,15898;935,30016
9,6;0,16006;936,83945
9,66;0,16107;938,99705
9,72;0,16191;939,39202
9,78;0,16281;939,90732
9,84;0,16388;940,75641
9,9;0,16502;942,34049
9,96;0,16604;943,9514
10,02;0,16699;944,84007
10,08;0,16801;945,94359
10,14;0,16902;947,49574
10,2;0,17004;948,01495
10,26;0,17106;949,44183
10,32;0,17201;950,09701
10,38;0,17285;950,3969
10,44;0,17387;950,71411
10,5;0,175;951,74443
10,56;0,17602;952,52385
10,62;0,17698;952,98262
10,68;0,17799;953,66398
10,74;0,17901;954,13961
10,8;0,17997;954,87004
10,86;0,18104;955,89589
10,92;0,18206;956,46251
10,98;0,18296;956,4193
11,04;0,18385;956,0043
11,1;0,18493;956,3108
11,16;0,18606;957,7848
11,22;0,18702;958,12371
11,28;0,18804;959,98971
11,34;0,18899;960,0414
11,4;0,19007;960,32219
11,46;0,19109;961,23312
11,52;0,1921;960,16023
11,58;0,19306;961,33929
11,64;0,19384;961,27642
11,7;0,19485;960,43423
11,76;0,19599;962,30945
11,82;0,19701;964,06657
11,88;0,19796;965,48907
11,94;0,19904;967,32499
12;0,2;970,29656
12,06;0,20101;973,41491
12,12;0,20197;977,60316
12,18;0,20305;982,61591
12,24;0,20394;986,25422
12,3;0,20484;989,65149
12,36;0,20597;994,50089
12,42;0,20705;1001,07938
12,48;0,20801;1005,34335
12,54;0,20902;1010,83731
12,6;0,21004;1016,31386
12,66;0,211;1020,6881
12,72;0,21207;1028,66571
12,78;0,21309;1032,48106
12,84;0,21399;1037,59598
12,9;0,21488;1040,87098
12,96;0,2159;1046,19162
13,02;0,21704;1052,22752
13,08;0,21799;1056,79967
13,14;0,21901;1061,69526
13,2;0,22003;1066,30437
13,26;0,22098;1071,81296
13,32;0,222;1075,82444
13,38;0,22301;1081,54304
13,44;0,22397;1086,9151
13,5;0,22487;1090,38083
13,56;0,22582;1094,53965
13,62;0,22696;1100,86296
13,68;0,22804;1106,4318
13,74;0,22899;1110,67137
13,8;0,23001;1115,01096
13,86;0,23103;1119,72429
13,92;0,23198;1125,15446
13,98;0,23306;1129,43808
14,04;0,23408;1133,57762
14,1;0,23497;1138,32224
14,16;0,23587;1141,76031
14,22;0,23689;1145,98842
14,28;0,23802;1152,13189
14,34;0,23904;1156,77342
14,4;0,24005;1161,50565
14,46;0,24107;1166,14206
14,52;0,24203;1170,11881
14,58;0,24298;1174,92331
14,64;0,24406;1178,66388
14,7;0,24502;1183,37851
14,76;0,24591;1187,85137
14,82;0,24681;1190,58937
14,88;0,24795;1194,86675
14,94;0,24896;1201,01348
15;0,24998;1207,79108
15,06;0,251;1211,77845
15,12;0,25201;1216,21899
15,18;0,25303;1220,23504
15,24;0,25405;1223,9188
15,3;0,25506;1229,02896
15,36;0,25596;1233,52557
15,42;0,25686;1235,51479
15,48;0,25793;1240,42984
15,54;0,25907;1245,92176
15,6;0,26002;1249,78386
15,66;0,26104;1253,83567
15,72;0,26206;1258,22183
15,78;0,26307;1262,11569
15,84;0,26403;1266,49095
15,9;0,26505;1269,5808
15,96;0,266;1274,00383
16,02;0,2669;1276,74146
16,08;0,26786;1280,03443
16,14;0,26899;1285,10911
16,2;0,27001;1290,13797
16,26;0,27097;1293,11727
16,32;0,27198;1297,30394
16,38;0,273;1301,19054
16,44;0,2739;1304,70255
16,5;0,27503;1309,98679
16,56;0,27605;1313,87664
16,62;0,27694;1317,50926
16,68;0,27778;1319,69815
16,74;0,27892;1323,2246
16,8;0,27999;1328,60597
16,86;0,28095;1332,09014
16,92;0,28197;1335,84375
16,98;0,28298;1338,75916
17,04;0,284;1342,36086
17,1;0,28502;1346,19642
17,16;0,28603;1349,77298
17,22;0,28705;1353,19801
17,28;0,28789;1355,83188
17,34;0,28884;1358,33621
17,4;0,28998;1362,69247
17,46;0,291;1366,31634
17,52;0,29201;1370,26366
17,58;0,29303;1373,87263
17,64;0,29398;1376,71223
17,7;0,295;1379,71416
17,76;0,29602;1383,23326
17,82;0,29703;1386,59384
17,88;0,29793;1389,6971
17,94;0,29883;1391,7827
18;0,2999;1394,63777
18,06;0,30104;1399,30723
18,12;0,302;1402,60281
18,18;0,30301;1404,76553
18,24;0,30403;1408,7352
18,3;0,30499;1410,85936
18,36;0,306;1414,64937
18,42;0,30708;1418,2169
18,48;0,3081;1421,0715
18,54;0,30893;1422,69731
18,6;0,30989;1425,14873
18,66;0,31102;1428,18782
18,72;0,31204;1431,3437
18,78;0,31306;1434,8357
18,84;0,31401;1437,38138
18,9;0,31503;1439,43168
18,96;0,31599;1442,38109
19,02;0,31706;1445,42549
19,08;0,31808;1448,23166
19,14;0,31898;1450,66399
19,2;0,31981;1452,01962
19,26;0,32083;1454,47655
19,32;0,32203;1457,11489
19,38;0,32304;1460,89941
19,44;0,324;1462,95829
19,5;0,32502;1465,5889
19,56;0,32597;1468,67558
19,62;0,32699;1470,03653
19,68;0,32806;1473,52852
19,74;0,32908;1476,5474
19,8;0,32992;1479,38291
19,86;0,33082;1479,4264
19,92;0,33195;1482,48971
19,98;0,33303;1486,74399
20,04;0,33404;1488,57934
20,1;0,33506;1490,85009
20,16;0,33602;1493,51396
20,22;0,33703;1495,39616
20,28;0,33805;1498,07306
20,34;0,33907;1500,21967
20,4;0,33996;1502,58895
20,46;0,3408;1502,57684
20,52;0,34182;1504,9817
20,58;0,34301;1508,11085
20,64;0,34397;1510,94776
20,7;0,34499;1513,92631
20,76;0,346;1515,51925
20,82;0,34696;1517,38133
20,88;0,34797;1519,95914
20,94;0,34905;1522,6
21;0,35007;1524,90567
21,06;0,3509;1525,91029
21,12;0,35186;1526,97396
21,18;0,353;1529,16675
21,24;0,35401;1532,38727
21,3;0,35503;1534,32786
21,36;0,35605;1536,51582
21,42;0,35706;1538,65498
21,48;0,35802;1540,13084
21,54;0,3591;1542,17258
21,6;0,36011;1545,11901
21,66;0,36101;1546,2161
21,72;0,36185;1547,46305
21,78;0,36292;1549,74656
21,84;0,36406;1552,60758
21,9;0,36501;1554,47843
21,96;0,36597;1556,72366
22,02;0,36699;1558,33075
22,08;0,368;1561,41268
22,14;0,36902;1564,11026
22,2;0,3701;1566,40373
22,26;0,37105;1568,4789
22,32;0,37189;1569,79971
22,38;0,37285;1570,28604
22,44;0,37398;1573,30614
22,5;0,375;1575,85833
22,56;0,37596;1576,97536
22,62;0,37697;1579,08518
22,68;0,37799;1581,78825
22,74;0,37901;1584,27861
22,8;0,38008;1586,48156
22,86;0,3811;1588,57126
22,92;0,38194;1590,1085
22,98;0,38283;1590,89006
23,04;0,38391;1593,18447
23,1;0,38504;1596,01662
23,16;0,386;1597,57715
23,22;0,38702;1599,74974
23,28;0,38803;1601,265
23,34;0,38905;1603,83843
23,4;0,39001;1605,35928
23,46;0,39049;1607,8718
23,52;0,39204;1617,80007
23,58;0,39294;1618,36501
23,64;0,39401;1619,36153
23,7;0,39497;1621,04852
23,76;0,39599;1622,21566
23,82;0,397;1624,68906
23,88;0,39802;1625,88544
23,94;0,39904;1627,59908
24;0,40005;1629,07299
24,06;0,40107;1631,23626
24,12;0,40196;1632,94785
24,18;0,40286;1633,20564
24,24;0,40394;1635,24617
24,3;0,40501;1638,26793
24,36;0,40603;1639,56787
24,42;0,40705;1641,66838
24,48;0,40806;1643,78323
24,54;0,40908;1645,94259
24,6;0,4101;1647,54242
24,66;0,41105;1650,52786
24,72;0,41201;1652,07945
24,78;0,41285;1652,41063
24,84;0,4138;1653,5731
24,9;0,41494;1655,85335
24,96;0,41602;1658,94572
25,02;0,41697;1661,50127
25,08;0,41805;1663,6597
25,14;0,419;1665,06246
25,2;0,42002;1667,85456
25,26;0,42104;1669,98673
25,32;0,42205;1672,15932
25,38;0,42295;1674,71673
25,44;0,42385;1675,91646
25,5;0,42492;1677,65431
25,56;0,42606;1681,05979
25,62;0,42702;1682,99396
25,68;0,42803;1683,52146
25,74;0,42905;1686,24986
25,8;0,43001;1688,73407
25,86;0,43108;1689,82241
25,92;0,4321;1692,98146
25,98;0,43306;1694,35162
26,04;0,43389;1696,09822
26,1;0,43491;1697,03327
26,16;0,43598;1700,46315
26,22;0,43694;1702,67802
26,28;0,43796;1705,02607
26,34;0,43897;1707,1655
26,4;0,43999;1709,27197
26,46;0,44101;1710,70676
26,52;0,44202;1713,21947
26,58;0,44304;1715,96929
26,64;0,44394;1717,709
26,7;0,44489;1719,69011
26,76;0,44597;1722,07523
26,82;0,44705;1724,92862
26,88;0,448;1726,88551
26,94;0,44902;1728,83049
27;0,45004;1730,67842
27,06;0,45105;1732,92309
27,12;0,45207;1735,08115
27,18;0,45308;1737,00824
27,24;0,45404;1738,46558
27,3;0,45488;1739,9963
27,36;0,45584;1740,75998
27,42;0,45703;1744,59275
27,48;0,45805;1747,15687
27,54;0,459;1749,07353
27,6;0,46002;1752,02955
27,66;0,46098;1753,30434
27,72;0,46193;1754,77378
27,78;0,46295;1756,91731
27,84;0,46403;1759,64367
27,9;0,46492;1761,49551
27,96;0,46576;1762,18636
28,02;0,46684;1764,23192
28,08;0,46797;1769,05803
28,14;0,46899;1772,18001
28,2;0,47001;1773,70533
28,26;0,47102;1775,9867
28,32;0,47198;1777,67668
28,38;0,47305;1780,46618
28,44;0,47413;1781,77431
28,5;0,47503;1783,99719
28,56;0,47586;1784,44795
28,62;0,47688;1785,86729
28,68;0,47802;1788,85665
28,74;0,47903;1792,23884
28,8;0,48005;1793,60751
28,86;0,48107;1796,12935
28,92;0,48208;1798,13355
28,98;0,48304;1799,31205
29,04;0,48406;1801,94154
29,1;0,48507;1804,4468
29,16;0,48591;1805,56327
29,22;0,48681;1805,99466
29,28;0,48794;1808,16408
29,34;0,48902;1811,53454
29,4;0,48997;1813,10717
29,46;0,49099;1815,49471
29,52;0,49201;1817,41267
29,58;0,49302;1818,78265
29,64;0,49404;1821,45219
29,7;0,49512;1823,8809
29,76;0,49601;1825,656
29,82;0,49685;1825,91639
29,88;0,49787;1827,33722
29,94;0,499;1830,49794
30;0,50002;1833,46793
30,06;0,50098;1835,51703
30,12;0,50205;1837,07513
30,18;0,50301;1840,45285
30,24;0,50403;1842,1242
30,3;0,50504;1844,12245
30,36;0,50606;1846,56493
30,42;0,50696;1847,86189
30,48;0,50785;1849,28626
30,54;0,50893;1850,57912
30,6;0,51;1854,63317
30,66;0,51096;1855,73325
30,72;0,51198;1857,63855
30,78;0,51299;1859,79232
30,84;0,51395;1862,78559
30,9;0,51497;1864,69015
30,96;0,51598;1866,88974
31,02;0,517;1868,85837
31,08;0,5179;1869,79566
31,14;0,51885;1871,52568
31,2;0,51999;1874,6959
31,26;0,52101;1877,65416
31,32;0,52196;1878,91405
31,38;0,52298;1880,95123
31,44;0,524;1883,15846
31,5;0,52495;1885,95597
31,56;0,52603;1887,04282
31,62;0,5271;1890,0536
31,68;0,528;1891,05924
31,74;0,52884;1892,72668
31,8;0,52991;1893,52743
31,86;0,53099;1897,67964
31,92;0,53201;1899,46145
31,98;0,53302;1901,12162
32,04;0,53398;1902,4685
32,1;0,535;1904,44347
32,16;0,53601;1907,17112
32,22;0,53703;1908,69868
32,28;0,53805;1910,92771
32,34;0,53888;1911,70033
32,4;0,53984;1913,00698
32,46;0,54098;1916,0917
32,52;0,54205;1918,45484
32,58;0,54307;1920,92508
32,64;0,54408;1922,61022
32,7;0,54504;1924,75058
32,76;0,546;1926,12745
32,82;0,54707;1928,42185
32,88;0,54809;1930,53354
32,94;0,54899;1931,9538
33;0,54982;1932,88084
33,06;0,5509;1934,95061
33,12;0,55204;1938,33169
33,18;0,55299;1940,20234
33,24;0,55401;1942,9408
33,3;0,55503;1944,70603
33,36;0,55598;1945,65281
33,42;0,557;1948,14373
33,48;0,55808;1950,33941
33,54;0,55903;1951,4991
33,6;0,55987;1953,57539
33,66;0,56083;1954,1759
33,72;0,56196;1956,67166
33,78;0,56178;1960,1576
33,84;0,56423;1972,88617
33,9;0,56507;1973,35109
33,96;0,56597;1972,4438
34,02;0,5671;1974,50407
34,08;0,56806;1975,7323
34,14;0,5689;1977,21049
34,2;0,56979;1977,08067
34,26;0,57093;1979,01428
34,32;0,57207;1981,98035
34,38;0,57302;1983,66009
34,44;0,57404;1986,71408
34,5;0,57506;1987,70668
34,56;0,57601;1988,91126
34,62;0,57703;1990,95346
34,68;0,5781;1993,4414
34,74;0,579;1995,52421
34,8;0,57984;1995,83191
34,86;0,58091;1997,31495
34,92;0,58205;2000,07763
34,98;0,58301;2001,72048
35,04;0,58402;2002,7183
35,1;0,58498;2004,78453
35,16;0,586;2006,36331
35,22;0,58701;2008,38465
35,28;0,58809;2011,43865
35,34;0,58911;2012,67451
35,4;0,59;2014,65208
35,46;0,5909;2015,00989
35,52;0,59198;2017,39091
35,58;0,59305;2020,30912
35,64;0,59401;2021,94303
35,7;0,59497;2023,67511
35,76;0,59598;2025,30436
35,82;0,597;2027,41455
35,88;0,59807;2029,09037
35,94;0,59909;2030,99735
36;0,59999;2032,77431
36,06;0,60088;2034,10052
36,12;0,60184;2034,86122
36,18;0,60298;2037,43782
36,24;0,60405;2040,59444
36,3;0,60501;2042,28181
36,36;0,60603;2043,54096
36,42;0,60704;2045,49059
36,48;0,608;2047,43743
36,54;0,60902;2048,90352
36,6;0,61009;2051,95043
36,66;0,61099;2054,49853
36,72;0,61189;2056,25929
36,78;0,61296;2057,09971
36,84;0,61404;2060,50668
36,9;0,61499;2061,73845
36,96;0,61601;2064,04384
37,02;0,61703;2065,71221
37,08;0,61804;2067,12708
37,14;0,61906;2069,45203
37,2;0,62008;2071,5123
37,26;0,62103;2073,19036
37,32;0,62187;2073,7892
37,38;0,62289;2075,03513
37,44;0,62402;2077,57894
37,5;0,62504;2080,5344
37,56;0,62594;2082,64403
37,62;0,62701;2084,56293
37,68;0,62803;2085,84052
37,74;0,62905;2088,07755
37,8;0,63006;2090,00614
37,86;0,63108;2091,4454
37,92;0,63192;2092,57361
37,98;0,63281;2093,01915
38,04;0,63395;2094,6892
38,1;0,63502;2099,09268
38,16;0,63604;2100,92347
38,22;0,63706;2102,81368
38,28;0,63807;2104,88122
38,34;0,63909;2107,42895
38,4;0,64005;2108,03989
38,46;0,64106;2109,94184
38,52;0,64196;2111,62008
38,58;0,64292;2112,32062
38,64;0,64393;2113,79062
38,7;0,64501;2115,48172
38,76;0,64597;2118,72458
38,82;0,64704;2120,8087
38,88;0,64806;2123,07665
38,94;0,64901;2123,81128
39;0,65003;2125,13227
39,06;0,65105;2127,58351
39,12;0,65206;2129,75703
39,18;0,6529;2130,80626
39,24;0,65386;2131,39001
39,3;0,65499;2133,28023
39,36;0,65601;2135,55954
39,42;0,65697;2136,61268
39,48;0,65798;2138,37866
39,54;0,65894;2140,17536
39,6;0,66002;2145,47701
39,66;0,66109;2146,73858
39,72;0,66205;2148,42502
39,78;0,66295;2149,39509
39,84;0,66384;2149,4519
39,9;0,66492;2151,55501
39,96;0,666;2154,0476
40,02;0,66701;2155,19518
40,08;0,66797;2156,00934
40,14;0,66898;2157,22974
40,2;0,67;2159,37942
40,26;0,67102;2160,81087
40,32;0,67203;2162,56306
40,38;0,67299;2164,21597
40,44;0,67383;2164,64791
40,5;0,67484;2165,11097
40,56;0,67598;2167,54414
40,62;0,677;2170,12186
40,68;0,67801;2170,96806
40,74;0,67897;2172,26613
40,8;0,67999;2173,98647
40,86;0,681;2174,74084
40,92;0,68202;2177,4061
40,98;0,68309;2179,34083
41,04;0,68393;2180,8045
41,1;0,68483;2180,77395
41,16;0,68596;2182,72954
41,22;0,68704;2186,00873
41,28;0,688;2187,16711
41,34;0,68901;2188,21596
41,4;0,69003;2190,49416
41,46;0,69105;2191,52868
41,52;0,69206;2192,69283
41,58;0,69308;2193,45726
41,64;0,69398;2196,21919
41,7;0,69487;2195,83102
41,76;0,69589;2197,37217
41,82;0,69703;2199,87147
41,88;0,69804;2202,18021
41,94;0,699;2203,17654
42;0,70002;2205,17237
42,06;0,70103;2206,45368
42,12;0,70199;2207,96131
42,18;0,703;2209,26199
42,24;0,70384;2211,48971
42,3;0,70492;2214,2021
42,36;0,70587;2213,74501
42,42;0,70701;2217,11881
42,48;0,70803;2219,19101
42,54;0,70898;2220,77966
42,6;0,71;2222,35247
42,66;0,71102;2223,23425
42,72;0,71203;2224,46397
42,78;0,71305;2226,38622
42,84;0,71407;2227,31996
42,9;0,71496;2228,30512
42,96;0,71586;2229,07439
43,02;0,71688;2230,1618
43,08;0,71801;2232,88909
43,14;0,71897;2235,36305
43,2;0,71999;2236,49349
43,26;0,721;2238,28312
43,32;0,72202;2239,33328
43,38;0,72297;2241,00873
43,44;0,72399;2243,30369
43,5;0,72501;2244,67982
43,56;0,72584;2245,1615
43,62;0,7268;2245,96597
43,68;0,72794;2247,50116
43,74;0,72895;2250,00158
43,8;0,72997;2251,8415
43,86;0,73099;2253,86415
43,92;0,732;2254,8683
43,98;0,73302;2256,13639
44,04;0,73404;2258,40285
44,1;0,73511;2259,64412
44,16;0,73601;2260,59519
44,22;0,73685;2260,94034
44,28;0,73786;2261,57047
44,34;0,739;2264,34339
44,4;0,74001;2265,79458
44,46;0,74097;2268,25643
44,52;0,74199;2269,2157
44,58;0,743;2270,40574
44,64;0,74396;2272,30638
44,7;0,74504;2273,38728
44,76;0,74605;2275,2719
44,82;0,74695;2276,04378
44,88;0,74785;2276,67671
44,94;0,74892;2278,00496
45;0,75;2280,62365
45,06;0,75096;2281,38361
45,12;0,75197;2283,20137
45,18;0,75293;2284,98224
45,24;0,75401;2286,88847
45,3;0,75502;2289,84728
45,36;0,75604;2291,77773
45,42;0,75688;2292,79846
45,48;0,75777;2291,90178
45,54;0,75891;2293,71171
45,6;0,76004;2296,31569
45,66;0,761;2297,09744
45,72;0,76202;2298,39738
45,78;0,76297;2299,97095
45,84;0,76399;2300,77785
45,9;0,76501;2302,08822
45,96;0,76608;2303,79924
46,02;0,76698;2305,33481
46,08;0,76788;2305,15264
46,14;0,76889;2305,35045
46,2;0,77003;2308,06079
46,26;0,77105;2309,55146
46,32;0,772;2310,31179
46,38;0,77296;2311,46216
46,44;0,77397;2312,4529
46,5;0,77493;2313,4999
46,56;0,77601;2315,34056
46,62;0,77702;2316,62132
46,68;0,77792;2317,82254
46,74;0,77882;2317,54314
46,8;0,77995;2318,60913
46,86;0,78103;2321,94532
46,92;0,78199;2322,45624
46,98;0,783;2323,97728
47,04;0,78402;2325,34129
47,1;0,78498;2325,41133
47,16;0,78599;2326,6647
47,22;0,78707;2328,22057
47,28;0,78803;2328,55696
47,34;0,78886;2328,67301
47,4;0,78988;2329,24465
47,46;0,79101;2331,91196
47,52;0,79203;2333,696
47,58;0,79305;2333,83831
47,64;0,79406;2336,22007
47,7;0,79502;2336,55795
47,76;0,79604;2337,21063
47,82;0,79705;2339,44952
47,88;0,79801;2340,16143
47,94;0,79891;2340,6066
48;0,79986;2340,78113
48,06;0,80094;2342,1295
48,12;0,80208;2344,64481
48,18;0,80303;2345,56478
48,24;0,80399;2346,15989
48,3;0,80501;2347,8508
48,36;0,80602;2349,56276
48,42;0,80704;2351,52375
48,48;0,80811;2353,248
48,54;0,80901;2355,25444
48,6;0,80991;2356,67881
48,66;0,81092;2357,46279
48,72;0,81206;2361,23744
48,78;0,81302;2364,18173
48,84;0,81397;2366,03618
48,9;0,81499;2369,35429
48,96;0,81607;2370,92637
49,02;0,81708;2374,02469
49,08;0,8181;2376,68939
49,14;0,81906;2379,53141
49,2;0,81995;2381,5902
49,26;0,82079;2383,20492
49,32;0,82193;2386,5778
49,38;0,823;2391,35232
49,44;0,82402;2395,72544
49,5;0,82504;2397,32265
49,56;0,82605;2400,48505
49,62;0,82707;2403,03278
49,68;0,82808;2406,55262
49,74;0,82904;2408,65462
49,8;0,82994;2411,4633
49,86;0,83083;2412,72971
49,92;0,83191;2415,1491
49,98;0,83299;2418,58996
50,04;0,834;2421,92
50,1;0,83502;2424,40049
50,16;0,83604;2426,56879
50,22;0,83705;2429,52444
50,28;0,83807;2431,88478
50,34;0,83909;2435,03358
50,4;0,84004;2437,87915
50,46;0,84094;2439,51231
50,52;0,84184;2440,84988
50,58;0,84297;2444,7104
50,64;0,84399;2447,84765
50,7;0,84495;2450,31025
50,76;0,84596;2452,64433
50,82;0,84698;2455,91328
50,88;0,84799;2458,57332
50,94;0,84901;2460,90386
51;0,85003;2463,68069
51,06;0,85092;2466,6477
51,12;0,85182;2467,83029
51,18;0,8529;2470,35939
51,24;0,85403;2473,47187
51,3;0,85499;2477,19157
51,36;0,85607;2480,3251
51,42;0,85708;2482,39562
51,48;0,85804;2485,44104
51,54;0,85906;2486,96748
51,6;0,86007;2489,71023
51,66;0,86103;2492,36468
51,72;0,86193;2493,44166
51,78;0,86288;2495,30654
51,84;0,86402;2498,36352
51,9;0,86503;2501,36554
51,96;0,86599;2504,19714
52,02;0,86701;2506,71562
52,08;0,86802;2508,86194
52,14;0,86898;2511,28618
52,2;0,87;2513,76331
52,26;0,87107;2516,16109
52,32;0,87197;2519,47455
52,38;0,87287;2519,43804
52,44;0,87394;2522,03587
52,5;0,87502;2526,00387
52,56;0,87598;2529,12231
52,62;0,87699;2531,14384
52,68;0,87801;2533,7588
52,74;0,87897;2535,81777
52,8;0,87998;2538,74622
52,86;0,88106;2541,07323
52,92;0,88201;2543,99739
52,98;0,88285;2545,34204
53,04;0,88393;2548,37926
53,1;0,88506;2551,99298
53,16;0,88602;2554,63663
53,22;0,88704;2556,8448
53,28;0,88799;2558,62568
53,34;0,88901;2561,44889
53,4;0,89003;2563,83941
53,46;0,89104;2565,87472
53,52;0,89206;2568,8339
53,58;0,8929;2570,13366
53,64;0,89379;2571,1054
53,7;0,89493;2573,8623
53,76;0,89601;2578,23691
53,82;0,89696;2580,46724
53,88;0,89798;2582,42935
53,94;0,89899;2584,55761
54;0,89995;2587,25025
54,06;0,90097;2589,4016
54,12;0,90204;2592,03706
54,18;0,90294;2594,4557
54,24;0,90384;2596,01343
54,3;0,90485;2597,88595
54,36;0,90605;2602,08808
54,42;0,90701;2605,08265
54,48;0,90802;2606,93859
54,54;0,9091;2608,85041
54,6;0,91012;2611,50151
54,66;0,91107;2614,69521
54,72;0,91209;2616,65434
54,78;0,91305;2618,392
54,84;0,91388;2620,56142
54,9;0,91484;2621,22992
54,96;0,91597;2625,1018
55,02;0,91705;2629,00181
55,08;0,91801;2630,40494
55,14;0,91902;2633,84078
55,2;0,92004;2635,81313
55,26;0,92106;2639,03383
55,32;0,92207;2641,48545
55,38;0,92303;2645,65628
55,44;0,92393;2647,81546
55,5;0,92482;2648,37537
55,56;0,92596;2651,31481
55,62;0,92704;2655,01682
55,68;0,92799;2656,87685
55,74;0,92901;2659,47394
55,8;0,93003;2662,45306
55,86;0,93104;2664,52786
55,92;0,93206;2666,85057
55,98;0,93307;2669,86918
56,04;0,93403;2671,9952
56,1;0,93487;2673,19307
56,16;0,93588;2675,05608
56,22;0,93696;2678,55916
56,28;0,93798;2681,48985
56,34;0,93899;2684,09085
56,4;0,94001;2686,47186
56,46;0,94097;2689,10844
56,52;0,94198;2690,89621
56,58;0,943;2694,58164
56,64;0,94402;2696,55902
56,7;0,94491;2699,44295
56,76;0,94581;2700,25693
56,82;0,94689;2702,08288
56,88;0,94796;2705,96985
56,94;0,94892;2708,59338
57;0,94994;2711,11988
57,06;0,95101;2713,58714
57,12;0,95197;2716,97659
57,18;0,95298;2718,58089
57,24;0,95406;2722,34045
57,3;0,95502;2724,89712
57,36;0,95591;2725,715
57,42;0,95693;2727,42044
57,48;0,95807;2731,45568
57,54;0,95908;2734,74827
57,6;0,96004;2736,65451
57,66;0,961;2738,72837
57,72;0,96201;2741,05221
57,78;0,96297;2743,03015
57,84;0,96405;2746,14301
57,9;0,96506;2748,69334
57,96;0,96596;2751,28949
58,02;0,96686;2752,48606
58,08;0,96793;2755,66075
58,14;0,96901;2759,19698
58,2;0,97002;2761,05925
58,26;0,97104;2763,82081
58,32;0,972;2766,71275
58,38;0,97295;2768,6812
58,44;0,97403;2771,4178
58,5;0,97511;2774,2574
58,56;0,976;2777,12476
58,62;0,97684;2777,94786
58,68;0,97786;2779,19974
58,74;0,97911;2784,28532
58,8;0,98013;2789,71661
58,86;0,98115;2791,65935
58,92;0,9821;2793,26271
58,98;0,98306;2795,23637
59,04;0,98402;2797,47453
59,1;0,98509;2800,14127
59,16;0,98605;2803,33199
59,22;0,98689;2804,17856
59,28;0,98784;2804,62727
59,34;0,98898;2809,19019
59,4;0,98999;2811,47156
59,46;0,99095;2813,70897
59,52;0,99197;2816,36994
59,58;0,99298;2818,71893
59,64;0,99394;2820,81757
59,7;0,99502;2823,53275
59,76;0,99603;2826,85645
59,82;0,99693;2828,92715
59,88;0,99777;2829,87542
59,94;0,9989;2831,50319
60;1,00004;2835,83868
60,06;1,001;2838,6699
60,12;1,00201;2840,61525
60,18;1,00303;2843,9099
60,24;1,00404;2846,2166
60,3;1,00506;2848,60786
60,36;1,00614;2851,75666
60,42;1,00709;2854,36716
60,48;1,00787;2856,3248
60,54;1,00889;2857,33491
60,6;1,01002;2861,00488
60,66;1,01104;2864,57539
60,72;1,012;2866,81652
60,78;1,01301;2870,00109
60,84;1,01403;2873,27841
60,9;1,01499;2876,95434
60,96;1,01606;2880,40787
61,02;1,01708;2884,94062
61,08;1,01792;2888,56514
61,14;1,01881;2892,4413
61,2;1,02001;2897,94132
61,26;1,02108;2904,64349
61,32;1,02198;2909,04641
61,38;1,023;2913,28169
61,44;1,02401;2917,74087
61,5;1,02503;2921,89158
61,56;1,02611;2926,70038
61,62;1,02712;2931,41939
61,68;1,02802;2936,07358
61,74;1,02892;2939,39952
61,8;1,02993;2943,30604
61,86;1,03107;2949,05156
61,92;1,03203;2954,70972
61,98;1,03298;2958,70826
62,04;1,034;2964,09186
62,1;1,03502;2967,71321
62,16;1,03603;2972,88746
62,22;1,03705;2978,10063
62,28;1,03807;2982,19603
62,34;1,0389;2987,12328
62,4;1,0398;2990,32535
62,46;1,04088;2994,31104
62,52;1,04201;3000,81726
62,58;1,04297;3006,05949
62,64;1,04398;3010,60043
62,7;1,045;3014,95586
62,76;1,04602;3019,98369
62,82;1,04703;3024,89512
62,88;1,04805;3029,5413
62,94;1,04901;3034,09118
63;1,0499;3038,07054
63,06;1,05092;3041,7826
63,12;1,052;3047,84346
63,18;1,05301;3053,46567
63,24;1,05403;3057,31017
63,3;1,05505;3062,26797
63,36;1,05606;3067,20342
63,42;1,05702;3072,62521
63,48;1,05803;3076,57775
63,54;1,05905;3081,88163
63,6;1,05995;3085,90848
63,66;1,06084;3089,38473
63,72;1,06192;3093,93406
63,78;1,063;3100,91879
63,84;1,06395;3105,50202
63,9;1,06497;3110,52185
63,96;1,06605;3115,1209
64,02;1,067;3121,20132
64,08;1,06808;3124,85807
64,14;1,0691;3130,40465
64,2;1,06999;3135,77093
64,26;1,07083;3139,07452
64,32;1,07185;3142,87022
64,38;1,07304;3148,57662
64,44;1,074;3153,91198
64,5;1,07507;3158,05636
64,56;1,07609;3163,17119
64,62;1,07705;3167,89076
64,68;1,07806;3172,63566
64,74;1,07908;3176,82549
64,8;1,08004;3180,9967
64,86;1,08093;3186,28773
64,92;1,08183;3189,65428
64,98;1,08297;3194,82982
65,04;1,08398;3200,08025
65,10001;1,085;3204,32633
65,16;1,08596;3208,83952
65,22;1,08697;3214,17302
65,28001;1,08799;3218,30735
65,34;1,08901;3223,30929
65,4;1,09002;3227,78486
65,46001;1,09098;3233,172
65,52;1,09188;3236,75387
65,58;1,09289;3240,31971
65,64;1,09397;3246,37219
65,70001;1,09498;3251,45349
65,76;1,096;3255,7819
65,82;1,09696;3259,90357
65,88001;1,09803;3265,68857
65,94;1,09899;3269,79421
66;1,10007;3274,64752
66,06001;1,10108;3279,61892
66,12;1,10192;3284,5974
66,18;1,10282;3287,56087
66,24001;1,10395;3292,04127
66,3;1,10503;3298,44728
66,36;1,10599;3303,38106
66,42001;1,107;3308,02463
66,48;1,10802;3312,92599
66,54;1,10898;3317,62731
66,60001;1,10999;3322,47131
66,66;1,11107;3327,16145
66,72;1,11196;3331,99762
66,78001;1,11286;3336,03546
66,84001;1,11388;3339,91013
66,9;1,11501;3345,7607
66,96001;1,11603;3351,22719
67,02001;1,11705;3355,97619
67,08;1,11806;3360,61195
67,14;1,11902;3365,58148
67,20001;1,12004;3369,78137
67,26;1,12105;3374,71142
67,32;1,12213;3380,09633
67,38001;1,12297;3384,4661
67,44;1,12386;3387,92503
67,5;1,12494;3391,96548
67,56001;1,12602;3398,64008
67,62;1,12697;3402,42237
67,68;1,12799;3407,68546
67,74001;1,12906;3411,04418
67,8;1,13002;3416,93312
67,86;1,13104;3420,84058
67,92001;1,13205;3425,58734
67,98;1,13301;3430,43022
68,04;1,13385;3434,27844
68,10001;1,1348;3437,34585
68,16;1,13594;3443,38678
68,22;1,13702;3449,05257
68,28001;1,13797;3453,30387
68,34001;1,13899;3458,6709
68,4;1,14001;3462,87563
68,46001;1,14102;3467,99083
68,52001;1,14204;3472,17768
68,58;1,14306;3476,64952
68,64001;1,14395;3481,13514
68,70001;1,14485;3483,7544
68,76;1,14593;3488,79807
68,82;1,14706;3494,97683
68,88001;1,14802;3500,15797
68,94;1,14897;3504,2569
69;1,14999;3509,07631
69,06001;1,15101;3513,98289
69,12;1,15202;3518,77324
69,18;1,1531;3523,64443
69,24001;1,15406;3527,8853
69,3;1,15489;3531,63294
69,36;1,15585;3535,87568
69,42001;1,15699;3541,33286
69,48;1,158;3548,73687
69,54;1,15896;3552,09485
69,60001;1,15998;3556,75444
69,66;1,16099;3561,16332
69,72;1,16201;3566,29081
69,78001;1,16303;3570,73955
69,84001;1,16404;3575,85028
69,9;1,165;3580,52142
69,96001;1,16584;3583,75981
70,02001;1,16685;3588,32031
70,08;1,16799;3593,90751
70,14001;1,169;3598,68631
70,20001;1,16996;3603,4368
70,26;1,17098;3608,39963
70,32;1,17199;3613,5383
70,38001;1,17301;3618,37335
70,44;1,17403;3622,80235
70,5;1,17504;3627,71414
70,56001;1,17594;3631,2934
70,62;1,17684;3634,73967
70,68;1,17797;3640,06683
70,74001;1,17905;3646,13794
70,8;1,18001;3650,34081
70,86;1,18096;3654,58764
70,92001;1,18198;3659,72854
70,98;1,18294;3664,18399
71,04;1,18395;3667,92642
71,10001;1,18503;3673,98672
71,16;1,18598;3679,08217
71,22;1,18688;3682,3459
71,28001;1,1879;3685,6439
71,34001;1,18903;3691,95044
71,4;1,18999;3696,90582
71,46001;1,19101;3701,57324
71,52001;1,19202;3707,03563
71,58;1,19298;3711,94147
71,64001;1,194;3716,72548
71,70001;1,19507;3721,21483
71,76;1,19609;3726,48165
71,82;1,19687;3730,25835
71,88001;1,19776;3733,82382
71,94;1,19896;3738,60709
72;1,20003;3744,6212
72,06001;1,20105;3749,35307
72,12;1,20201;3754,42468
72,18;1,20344;3766,23422
72,24001;1,20428;3776,896
72,3;1,20512;3778,40623
72,36;1,20589;3781,57236
72,42001;1,20679;3783,89172
72,48;1,20787;3788,38181
72,54;1,209;3794,77851
72,60001;1,21002;3799,26786
72,66;1,21104;3804,14613
72,72;1,21199;3809,49937
72,78001;1,21301;3812,55485
72,84001;1,21403;3817,1459
72,9;1,2151;3822,06254
72,96001;1,216;3826,63496
73,02001;1,21684;3829,56043
73,08;1,21785;3832,93815
73,14001;1,21899;3838,90457
73,20001;1,22006;3844,73242
73,26;1,22102;3849,12044
73,32;1,22198;3854,32988
73,38001;1,22299;3857,56455
73,44;1,22401;3863,04669
73,5;1,22503;3867,96296
73,56001;1,2261;3872,70562
73,62;1,22694;3877,49709
73,68;1,22778;3879,90214
73,74001;1,22891;3884,40005
73,8;1,22999;3890,86716
73,86;1,23101;3896,32322
73,92001;1,23196;3900,48325
73,98;1,23298;3904,3244
74,04;1,234;3909,43512
74,10001;1,23501;3914,31712
74,16;1,23609;3919,97546
74,22;1,23704;3924,87459
74,28001;1,23788;3929,23392
74,34001;1,23884;3932,31809
74,4;1,24003;3938,40969
74,46001;1,24105;3943,67427
74,52001;1,24201;3947,19467
74,58;1,24296;3951,93659
74,64001;1,24398;3957,20415
74,70001;1,245;3963,18957
74,76;1,24607;3966,72562
74,82001;1,24709;3972,33851
74,88001;1,24799;3976,91578
74,94;1,24888;3980,27077
75;1,2499;3984,06535
75,06001;1,25104;3990,37413
75,12;1,25199;3995,14548
75,18;1,25295;3999,0779
75,24001;1,25343;4003,4201
75,3;1,2551;4013,76635
75,36;1,25606;4017,83064
75,42001;1,25707;4022,41871
75,48;1,25797;4027,26792
75,54;1,25881;4030,41355
75,60001;1,25988;4034,75687
75,66;1,26102;4040,47295
75,72;1,26204;4045,02787
75,78001;1,26299;4049,76346
75,84001;1,26401;4054,30049
75,9;1,26503;4059,20148
75,96001;1,26604;4063,78284
76,02001;1,26706;4068,25356
76,08;1,26802;4073,62729
76,14001;1,26891;4077,38723
76,20001;1,26987;4081,73986
76,26;1,27095;4086,73994
76,32001;1,27202;4093,05543
76,38001;1,27298;4097,50119
76,44;1,27399;4101,92125
76,5;1,27501;4106,21688
76,56001;1,27585;4110,28266
76,62;1,27704;4118,542
76,68;1,27806;4123,79466
76,74001;1,27896;4127,01704
76,8;1,27985;4130,27592
76,86;1,28093;4135,43247
76,92001;1,28201;4142,00127
76,98;1,28296;4146,96932
77,04;1,28398;4150,92371
77,10001;1,285;4157,33829
77,16;1,28601;4161,58475
77,22;1,28703;4166,63326
77,28001;1,2881;4173,05529
77,34001;1,289;4176,54924
77,4;1,28984;4180,2533
77,46001;1,29086;4182,96605
77,52001;1,29199;4189,6075
77,58;1,29301;4195,71288
77,64001;1,29402;4200,2257
77,70001;1,2951;4205,36548
77,76;1,29606;4210,23369
77,82001;1,29707;4214,03535
77,88001;1,29809;4219,47911
77,94;1,29905;4223,39328
78;1,29994;4227,96793
78,06001;1,30084;4230,66914
78,12;1,30192;4235,72063
78,18;1,30299;4241,85283
78,24001;1,30401;4246,22595
78,3;1,30503;4250,88257
78,36;1,30604;4258,00048
78,42001;1,307;4263,25053
78,48;1,30807;4267,30439
78,54;1,30909;4271,78442
78,60001;1,30999;4276,08192
78,66;1,31088;4280,01732
78,72;1,3119;4283,73702
78,78001;1,31298;4289,32421
78,84001;1,31399;4294,44201
78,9;1,31501;4299,05802
78,96001;1,31603;4303,63379
79,02001;1,31698;4307,89404
79,08;1,318;4312,98688
79,14001;1,31908;4317,32014
79,20001;1,32003;4321,67314
79,26;1,32087;4325,3772
79,32001;1,32183;4329,02239
79,38001;1,32296;4335,46528
79,44;1,32398;4340,42104
79,5;1,32499;4344,98675
79,56001;1,32595;4349,19894
79,62;1,32697;4354,27688
79,68;1,32798;4358,08524
79,74001;1,329;4363,69702
79,8;1,33002;4368,46651
79,86;1,33091;4373,42897
79,92001;1,33181;4375,89735
79,98;1,33289;4380,55359
80,04;1,33402;4386,58744
80,10001;1,33504;4391,63409
80,16;1,336;4395,97927
80,22;1,33701;4400,58
80,28001;1,33803;4405,79392
80,34001;1,33899;4409,3594
80,4;1,34006;4415,08442
80,46001;1,34108;4420,51031
80,52001;1,34192;4424,15774
80,58;1,34287;4427,97653
80,64001;1,34401;4432,78663
80,70001;1,34502;4438,66327
80,76;1,34598;4443,18913
80,82001;1,347;4447,74553
80,88001;1,34801;4451,85527
80,94;1,34903;4456,48767
81,00001;1,35005;4461,29628
81,06001;1,35106;4465,44699
81,12;1,35196;4469,87785
81,18;1,35286;4473,2172
81,24001;1,35393;4477,21146
81,3;1,35507;4483,76648
81,36;1,35603;4488,41155
81,42001;1,35698;4492,5712
81,48;1,35806;4497,46735
81,54;1,35902;4502,1452
81,60001;1,36003;4506,62561
81,66;1,36105;4511,14886
81,72;1,362;4515,74586
81,78001;1,3629;4520,26539
81,84001;1,36386;4523,84092
81,9;1,36499;4529,4188
81,96001;1,36607;4535,09949
82,02001;1,36697;4539,80379
82,08;1,36798;4545,39135
82,14001;1,369;4549,22244
82,20001;1,37002;4554,57531
82,26;1,37103;4558,91266
82,32001;1,37205;4564,23424
82,38001;1,37295;4570,09189
82,44;1,37378;4573,06504
82,50001;1,37492;4577,29287
82,56001;1,376;4584,27705
82,62;1,37695;4588,60695
82,68;1,37797;4592,75693
82,74001;1,37898;4597,33494
82,8;1,38;4602,68222
82,86;1,38102;4607,11606
82,92001;1,38203;4612,308
82,98;1,38305;4616,59841
83,04;1,38389;4619,66358
83,10001;1,38484;4622,8148
83,16;1,38598;4628,19152
83,22;1,387;4634,28237
83,28001;1,38801;4639,09358
83,34001;1,38903;4643,67867
83,4;1,39005;4648,3051
83,46001;1,39106;4652,51878
83,52001;1,39208;4656,93623
83,58;1,3931;4662,66237
83,64001;1,39399;4666,55493
83,70001;1,39483;4669,17083
83,76;1,39591;4674,43764
83,82001;1,39704;4680,84663
83,88001;1,398;4685,28718
83,94;1,39901;4689,70872
84,00001;1,39997;4694,21744
84,06001;1,40093;4698,70009
84,12;1,40194;4702,4291
84,18;1,40302;4708,53783
84,24001;1,40404;4713,08418
84,3;1,40487;4717,74153
84,36;1,40589;4720,52805
84,42001;1,40697;4725,87943
84,48;1,40786;4731,3232
84,54;1,40906;4739,67306
84,60001;1,41008;4744,21829
84,66;1,41097;4748,25986
84,72;1,41199;4752,29733
84,78001;1,41306;4756,52851
84,84001;1,41408;4761,82625
84,9;1,41492;4765,5426
84,96001;1,41582;4768,90318
85,02001;1,41695;4773,60003
85,08;1,41803;4780,06266
85,14001;1,41904;4784,19438
85,20001;1,42;4789,30622
85,26;1,42102;4793,46886
85,32001;1,42197;4798,00403
85,38001;1,42299;4802,32164
85,44;1,42407;4807,69835
85,50001;1,42496;4812,33522
85,56001;1,42586;4815,65557
85,62;1,42688;4819,55856
85,68;1,42801;4825,18375
85,74001;1,42903;4830,5884
85,8;1,43005;4834,6851
85,86;1,431;4839,29813
85,92001;1,43202;4843,78077
85,98;1,43303;4848,26751
86,04;1,43411;4853,89642
86,10001;1,43507;4858,20174
86,16;1,4359;4861,34663
86,22;1,4368;4864,41925
86,28001;1,43794;4869,98297
86,34001;1,43907;4876,57189
86,4;1,44003;4880,9994
86,46001;1,44099;4884,74369
86,52001;1,44194;4889,42601
86,58;1,44296;4894,34339
86,64001;1,44404;4899,93021
86,70001;1,44505;4906,01361
86,76;1,44595;4910,48396
86,82001;1,44679;4913,91867
86,88001;1,44786;4917,74939
86,94;1,44906;4924,66129
87,00001;1,45001;4929,41588
87,06001;1,45103;4934,37462
87,12;1,45205;4938,76226
87,18001;1,453;4943,48742
87,24001;1,45402;4948,52923
87,3;1,45504;4953,22086
87,36;1,45605;4957,45912
87,42001;1,45689;4962,45995
87,48;1,45791;4965,72182
87,54;1,45904;4972,08796
87,60001;1,46006;4977,82379
87,66;1,46102;4982,19654
87,72;1,46197;4987,07071
87,78001;1,46299;4991,07689
87,84001;1,46401;4995,62658
87,9;1,46508;5001,02229
87,96001;1,4661;5006,15574
88,02001;1,46699;5010,69874
88,08;1,46783;5013,5117
88,138;1,46885;5018,42797