File: SU - Suspension/test en traction/Courbes/triangles/Specimen_RawData_8.csv
Temps;Déplacement;Charge
(sec);(mm);(N)
0,00000;0,00000;179,06439
0,08000;0,00012;178,76163
0,16000;0,00072;179,31029
0,24000;0,00245;186,48694
0,32000;0,00425;195,47765
0,40000;0,00610;204,62063
0,48000;0,00765;213,35229
0,56000;0,00909;218,91324
0,64000;0,01046;225,78314
0,72000;0,01190;232,52517
0,80000;0,01321;238,74315
0,88000;0,01447;243,50106
0,96000;0,01590;249,60993
1,04000;0,01728;255,73599
1,12000;0,01859;260,85794
1,20000;0,01997;267,01041
1,28000;0,02129;272,40566
1,36000;0,02266;279,00960
1,44000;0,02392;283,66486
1,52000;0,02511;288,74979
1,60000;0,02661;294,55691
1,68000;0,02792;299,73164
1,76000;0,02924;304,99243
1,84000;0,03055;310,57899
1,92000;0,03193;316,21677
2,00000;0,03330;321,28373
2,08000;0,03456;326,49781
2,16000;0,03575;331,25714
2,24000;0,03731;337,07139
2,32000;0,03862;342,37066
2,40000;0,03994;346,38688
2,48000;0,04131;351,31811
2,56000;0,04263;356,28760
2,64000;0,04406;361,82764
2,72000;0,04526;366,43590
2,80000;0,04652;370,06349
2,88000;0,04795;333,48824
2,96000;0,04927;305,77823
3,04000;0,05064;312,10983
3,12000;0,05202;318,14633
3,20000;0,05333;324,89526
3,28000;0,05471;330,45004
3,36000;0,05584;335,97345
3,44000;0,05716;341,43606
3,52000;0,05865;347,56691
3,60000;0,05997;355,19490
3,68000;0,06134;360,15043
3,76000;0,06266;367,10582
3,84000;0,06403;372,64172
3,92000;0,06535;377,71866
4,00000;0,06649;382,23423
4,08000;0,06792;387,33904
4,16000;0,06936;393,40672
4,24000;0,07061;398,87680
4,32000;0,07199;403,87632
4,40000;0,07330;410,20764
4,48000;0,07468;415,24144
4,56000;0,07599;421,30998
4,64000;0,07713;424,45473
4,72000;0,07850;429,35479
4,80000;0,08000;435,18883
4,88000;0,08131;441,12592
4,96000;0,08263;446,27604
5,04000;0,08400;450,69717
5,12000;0,08538;456,19686
5,20000;0,08669;461,69423
5,28000;0,08777;465,11698
5,36000;0,08927;470,80475
5,44000;0,09052;476,08954
5,52000;0,09202;483,47288
5,60000;0,09333;487,81754
5,68000;0,09465;492,31448
5,76000;0,09608;499,42830
5,84000;0,09722;502,27242
5,92000;0,09847;507,29290
6,00000;0,09997;511,79314
6,08000;0,10128;517,18908
6,16000;0,10260;521,94991
6,24000;0,10391;526,13430
6,32000;0,10529;531,27618
6,40000;0,10672;535,80785
6,48000;0,10792;540,82358
6,56000;0,10912;544,22035
6,64000;0,11067;549,91124
6,72000;0,11199;554,99654
6,80000;0,11330;559,71085
6,88000;0,11462;564,07987
6,96000;0,11599;568,61681
7,04000;0,11743;573,68437
7,12000;0,11850;578,29111
7,20000;0,11982;582,03908
7,28000;0,12131;586,97453
7,36000;0,12263;592,27045
7,44000;0,12400;595,74381
7,52000;0,12532;599,44680
7,60000;0,12663;604,29340
7,68000;0,12801;609,69330
7,76000;0,12921;615,38168
7,84000;0,13058;619,43894
7,92000;0,13202;624,45165
8,00000;0,13327;629,10235
8,08000;0,13465;633,09153
8,16000;0,13596;638,07564
8,24000;0,13734;642,48717
8,32000;0,13871;647,26467
8,40000;0,13979;650,68617
8,48000;0,14122;655,58460
8,56000;0,14266;660,01546
8,64000;0,14397;664,66206
8,72000;0,14529;668,23279
8,80000;0,14660;672,51003
8,88000;0,14798;677,12283
8,96000;0,14935;681,82182
9,04000;0,15049;684,23897
9,12000;0,15187;689,07053
9,20000;0,15330;693,61115
9,28000;0,15468;698,44518
9,36000;0,15599;701,35328
9,44000;0,15731;705,81883
9,52000;0,15868;709,50235
9,60000;0,16000;713,97154
9,68000;0,16113;716,68751
9,76000;0,16257;721,42449
9,84000;0,16400;726,23263
9,92000;0,16532;729,50083
10,00000;0,16663;733,14812
10,08000;0,16801;737,43486
10,16000;0,16938;741,21994
10,24000;0,17070;744,95608
10,32000;0,17183;747,84420
10,40000;0,17327;751,15715
10,48000;0,17470;758,46687
10,56000;0,17596;761,65474
10,64000;0,17734;765,41789
10,72000;0,17871;768,74578
10,80000;0,18003;772,42074
10,88000;0,18122;774,94322
10,96000;0,18248;777,16857
11,04000;0,18397;781,07300
11,12000;0,18529;784,82684
11,20000;0,18660;788,46095
11,28000;0,18798;792,03062
11,36000;0,18935;794,30528
11,44000;0,19073;798,56049
11,52000;0,19186;801,38426
11,60000;0,19318;802,85305
11,68000;0,19467;807,51991
11,76000;0,19593;810,85935
11,84000;0,19731;813,66356
11,92000;0,19862;817,20594
12,00000;0,20000;819,94813
12,08000;0,20137;824,30895
12,16000;0,20251;826,09905
12,24000;0,20388;828,50531
12,32000;0,20532;833,37277
12,40000;0,20663;836,07081
12,48000;0,20795;838,20364
12,56000;0,20926;841,62187
12,64000;0,21070;845,63680
12,72000;0,21201;848,81680
12,80000;0,21321;851,05291
12,88000;0,21458;855,38635
12,96000;0,21596;858,97390
13,04000;0,21728;861,80512
13,12000;0,21859;864,20719
13,20000;0,21997;867,30951
13,28000;0,22128;869,93938
13,36000;0,22260;873,42532
13,44000;0,22385;875,70548
13,52000;0,22529;879,25373
13,60000;0,22666;882,75066
13,68000;0,22798;885,28944
13,76000;0,22929;888,40714
13,84000;0,23061;891,19989
13,92000;0,23204;894,56346
14,00000;0,23330;897,52041
14,08000;0,23449;899,69663
14,16000;0,23593;902,16314
14,24000;0,23730;906,05486
14,32000;0,23862;908,69721
14,40000;0,24000;912,10296
14,48000;0,24131;914,56380
14,56000;0,24269;918,63824
14,64000;0,24394;921,10960
14,72000;0,24514;922,85136
14,80000;0,24663;927,59477
14,88000;0,24795;930,97584
14,96000;0,24932;934,34574
15,04000;0,25064;936,89878
15,12000;0,25195;939,20343
15,20000;0,25333;942,96588
15,28000;0,25452;945,48520
15,36000;0,25578;947,56940
15,44000;0,25727;950,62833
15,52000;0,25859;953,65234
15,60000;0,25996;957,89367
15,68000;0,26128;960,63903
15,76000;0,26266;963,21534
15,84000;0,26403;967,41086
15,92000;0,26523;969,66242
16,00000;0,26654;971,91771
16,08000;0,26798;975,44277
16,16000;0,26923;978,21606
16,24000;0,27061;981,54359
16,32000;0,27198;984,72545
16,40000;0,27336;988,59835
16,48000;0,27467;991,83116
16,56000;0,27581;993,60896
16,64000;0,27724;996,42109
16,72000;0,27868;1000,27248
16,80000;0,27999;1003,09011
16,88000;0,28131;1006,31639
16,96000;0,28262;1009,10217
17,04000;0,28400;1011,94242
17,12000;0,28532;1014,94733
17,20000;0,28645;1017,20588
17,28000;0,28795;1020,66649
17,36000;0,28932;1023,93115
17,44000;0,29058;1027,14319
17,52000;0,29195;1029,94991
17,60000;0,29309;1033,00987
17,68000;0,29470;1037,71044
17,76000;0,29590;1040,91512
17,84000;0,29715;1042,14530
17,92000;0,29865;1046,39903
18,00000;0,29990;1050,13587
18,08000;0,30128;1051,96200
18,16000;0,30259;1055,21800
18,24000;0,30391;1058,22459
18,32000;0,30534;1061,33278
18,40000;0,30654;1064,01555
18,48000;0,30780;1066,16234
18,56000;0,30929;1069,48502
18,64000;0,31061;1072,83434
18,72000;0,31198;1076,84387
18,80000;0,31330;1079,84142
18,88000;0,31461;1082,57355
18,96000;0,31599;1085,34219
19,04000;0,31718;1088,29141
19,12000;0,31850;1090,54213
19,20000;0,31999;1094,73746
19,28000;0,32131;1098,03462
19,36000;0,32262;1101,10622
19,44000;0,32394;1103,46116
19,52000;0,32531;1106,84736
19,60000;0,32669;1109,92054
19,68000;0,32789;1112,33434
19,76000;0,32920;1114,14660
19,84000;0,33064;1118,45331
19,92000;0,33201;1122,43574
20,00000;0,33333;1124,26486
20,08000;0,33464;1127,50512
20,16000;0,33602;1130,32311
20,24000;0,33739;1133,75457
20,32000;0,33847;1136,29028
20,40000;0,33984;1138,44760
20,48000;0,34134;1143,85793
20,56000;0,34265;1145,93096
20,64000;0,34397;1149,37695
20,72000;0,34522;1152,17092
20,80000;0,34666;1155,68480
20,88000;0,34797;1158,76487
20,96000;0,34911;1160,55477
21,04000;0,35055;1163,56947
21,12000;0,35198;1167,36200
21,20000;0,35330;1170,86573
21,28000;0,35467;1172,92302
21,36000;0,35599;1176,09389
21,44000;0,35742;1180,01979
21,52000;0,35862;1182,51601
21,60000;0,35975;1183,64664
21,68000;0,36125;1187,71065
21,76000;0,36262;1192,02249
21,84000;0,36394;1195,35364
21,92000;0,36525;1197,88283
22,00000;0,36657;1200,94987
22,08000;0,36806;1204,55176
22,16000;0,36926;1207,80570
22,24000;0,37046;1209,61256
22,32000;0,37201;1213,68067
22,40000;0,37333;1217,07153
22,48000;0,37464;1219,57939
22,56000;0,37596;1222,22248
22,64000;0,37733;1225,65450
22,72000;0,37871;1228,16889
22,80000;0,37990;1231,19913
22,88000;0,38116;1233,43691
22,96000;0,38271;1237,01058
23,04000;0,38397;1240,48209
23,12000;0,38528;1243,08402
23,20000;0,38666;1247,05750
23,28000;0,38803;1250,83001
23,36000;0,38935;1254,94376
23,44000;0,39049;1256,88789
23,52000;0,39186;1259,11580
23,60000;0,39330;1263,63449
23,68000;0,39461;1266,39307
23,76000;0,39593;1269,15248
23,84000;0,39730;1272,11474
23,92000;0,39874;1274,86540
24,00000;0,39999;1278,71819
24,08000;0,40119;1280,47140
24,16000;0,40256;1282,82793
24,24000;0,40400;1287,16519
24,32000;0,40531;1289,85578
24,40000;0,40669;1293,80301
24,48000;0,40800;1296,54324
24,56000;0,40932;1299,25329
24,64000;0,41063;1302,14896
24,72000;0,41183;1304,56397
24,80000;0,41326;1307,03384
24,88000;0,41464;1312,31816
24,96000;0,41596;1314,36987
25,04000;0,41733;1318,38368
25,12000;0,41865;1320,66421
25,20000;0,42002;1324,77833
25,28000;0,42134;1326,96824
25,36000;0,42253;1329,15592
25,44000;0,42397;1332,43920
25,52000;0,42534;1336,64338
25,60000;0,42666;1338,91394
25,68000;0,42803;1342,31672
25,76000;0,42935;1345,25504
25,84000;0,43072;1347,97897
25,92000;0,43198;1350,65904
26,00000;0,43312;1352,64173
26,08000;0,43455;1355,77628
26,16000;0,43598;1360,93311
26,24000;0,43736;1363,71152
26,32000;0,43868;1367,70159
26,40000;0,43999;1369,87315
26,48000;0,44137;1373,68822
26,56000;0,44262;1375,97769
26,64000;0,44382;1378,09636
26,72000;0,44531;1382,05215
26,80000;0,44663;1384,90405
26,88000;0,44800;1387,99781
26,96000;0,44932;1390,52374
27,04000;0,45069;1393,23035
27,12000;0,45207;1396,46539
27,20000;0,45326;1399,84069
27,28000;0,45452;1400,56200
27,36000;0,45595;1405,67375
27,44000;0,45733;1408,54651
27,52000;0,45865;1411,69345
27,60000;0,45996;1414,46292
27,68000;0,46134;1417,50900
27,76000;0,46271;1420,52975
27,84000;0,46385;1422,95733
27,92000;0,46516;1424,71492
28,00000;0,46666;1428,67360
28,08000;0,46797;1432,42134
28,16000;0,46935;1435,85997
28,24000;0,47066;1440,29837
28,32000;0,47210;1442,27762
28,40000;0,47335;1446,10070
28,48000;0,47449;1447,74560
28,56000;0,47592;1450,19582
28,64000;0,47736;1453,90807
28,72000;0,47861;1456,47880
28,80000;0,47999;1459,67687
28,88000;0,48125;1462,13556
28,96000;0,48268;1464,97926
29,04000;0,48394;1468,29532
29,12000;0,48507;1470,01771
29,20000;0,48657;1473,19594
29,28000;0,48794;1477,00431
29,36000;0,48926;1479,96107
29,44000;0,49063;1483,26056
29,52000;0,49201;1486,26333
29,60000;0,49338;1490,05894
29,68000;0,49458;1492,15544
29,76000;0,49583;1493,37277
29,84000;0,49739;1497,49024
29,92000;0,49864;1500,53147
30,00000;0,50002;1503,52921
30,08000;0,50133;1505,90353
30,16000;0,50265;1508,93182
30,24000;0,50403;1511,79358
30,32000;0,50522;1513,45413
30,40000;0,50654;1515,48246
30,48000;0,50803;1520,38336
30,56000;0,50929;1523,15488
30,64000;0,51060;1526,25209
30,72000;0,51192;1528,54705
30,80000;0,51329;1532,06494
30,88000;0,51467;1534,48675
30,96000;0,51580;1536,69072
31,04000;0,51718;1539,03197
31,12000;0,51867;1542,46185
31,20000;0,51999;1545,83910
31,28000;0,52136;1548,40937
31,36000;0,52268;1551,31873
31,44000;0,52400;1554,54557
31,52000;0,52531;1556,45125
31,60000;0,52651;1558,88777
31,68000;0,52788;1561,73175
31,76000;0,52926;1565,39883
31,84000;0,53057;1567,82549
31,92000;0,53201;1571,96857
32,00000;0,53332;1575,48916
32,08000;0,53470;1577,79790
32,16000;0,53595;1581,05232
32,24000;0,53709;1582,44427
32,32000;0,53864;1585,82795
32,40000;0,53996;1588,73312
32,48000;0,54127;1592,26395
32,56000;0,54259;1593,96566
32,64000;0,54396;1596,93528
32,72000;0,54540;1599,96953
32,80000;0,54660;1603,16192
32,88000;0,54785;1604,26721
32,96000;0,54929;1608,39353
33,04000;0,55066;1611,44529
33,12000;0,55198;1613,38523
33,20000;0,55329;1616,14791
33,28000;0,55467;1619,28218
33,36000;0,55604;1622,03796
33,44000;0,55718;1623,11625
33,52000;0,55843;1625,46057
33,60000;0,55999;1629,75099
33,68000;0,56130;1633,09593
33,76000;0,56268;1635,15043
33,84000;0,56399;1639,05453
33,92000;0,56531;1640,85608
34,00000;0,56674;1644,78272
34,08000;0,56788;1646,04429
34,16000;0,56920;1648,47001
34,24000;0,57069;1652,24839
34,32000;0,57201;1655,16399
34,40000;0,57332;1657,73127
34,48000;0,57464;1660,43881
34,56000;0,57601;1663,65989
34,64000;0,57733;1665,79578
34,72000;0,57846;1667,66625
34,80000;0,57984;1669,56298
34,88000;0,58133;1674,84917
34,96000;0,58259;1676,51810
35,04000;0,58390;1679,38378
35,12000;0,58528;1682,54022
35,20000;0,58665;1685,06671
35,28000;0,58803;1687,83814
35,36000;0,58917;1690,03699
35,44000;0,59054;1692,22578
35,52000;0,59204;1695,67689
35,60000;0,59335;1699,04586
35,68000;0,59467;1700,76061
35,76000;0,59598;1704,39202
35,84000;0,59736;1707,22753
35,92000;0,59861;1710,42774
36,00000;0,59981;1711,29350
36,08000;0,60124;1713,89617
36,16000;0,60268;1717,56316
36,24000;0,60393;1720,80752
36,32000;0,60531;1722,73722
36,40000;0,60662;1725,75694
36,48000;0,60806;1728,92790
36,56000;0,60931;1730,52419
36,64000;0,61051;1732,42483
36,72000;0,61195;1735,77406
36,80000;0,61332;1738,51196
36,88000;0,61464;1740,64636
36,96000;0,61601;1743,43232
37,04000;0,61739;1745,91895
37,12000;0,61870;1749,93016
37,20000;0,61996;1751,51676
37,28000;0,62115;1752,59635
37,36000;0,62259;1754,80209
37,44000;0,62396;1759,39221
37,52000;0,62522;1761,44987
37,60000;0,62659;1763,74540
37,68000;0,62791;1766,58947
37,76000;0,62928;1769,58647
37,84000;0,63060;1772,26644
37,92000;0,63180;1773,85490
38,00000;0,63329;1776,94466
38,08000;0,63461;1780,07334
38,16000;0,63598;1782,15355
38,24000;0,63730;1785,63260
38,32000;0,63867;1787,56099
38,40000;0,64005;1791,20004
38,48000;0,64130;1793,63303
38,56000;0,64250;1795,37609
38,64000;0,64399;1797,84149
38,72000;0,64531;1801,96725
38,80000;0,64662;1804,39092
38,88000;0,64800;1805,71266
38,96000;0,64931;1809,36120
39,04000;0,65069;1811,53547
39,12000;0,65188;1814,00273
39,20000;0,65308;1815,07207
39,28000;0,65464;1818,53212
39,36000;0,65601;1822,66757
39,44000;0,65733;1824,48309
39,52000;0,65870;1827,23086
39,60000;0,66002;1830,05445
39,68000;0,66139;1832,07653
39,76000;0,66259;1835,72322
39,84000;0,66384;1837,12989
39,92000;0,66534;1841,13700
40,00000;0,66665;1844,29716
40,08000;0,66797;1848,01277
40,16000;0,66928;1852,40358
40,24000;0,67066;1856,41143
40,32000;0,67203;1859,52466
40,40000;0,67323;1864,15520
40,48000;0,67449;1867,58842
40,56000;0,67592;1873,26893
40,64000;0,67724;1877,48037
40,72000;0,67861;1881,78960
40,80000;0,67993;1886,46037
40,88000;0,68130;1890,63642
40,96000;0,68268;1895,45881
41,04000;0,68387;1899,61512
41,12000;0,68519;1903,26981
41,20000;0,68662;1909,31186
41,28000;0,68800;1914,42948
41,36000;0,68931;1918,40231
41,44000;0,69063;1922,52100
41,52000;0,69200;1927,06175
41,60000;0,69338;1932,28014
41,68000;0,69451;1935,39690
41,76000;0,69583;1939,24680
41,84000;0,69732;1945,42427
41,92000;0,69864;1949,99538
42,00000;0,69996;1954,81218
42,08000;0,70127;1958,74926
42,16000;0,70271;1964,00825
42,24000;0,70420;1974,08255
42,32000;0,70540;1978,23718
42,40000;0,70665;1982,41081
42,48000;0,70791;1985,51789
42,56000;0,70928;1989,64607
42,64000;0,71060;1993,40247
42,72000;0,71203;1998,58118
42,80000;0,71329;2002,29511
42,88000;0,71442;2004,84078
42,96000;0,71592;2008,45879
43,04000;0,71729;2014,22404
43,12000;0,71867;2017,78691
43,20000;0,71999;2022,49158
43,28000;0,72130;2025,72122
43,36000;0,72268;2029,65755
43,44000;0,72393;2033,88333
43,52000;0,72513;2036,18407
43,60000;0,72662;2040,51342
43,68000;0,72800;2046,66909
43,76000;0,72925;2049,60983
43,84000;0,73063;2054,23851
43,92000;0,73194;2058,15639
44,00000;0,73332;2062,37063
44,08000;0,73457;2066,51017
44,16000;0,73577;2069,04914
44,24000;0,73726;2073,66385
44,32000;0,73858;2078,73154
44,40000;0,73995;2083,08417
44,48000;0,74133;2086,88322
44,56000;0,74265;2090,47291
44,64000;0,74402;2094,90862
44,72000;0,74528;2099,32327
44,80000;0,74647;2101,51523
44,88000;0,74791;2106,64738
44,96000;0,74928;2110,63009
45,04000;0,75060;2113,91114
45,12000;0,75197;2118,60090
45,20000;0,75335;2122,47930
45,28000;0,75472;2127,13387
45,36000;0,75592;2130,22009
45,44000;0,75717;2132,33717
45,52000;0,75861;2136,82074
45,60000;0,75998;2141,62190
45,68000;0,76130;2144,65838
45,76000;0,76261;2148,89888
45,84000;0,76393;2153,61807
45,92000;0,76537;2157,39142
46,00000;0,76662;2160,60504
46,08000;0,76782;2163,13507
46,16000;0,76931;2167,72333
46,24000;0,77063;2171,46464
46,32000;0,77200;2175,58127
46,40000;0,77332;2179,21212
46,48000;0,77463;2182,76046
46,56000;0,77613;2186,76794
46,64000;0,77726;2190,17323
46,72000;0,77846;2192,58536
46,80000;0,77995;2197,92463
46,88000;0,78133;2201,74752
46,96000;0,78264;2205,23104
47,04000;0,78396;2208,51488
47,12000;0,78528;2212,43873
47,20000;0,78671;2216,09268
47,28000;0,78791;2220,00089
47,36000;0,78916;2222,11163
47,44000;0,79066;2226,76415
47,52000;0,79197;2230,53750
47,60000;0,79329;2234,21399
47,68000;0,79460;2237,80479
47,76000;0,79598;2241,59155
47,84000;0,79735;2246,20700
47,92000;0,79849;2248,56995
48,00000;0,79980;2251,56769
48,08000;0,80136;2256,79763
48,16000;0,80267;2259,71490
48,24000;0,80399;2263,52978
48,32000;0,80530;2267,21466
48,40000;0,80668;2271,27969
48,48000;0,80805;2275,18547
48,56000;0,80919;2277,05687
48,64000;0,81051;2280,11403
48,72000;0,81200;2285,25121
48,80000;0,81332;2287,64601
48,88000;0,81463;2291,56744
48,96000;0,81595;2295,26497
49,04000;0,81732;2298,42737
49,12000;0,81864;2302,87407
49,20000;0,81983;2305,51120
49,28000;0,82121;2307,72626
49,36000;0,82270;2313,23168
49,44000;0,82396;2316,30784
49,52000;0,82527;2319,59354
49,60000;0,82665;2322,30630
49,68000;0,82820;2335,34034
49,76000;0,82928;2336,64569
49,84000;0,83060;2339,09264
49,92000;0,83197;2342,70766
50,00000;0,83323;2345,45562
50,08000;0,83460;2348,49732
50,16000;0,83598;2352,16599
50,24000;0,83735;2355,40159
50,32000;0,83861;2359,05442
50,40000;0,83980;2361,29258
50,48000;0,84124;2364,79621
50,56000;0,84261;2367,93421
50,64000;0,84393;2370,95952
50,72000;0,84530;2374,30781
50,80000;0,84662;2377,96679
50,88000;0,84805;2381,33054
50,96000;0,84931;2384,12675
51,04000;0,85051;2386,47163
51,12000;0,85194;2388,94876
51,20000;0,85332;2392,48220
51,28000;0,85463;2396,59455
51,36000;0,85601;2400,21478
51,44000;0,85738;2402,99571
51,52000;0,85870;2407,58620
51,60000;0,85995;2410,28573
51,68000;0,86115;2412,62298
51,76000;0,86264;2415,30966
51,84000;0,86396;2419,03402
51,92000;0,86527;2422,01276
52,00000;0,86665;2424,67355
52,08000;0,86796;2428,69686
52,16000;0,86934;2431,07472
52,24000;0,87059;2434,39712
52,32000;0,87179;2436,82861
52,40000;0,87329;2440,49616
52,48000;0,87466;2443,94299
52,56000;0,87604;2447,71577
52,64000;0,87735;2450,28790
52,72000;0,87849;2453,93720
52,80000;0,88004;2458,42971
52,88000;0,88124;2461,78377
52,96000;0,88249;2463,47059
53,04000;0,88399;2468,81545
53,12000;0,88530;2471,41793
53,20000;0,88668;2474,21265
53,28000;0,88793;2478,04504
53,36000;0,88931;2480,99919
53,44000;0,89068;2484,52686
53,52000;0,89188;2487,07980
53,60000;0,89314;2489,20061
53,68000;0,89463;2494,09135
53,76000;0,89595;2498,01446
53,84000;0,89732;2500,88181
53,92000;0,89864;2504,33274
54,00000;0,90001;2507,88610
54,08000;0,90139;2511,47635
54,16000;0,90252;2514,32993
54,24000;0,90390;2517,28315
54,32000;0,90533;2521,49776
54,40000;0,90665;2525,09695
54,48000;0,90796;2527,94847
54,56000;0,90934;2531,98985
54,64000;0,91071;2535,24370
54,72000;0,91197;2538,62720
54,80000;0,91311;2541,18573
54,88000;0,91454;2543,50100
54,96000;0,91597;2549,59092
55,04000;0,91729;2551,89333
55,12000;0,91867;2555,84083
55,20000;0,91998;2558,65846
55,28000;0,92136;2562,57299
55,36000;0,92261;2564,87094
55,44000;0,92381;2567,42891
55,52000;0,92524;2571,36934
55,60000;0,92662;2575,16466
55,68000;0,92793;2578,07206
55,76000;0,92931;2581,71279
55,84000;0,93068;2585,35929
55,92000;0,93206;2588,70050
56,00000;0,93325;2591,58704
56,08000;0,93445;2593,32228
56,16000;0,93600;2599,11902
56,24000;0,93726;2602,57032
56,32000;0,93864;2606,46250
56,40000;0,94001;2611,77495
56,48000;0,94133;2614,92375
56,56000;0,94264;2619,31233
56,64000;0,94384;2622,29126
56,72000;0,94521;2625,27876
56,80000;0,94665;2630,21719
56,88000;0,94796;2633,48669
56,96000;0,94928;2637,49305
57,04000;0,95065;2641,66668
57,12000;0,95197;2646,04259
57,20000;0,95334;2649,80420
57,28000;0,95454;2653,15659
57,36000;0,95585;2655,99936
57,44000;0,95729;2661,83689
57,52000;0,95860;2664,84953
57,60000;0,95980;2669,50354
57,68000;0,96124;2674,02437
57,76000;0,96261;2677,88395
57,84000;0,96399;2682,34909
57,92000;0,96512;2685,37477
58,00000;0,96650;2688,57386
58,08000;0,96793;2694,67495
58,16000;0,96925;2697,92899
58,24000;0,97062;2702,13988
58,32000;0,97194;2706,40906
58,40000;0,97337;2710,53500
58,48000;0,97469;2714,42402
58,56000;0,97582;2718,08337
58,64000;0,97726;2722,09942
58,72000;0,97869;2727,40256
58,80000;0,97995;2730,83989
58,88000;0,98127;2734,63391
58,96000;0,98258;2739,18305
59,04000;0,98396;2743,56287
59,12000;0,98527;2747,67093
59,20000;0,98647;2751,78291
59,28000;0,98796;2757,16893
59,36000;0,98934;2762,63170
59,44000;0,99065;2766,84891
59,52000;0,99197;2770,37341
59,60000;0,99334;2774,58355
59,68000;0,99478;2779,02223
59,76000;0,99591;2783,03418
59,84000;0,99711;2785,51634
59,92000;0,99866;2790,85189
60,00000;0,99998;2795,80355
60,08000;1,00135;2799,39994
60,16000;1,00261;2803,88743
60,24000;1,00399;2808,07391
60,32000;1,00536;2811,85191
60,40000;1,00656;2815,86610
60,48000;1,00781;2818,46337
60,56000;1,00931;2823,68064
60,64000;1,01062;2827,96193
60,72000;1,01194;2832,68709
60,80000;1,01325;2836,25014
60,88000;1,01463;2840,46140
60,96000;1,01600;2845,47433
61,04000;1,01714;2848,09787
61,12000;1,01845;2851,80360
61,20000;1,02001;2856,69621
61,28000;1,02126;2860,94137
61,36000;1,02264;2864,67467
61,44000;1,02395;2869,62595
61,52000;1,02539;2874,39357
61,60000;1,02676;2878,31407
61,68000;1,02784;2881,33118
61,76000;1,02922;2885,13973
61,84000;1,03065;2889,78554
61,92000;1,03197;2893,98525
62,00000;1,03328;2899,46049
62,08000;1,03466;2903,42718
62,16000;1,03597;2907,46335
62,24000;1,03735;2912,44779
62,32000;1,03848;2916,24628
62,40000;1,03992;2919,35578
62,48000;1,04135;2925,26912
62,56000;1,04267;2929,43623
62,64000;1,04398;2933,88423
62,72000;1,04476;2939,14359
62,80000;1,04685;2947,59758
62,88000;1,04799;2950,75960
62,96000;1,04925;2955,05617
63,04000;1,05068;2959,38347
63,12000;1,05194;2963,74019
63,20000;1,05325;2967,23843
63,28000;1,05463;2972,48513
63,36000;1,05600;2976,30336
63,44000;1,05738;2981,19001
63,52000;1,05857;2984,88829
63,60000;1,05977;2987,60738
63,68000;1,06132;2992,99192
63,76000;1,06258;2997,87726
63,84000;1,06395;3001,72716
63,92000;1,06527;3007,07668
64,00000;1,06664;3011,41459
64,08000;1,06802;3016,02092
64,16000;1,06922;3020,09191
64,24000;1,07053;3023,41040
64,32000;1,07203;3029,35001
64,40000;1,07328;3034,29049
64,48000;1,07466;3038,33950
64,56000;1,07597;3042,45334
64,64000;1,07735;3047,02464
64,72000;1,07872;3050,70467
64,80000;1,07986;3054,84422
64,88000;1,08117;3058,64848
64,96001;1,08261;3064,78422
65,04000;1,08392;3070,01919
65,12000;1,08530;3074,09894
65,20000;1,08661;3078,33273
65,28001;1,08799;3083,90036
65,36000;1,08936;3088,34203
65,44000;1,09050;3092,40054
65,52000;1,09188;3095,19377
65,60001;1,09295;3101,99931
65,68000;1,09475;3108,67708
65,76000;1,09606;3113,17034
65,84001;1,09732;3118,25480
65,92001;1,09869;3121,21790
66,00000;1,10001;3126,66595
66,08000;1,10114;3130,05410
66,16000;1,10258;3134,50806
66,24001;1,10395;3140,46964
66,32000;1,10527;3145,08565
66,40000;1,10664;3149,76834
66,48000;1,10790;3154,32325
66,56001;1,10933;3160,29638
66,64000;1,11059;3165,21861
66,72000;1,11179;3167,90231
66,80000;1,11328;3172,68521
66,88001;1,11460;3178,85838
66,96001;1,11597;3183,98513
67,04000;1,11735;3188,21035
67,12000;1,11866;3192,84983
67,20001;1,12016;3199,20629
67,28001;1,12129;3204,56810
67,36000;1,12255;3208,41260
67,44000;1,12398;3214,14880
67,52001;1,12530;3218,93729
67,60001;1,12661;3223,51046
67,68000;1,12793;3228,19613
67,76000;1,12930;3233,20143
67,84001;1,13068;3238,79160
67,92001;1,13182;3242,42972
68,00000;1,13313;3246,27720
68,08000;1,13463;3252,74989
68,16000;1,13594;3257,83230
68,24001;1,13732;3263,12743
68,32000;1,13863;3269,09013
68,40000;1,14007;3273,66143
68,48000;1,14138;3277,85239
68,56001;1,14252;3282,15547
68,64001;1,14389;3287,38652
68,72000;1,14533;3292,97557
68,80000;1,14664;3297,37589
68,88001;1,14802;3303,21305
68,96001;1,14933;3308,26379
69,04000;1,15071;3313,80703
69,12000;1,15196;3318,52771
69,20001;1,15310;3322,35619
69,28001;1,15442;3327,81821
69,36000;1,15597;3336,36850
69,44000;1,15735;3340,41305
69,52001;1,15866;3346,06692
69,60001;1,15998;3351,38850
69,68000;1,16135;3355,45540
69,76000;1,16255;3360,96138
69,84001;1,16380;3364,87070
69,92001;1,16536;3370,60764
70,00000;1,16667;3376,48019
70,08000;1,16799;3380,44353
70,16000;1,16936;3385,54829
70,24001;1,17068;3391,01739
70,32000;1,17205;3395,75298
70,40000;1,17319;3399,73420
70,48000;1,17444;3404,18331
70,56001;1,17594;3409,55555
70,64001;1,17726;3414,83876
70,72000;1,17863;3419,42236
70,80000;1,17995;3424,64186
70,88001;1,18126;3430,03906
70,96001;1,18270;3434,81749
71,04000;1,18383;3439,85483
71,12000;1,18521;3443,91130
71,20001;1,18664;3450,19698
71,28001;1,18796;3454,34770
71,36000;1,18933;3459,09856
71,44000;1,19065;3464,03420
71,52001;1,19202;3468,94674
71,60001;1,19340;3473,94310
71,68000;1,19453;3478,46448
71,76000;1,19585;3482,76943
71,84001;1,19734;3489,18028
71,92001;1,19860;3493,08625
72,00000;1,19998;3498,47376
72,08000;1,20123;3503,21047
72,16000;1,20267;3510,45541
72,24001;1,20398;3516,18528
72,32000;1,20512;3519,72803
72,40000;1,20655;3524,44984
72,48000;1,20793;3530,17151
72,56001;1,20930;3535,57579
72,64001;1,21068;3540,61201
72,72000;1,21193;3545,59943
72,80000;1,21337;3550,38084
72,88001;1,21468;3556,19006
72,96001;1,21582;3559,58529
73,04000;1,21725;3565,59232
73,12000;1,21863;3573,03694
73,20001;1,22000;3578,07837
73,28001;1,22132;3582,46677
73,36000;1,22258;3586,63797
73,44000;1,22401;3592,37455
73,52001;1,22527;3597,07102
73,60001;1,22640;3599,58112
73,68000;1,22790;3605,56580
73,76000;1,22927;3611,35155
73,84001;1,23065;3617,00356
73,92001;1,23196;3621,64937
74,00000;1,23328;3627,02422
74,08000;1,23471;3632,59986
74,16000;1,23591;3637,06686
74,24001;1,23710;3640,61110
74,32001;1,23866;3645,84476
74,40000;1,24003;3651,66701
74,48000;1,24129;3656,31282
74,56001;1,24261;3661,06406
74,64001;1,24398;3666,30629
74,72000;1,24542;3672,04398
74,80000;1,24655;3676,83917
74,88001;1,24775;3679,56311
74,96001;1,24930;3685,56082
75,04000;1,25062;3690,92524
75,12000;1,25193;3695,92942
75,20001;1,25331;3701,43726
75,28001;1,25462;3705,55036
75,36000;1,25600;3710,94458
75,44000;1,25719;3716,36339
75,52001;1,25845;3720,04583
75,60001;1,26000;3726,61911
75,68000;1,26132;3731,60467
75,76000;1,26263;3736,43823
75,84001;1,26401;3741,49159
75,92001;1,26538;3746,69209
76,00000;1,26676;3752,55980
76,08000;1,26790;3756,76937
76,16000;1,26915;3760,46039
76,24001;1,27065;3767,11451
76,32001;1,27190;3771,65601
76,40000;1,27322;3775,97138
76,48000;1,27459;3781,02139
76,56001;1,27597;3786,44392
76,64001;1,27734;3792,58096
76,72000;1,27866;3803,87157
76,80000;1,28003;3807,63896
76,88001;1,28129;3812,27508
76,96001;1,28260;3817,12615
77,04000;1,28398;3822,17839
77,12000;1,28529;3827,67692
77,20001;1,28667;3831,98820
77,28001;1,28787;3836,16537
77,36000;1,28918;3840,61076
77,44000;1,29068;3847,34422
77,52001;1,29193;3852,41583
77,60001;1,29331;3857,65433
77,68000;1,29462;3862,29008
77,76000;1,29600;3867,33674
77,84001;1,29731;3872,83973
77,92001;1,29851;3876,49164
78,00000;1,29982;3881,48390
78,08000;1,30132;3887,22308
78,16000;1,30257;3892,84268
78,24001;1,30395;3897,92956
78,32001;1,30532;3902,95349
78,40000;1,30670;3908,19274
78,48000;1,30801;3913,77322
78,56001;1,30921;3918,24208
78,64001;1,31047;3922,37864
78,72000;1,31202;3930,18275
78,80000;1,31334;3935,36314
78,88001;1,31471;3941,19062
78,96001;1,31603;3946,32928
79,04000;1,31734;3950,92405
79,12000;1,31866;3956,59171
79,20001;1,31985;3960,87207
79,28001;1,32117;3964,94456
79,36000;1,32260;3971,63928
79,44000;1,32374;3976,07535
79,52001;1,32535;3983,67047
79,60001;1,32667;3989,09561
79,68000;1,32804;3994,33635
79,76000;1,32930;3999,69332
79,84001;1,33050;4003,32063
79,92001;1,33193;4008,52300
80,00000;1,33331;4014,60342
80,08000;1,33462;4019,70074
80,16000;1,33600;4025,08937
80,24001;1,33731;4029,79106
80,32001;1,33869;4035,14579
80,40000;1,33994;4040,05535
80,48000;1,34114;4044,39755
80,56001;1,34257;4049,58092
80,64001;1,34395;4056,13258
80,72000;1,34526;4060,54184
80,80000;1,34658;4065,69913
80,88001;1,34795;4070,46080
80,96001;1,34933;4076,59486
81,04000;1,35058;4081,89110
81,12000;1,35178;4086,28657
81,20001;1,35328;4092,81775
81,28001;1,35465;4098,91345
81,36000;1,35597;4103,85057
81,44000;1,35734;4109,66687
81,52001;1,35872;4115,69625
81,60001;1,36009;4121,40079
81,68000;1,36123;4126,02313
81,76000;1,36248;4129,89780
81,84001;1,36398;4137,14908
81,92001;1,36529;4142,94712
82,00001;1,36661;4147,70059
82,08000;1,36798;4153,06017
82,16000;1,36936;4159,34548
82,24001;1,37067;4163,79422
82,32001;1,37181;4167,81269
82,40000;1,37319;4172,47452
82,48000;1,37468;4179,85544
82,56001;1,37600;4185,06898
82,64001;1,37731;4190,81487
82,72000;1,37869;4196,68928
82,80000;1,38000;4201,19539
82,88001;1,38132;4206,63953
82,96001;1,38251;4211,01376
83,04000;1,38377;4215,95126
83,12000;1,38532;4226,14776
83,20001;1,38664;4230,47133
83,28001;1,38801;4236,29843
83,36000;1,38933;4242,04245
83,44000;1,39070;4247,60617
83,52001;1,39190;4252,74968
83,60001;1,39310;4255,60623
83,68000;1,39459;4261,47133
83,76000;1,39591;4267,29769
83,84001;1,39728;4272,84986
83,92001;1,39860;4278,64715
84,00001;1,39991;4284,60725
84,08000;1,40135;4290,26298
84,16000;1,40254;4295,74139
84,24001;1,40380;4299,13439
84,32001;1,40529;4305,88312
84,40000;1,40661;4312,55177
84,48000;1,40798;4317,35478
84,56001;1,40930;4323,30929
84,64001;1,41067;4328,87934
84,72000;1,41205;4334,79026
84,80000;1,41324;4339,34703
84,88001;1,41444;4344,56654
84,96001;1,41593;4349,80355
85,04000;1,41725;4356,40626
85,12000;1,41863;4362,16556
85,20001;1,41994;4367,34781
85,28001;1,42132;4374,43927
85,36000;1,42269;4381,95392
85,44000;1,42389;4386,08527
85,52001;1,42514;4390,94193
85,60001;1,42664;4397,75698
85,68000;1,42795;4403,25104
85,76000;1,42927;4408,21014
85,84001;1,43064;4414,44628
85,92001;1,43202;4420,82286
86,00001;1,43339;4426,56279
86,08000;1,43447;4431,00110
86,16000;1,43584;4436,17217
86,24001;1,43734;4443,22750
86,32001;1,43865;4448,81245
86,40000;1,43997;4453,88667
86,48000;1,44129;4459,57854
86,56001;1,44266;4465,43992
86,64001;1,44398;4471,64178
86,72000;1,44511;4475,35813
86,80000;1,44655;4481,21354
86,88001;1,44798;4488,39739
86,96001;1,44930;4493,41238
87,04000;1,45067;4499,12809
87,12000;1,45199;4503,96985
87,20001;1,45336;4510,77856
87,28001;1,45468;4516,35830
87,36000;1,45581;4520,82381
87,44000;1,45725;4527,08714
87,52001;1,45868;4534,26801
87,60001;1,45994;4540,14912
87,68001;1,46131;4545,92220
87,76000;1,46263;4551,50753
87,84001;1,46401;4557,84053
87,92001;1,46526;4562,86035
88,00001;1,46640;4567,46556
88,08000;1,46795;4574,01983
88,16000;1,46933;4581,88616
88,24001;1,47064;4587,09113
88,32001;1,47202;4592,54570
88,40000;1,47333;4598,62761
88,48000;1,47471;4604,29676
88,56001;1,47590;4609,00515
88,64001;1,47716;4614,36771
88,72000;1,47865;4621,12315
88,80000;1,47997;4627,93596
88,88001;1,48128;4633,04780
88,96001;1,48266;4639,17106
89,04000;1,48404;4645,30066
89,12000;1,48541;4651,24585
89,20001;1,48655;4656,36104
89,28001;1,48786;4660,90515
89,36000;1,48930;4670,78649
89,44000;1,49055;4675,35146
89,52001;1,49193;4681,40133
89,60001;1,49324;4687,51565
89,68001;1,49468;4693,20379
89,76000;1,49599;4699,49655
89,84001;1,49719;4703,76797
89,92001;1,49850;4709,03367
90,00001;1,50000;4717,32542
90,08000;1,50131;4722,49128
90,16000;1,50269;4728,68085
90,24001;1,50400;4734,08774
90,32001;1,50538;4740,16033
90,40000;1,50664;4746,39609
90,48000;1,50783;4751,53327
90,56001;1,50927;4756,34262
90,64001;1,51064;4763,74701
90,72000;1,51196;4769,58193
90,80000;1,51327;4775,14863
90,88001;1,51459;4781,21489
90,96001;1,51602;4787,35119
91,04000;1,51734;4793,20399
91,12000;1,51847;4798,33372
91,20001;1,51991;4804,59258
91,28001;1,52128;4811,01535
91,36000;1,52266;4816,22778
91,44000;1,52397;4822,04333
91,52001;1,52535;4828,41358
91,60001;1,52672;4834,91868
91,68001;1,52798;4840,66829
91,76000;1,52912;4844,30715
91,84001;1,53061;4850,86665
91,92001;1,53199;4857,68802
92,00001;1,53330;4862,93621
92,08000;1,53468;4869,39773
92,16000;1,53599;4875,72849
92,24001;1,53737;4881,72658
92,32001;1,53862;4887,40392
92,40000;1,53982;4891,83329
92,48000;1,54125;4898,67926
92,56001;1,54263;4904,37113
92,64001;1,54394;4911,02822
92,72000;1,54526;4916,81919
92,80000;1,54663;4922,60382
92,88001;1,54807;4929,44680
92,96001;1,54927;4934,93490
93,04000;1,55052;4939,75580
93,12000;1,55202;4945,81088
93,20001;1,55333;4952,81965
93,28001;1,55465;4958,75962
93,36001;1,55596;4964,79683
93,44000;1,55734;4970,37843
93,52001;1,55871;4977,66510
93,60001;1,55985;4983,60917
93,68001;1,56116;4988,31496
93,76000;1,56266;4995,73722
93,84001;1,56391;5002,40587
93,92001;1,56523;5008,62822
94,00001;1,56660;5014,25751
94,08000;1,56798;5021,19586
94,12200;1,56870;5023,55248