File: SU - Suspension/test en traction/Courbes/triangles/Specimen_RawData_3.csv
Temps;Déplacement;Charge
(sec);(mm);(N)
0;0,00001;311,31476
0,08;0,00018;310,91985
0,16;0,00096;312,87419
0,24;0,00269;320,92114
0,32;0,00466;334,91165
0,4;0,00622;345,13869
0,48;0,00789;354,01713
0,56;0,00933;358,85794
0,64;0,01076;359,91543
0,72;0,01214;360,69755
0,8;0,01345;360,12605
0,88;0,01483;360,17825
0,96;0,01602;358,76418
1,04;0,01734;358,01393
1,12;0,01877;359,27317
1,2;0,02009;358,44017
1,28;0,0214;358,19719
1,36;0,02272;358,15551
1,44;0,0241;358,8804
1,52;0,02547;358,17584
1,6;0,02661;358,64203
1,68;0,02798;358,14964
1,76;0,02942;359,23347
1,84;0,03073;359,24101
1,92;0,03211;358,91058
2;0,03342;358,85358
2,08;0,0348;359,10427
2,16;0,03617;358,77079
2,24;0,03731;357,83111
2,32;0,03868;357,4034
2,4;0,04012;358,03053
2,48;0,04137;357,34111
2,56;0,04275;357,30361
2,64;0,04412;356,54616
2,72;0,0455;356,78709
2,8;0,04682;356,86803
2,88;0,04795;356,08103
2,96;0,04945;356,56628
3,04;0,05076;356,72961
3,12;0,05214;356,91834
3,2;0,05351;356,768
3,28;0,05483;356,14513
3,36;0,0562;356,63936
3,44;0,05746;356,07154
3,52;0,05865;355,36538
3,6;0,06015;356,69818
3,68;0,06146;357,06875
3,76;0,06278;356,85578
3,84;0,06409;355,94781
3,92;0,06547;356,48227
4;0,06684;357,18994
4,08;0,06804;355,11609
4,16;0,0693;354,70403
4,24;0,07079;356,57685
4,32;0,07211;356,9606
4,4;0,07342;356,30665
4,48;0,07474;356,77841
4,56;0,07611;356,31775
4,64;0,07755;356,92751
4,72;0,07868;355,52555
4,8;0,07994;354,49869
4,88;0,08149;356,12667
4,96;0,08281;355,86585
5,04;0,08418;355,63726
5,12;0,0855;356,1439
5,2;0,08687;357,26014
5,28;0,08819;360,09075
5,36;0,08933;362,08145
5,44;0,09064;365,98404
5,52;0,09214;373,02664
5,6;0,09345;377,66339
5,68;0,09477;382,54238
5,76;0,09608;388,58864
5,84;0,09752;393,76048
5,92;0,09889;399,42916
6;0,10003;403,12358
6,08;0,1014;407,23528
6,16;0,10284;413,8255
6,24;0,10415;417,58791
6,32;0,10553;423,36597
6,4;0,10684;428,25602
6,48;0,10822;433,89862
6,56;0,10953;438,98793
6,64;0,11061;442,98274
6,72;0,11205;447,83596
6,8;0,11348;454,25491
6,88;0,1148;458,58533
6,96;0,11611;463,47645
7,04;0,11743;468,81973
7,12;0,1188;473,20398
7,2;0,12012;479,04258
7,28;0,12131;483,92913
7,36;0,12269;488,87264
7,44;0,12412;495,16372
7,52;0,12544;499,88818
7,6;0,12681;504,41809
7,68;0,12813;509,64304
7,76;0,1295;515,1582
7,84;0,13082;520,90855
7,92;0,13196;523,7916
8;0,13345;529,31332
8,08;0,13483;538,31832
8,16;0,13614;541,23485
8,24;0,13746;546,41063
8,32;0,13877;549,88936
8,4;0,14021;555,63357
8,48;0,1414;559,74354
8,56;0,1426;563,09099
8,64;0,14415;569,26599
8,72;0,14547;574,50365
8,8;0,14684;578,37153
8,88;0,14816;583,5345
8,96;0,14947;586,75394
9,04;0,15085;592,13941
9,12;0,1521;596,1969
9,2;0,15336;599,46389
9,28;0,15485;605,47073
9,36;0,15617;611,20582
9,44;0,15749;615,32403
9,52;0,1588;620,8634
9,6;0,16018;624,73738
9,68;0,16155;630,96108
9,76;0,16275;634,87203
9,84;0,16394;638,74498
9,92;0,16544;644,0979
10;0,16681;652,67845
10,08;0,16813;656,86726
10,16;0,1695;662,69436
10,24;0,17088;668,1351
10,32;0,17213;672,96545
10,4;0,17333;676,40971
10,48;0,1747;681,48575
10,56;0,17614;688,03169
10,64;0,17746;692,31489
10,72;0,17883;697,90934
10,8;0,18015;702,46868
10,88;0,18152;708,43641
10,96;0,18278;713,15086
11,04;0,18397;716,10571
11,12;0,18541;721,36996
11,2;0,18678;726,76502
11,28;0,1881;731,0872
11,36;0,18941;736,39331
11,44;0,19079;741,00178
11,52;0,19216;746,05248
11,6;0,19348;751,12269
11,68;0,19461;754,41925
11,76;0,19611;759,62935
11,84;0,19748;765,25183
11,92;0,1988;768,56874
12;0,20012;772,79368
12,08;0,20149;778,05775
12,16;0,20293;783,37397
12,24;0,20406;791,19159
12,32;0,20532;793,19039
12,4;0,20681;798,41809
12,48;0,20813;802,88323
12,56;0,2095;807,66939
12,64;0,21082;811,33563
12,72;0,21213;816,52394
12,8;0,21351;821,68272
12,88;0,2147;824,45899
12,96;0,21602;829,06196
13,04;0,21751;834,42423
13,12;0,21877;839,09826
13,2;0,22014;842,73508
13,28;0,22146;848,40413
13,36;0,22284;852,22321
13,44;0,22415;856,81845
13,52;0,22535;860,68176
13,6;0,22666;865,26172
13,68;0,22816;871,01599
13,76;0,22941;876,13054
13,84;0,23079;879,76763
13,92;0,2321;884,68101
14;0,23348;889,54782
14,08;0,23485;894,3676
14,16;0,23599;897,43333
14,24;0,23736;901,68733
14,32;0,2388;906,5791
14,4;0,24017;913,22809
14,48;0,24149;917,5525
14,56;0,24281;922,19161
14,64;0,24418;925,98554
14,72;0,2455;930,5343
14,8;0,24663;933,47915
14,88;0,24807;937,60565
14,96;0,2495;943,08313
15,04;0,25082;947,16512
15,12;0,25213;951,57865
15,2;0,25351;955,84439
15,28;0,25488;961,42031
15,36;0,25614;965,29601
15,44;0,25733;967,9527
15,52;0,25877;972,775
15,6;0,26008;976,31039
15,68;0,2614;980,11969
15,76;0,26277;984,79958
15,84;0,26415;989,58584
15,92;0,26558;995,02197
16;0,26678;999,52715
16,08;0,26798;1002,44302
16,16;0,26947;1007,20897
16,24;0,27079;1012,99463
16,32;0,27216;1016,49947
16,4;0,27348;1020,76177
16,48;0,27485;1024,64538
16,56;0,27623;1029,77278
16,64;0,27736;1032,57038
16,72;0,27868;1035,44202
16,8;0,28017;1041,51834
16,88;0,28143;1045,4705
16,96;0,2828;1049,79882
17,04;0,28412;1053,02893
17,12;0,28549;1056,93229
17,2;0,28687;1061,68222
17,28;0,28801;1064,86483
17,36;0,28932;1067,76161
17,44;0,29076;1073,17073
17,52;0,29189;1076,48559
17,6;0,29351;1082,76792
17,68;0,29482;1086,17358
17,76;0,2962;1089,06245
17,84;0,29745;1093,8392
17,92;0,29865;1095,9561
18;0,30008;1100,1003
18,08;0,30146;1104,54233
18,16;0,30277;1107,56718
18,24;0,30415;1113,04373
18,32;0,30546;1121,95192
18,4;0,30684;1120,07717
18,48;0,3081;1123,1686
18,56;0,30929;1125,37602
18,64;0,31073;1128,6634
18,72;0,31216;1133,49613
18,8;0,31348;1137,01047
18,88;0,31479;1140,25511
18,96;0,31611;1144,76457
19,04;0,31748;1146,92906
19,12;0,3188;1150,41519
19,2;0,31999;1152,45646
19,28;0,32143;1156,46906
19,36;0,3228;1160,53754
19,44;0,32418;1163,74092
19,52;0,32549;1167,3213
19,6;0,32681;1170,77781
19,68;0,32824;1174,08959
19,76;0,32938;1177,22489
19,84;0,33058;1179,01061
19,92;0,33195;1182,99685
20;0,33351;1188,1059
20,08;0,33482;1191,39887
20,16;0,33614;1195,4925
20,24;0,33745;1198,79432
20,32;0,33889;1202,00887
20,4;0,34002;1204,23175
20,48;0,34128;1207,02637
20,56;0,34277;1211,17765
20,64;0,34409;1214,833
20,72;0,34546;1218,3045
20,8;0,34678;1221,28306
20,88;0,34815;1224,71461
20,96;0,34953;1229,24894
21,04;0,35067;1230,71261
21,12;0,35204;1234,12684
21,2;0,35348;1238,88412
21,28;0,35479;1241,99633
21,36;0,35605;1245,22019
21,44;0,35736;1248,25677
21,52;0,3588;1252,18034
21,6;0,36011;1256,29799
21,68;0,36131;1258,38825
21,76;0,36274;1260,79777
21,84;0,36418;1265,56037
21,92;0,36549;1269,20315
22;0,36681;1271,97811
22,08;0,36812;1274,68472
22,16;0,36956;1278,71027
22,24;0,37081;1282,14993
22,32;0,37201;1283,44055
22,4;0,37345;1288,57959
22,48;0,37482;1292,73683
22,56;0,37614;1295,23855
22,64;0,37751;1298,60267
22,72;0,37883;1301,47627
22,8;0,3802;1304,57301
22,88;0,38146;1307,43198
22,96;0,38265;1310,6497
23,04;0,38409;1313,82719
23,12;0,38546;1317,7502
23,2;0,38678;1320,12563
23,28;0,38815;1323,16016
23,36;0,38953;1325,76041
23,44;0,3909;1328,97515
23,52;0,3921;1331,34937
23,6;0,3933;1333,12494
23,68;0,39479;1338,2256
23,76;0,39611;1342,04701
23,84;0,39748;1344,385
23,92;0,39886;1347,81543
24;0,40017;1349,77736
24,08;0,40149;1352,73999
24,16;0,40274;1354,96315
24,24;0,404;1356,77801
24,32;0,40543;1360,56775
24,4;0,40675;1364,15493
24,48;0,40812;1366,62386
24,56;0,40944;1369,78114
24,64;0,41081;1372,00002
24,72;0,41213;1374,52148
24,8;0,41332;1376,42091
24,88;0,4147;1378,40118
24,96;0,41613;1381,97094
25,04;0,41745;1383,9649
25,12;0,41883;1386,91058
25,2;0,4202;1389,23395
25,28;0,42158;1391,31239
25,36;0,42289;1393,20595
25,44;0,42397;1394,03725
25,52;0,42534;1395,80816
25,6;0,42678;1398,08757
25,68;0,42815;1399,99026
25,76;0,42947;1371,86795
25,84;0,43084;1378,29734
25,92;0,43222;1383,55643
26;0,43347;1386,14345
26,08;0,43467;1388,94776
26,16;0,43604;1390,53939
26,24;0,43748;1394,46985
26,32;0,4388;1396,79853
26,4;0,44017;1399,41685
26,48;0,44149;1401,48522
26,56;0,44286;1404,93587
26,64;0,44418;1408,21384
26,72;0,44537;1408,40719
26,8;0,44675;1411,9559
26,88;0,44812;1415,24263
26,96;0,44944;1418,347
27,04;0,45081;1420,92565
27,12;0,45207;1423,73359
27,2;0,4535;1426,29994
27,28;0,45476;1429,97783
27,36;0,45595;1431,11991
27,44;0,45745;1435,33582
27,52;0,45876;1438,3059
27,6;0,46008;1441,11766
27,68;0,46146;1443,24601
27,76;0,46283;1446,75523
27,84;0,46421;1450,15875
27,92;0,4654;1452,45278
28;0,4666;1453,83356
28,08;0,46815;1457,73562
28,16;0,46947;1461,914
28,24;0,47078;1463,02786
28,32;0,4721;1466,91678
28,4;0,47347;1470,7
28,48;0,47485;1474,40275
28,56;0,47598;1475,66041
28,64;0,4773;1477,62857
28,72;0,47879;1482,31266
28,8;0,48005;1485,08521
28,88;0,48142;1487,8232
28,96;0,4828;1490,72222
29,04;0,48418;1494,21953
29,12;0,48549;1496,86672
29,2;0,48663;1498,12046
29,28;0,48806;1500,32975
29,36;0,4895;1504,41006
29,44;0,49081;1507,13893
29,52;0,49219;1509,46472
29,6;0,4935;1512,61007
29,68;0,49482;1514,968
29,76;0,49613;1517,75982
29,84;0,49733;1518,88179
29,92;0,49876;1521,82141
30;0,50014;1525,43578
30,08;0,50139;1527,99599
30,16;0,50277;1530,73715
30,24;0,50409;1532,88553
30,32;0,50546;1536,18231
30,4;0,50678;1538,82829
30,48;0,50797;1540,28144
30,56;0,50947;1543,85837
30,64;0,51078;1546,42742
30,72;0,51216;1548,45472
30,8;0,51347;1551,89903
30,88;0,51479;1554,33156
30,96;0,51622;1556,5929
31,04;0,51742;1559,56903
31,12;0,51861;1560,95438
31,2;0,52011;1564,36637
31,28;0,52142;1566,63358
31,36;0,5228;1569,17349
31,44;0,52411;1571,48354
31,52;0,52549;1574,48687
31,6;0,52686;1578,19856
31,68;0,52806;1579,73878
31,76;0,52932;1581,26429
31,84;0,53081;1584,55819
31,92;0,53213;1587,15099
32;0,53344;1589,70524
32,08;0,53482;1593,59854
32,16;0,53619;1596,33849
32,24;0,53757;1598,1935
32,32;0,5387;1600,0744
32,4;0,54002;1601,95418
32,48;0,54145;1605,98122
32,56;0,54277;1606,75365
32,64;0,54414;1610,07363
32,72;0,54546;1612,29055
32,8;0,54683;1614,82934
32,88;0,54821;1616,96803
32,96;0,54929;1618,18489
33,04;0,55066;1619,63198
33,12;0,5521;1623,4111
33,2;0,55347;1626,68824
33,28;0,55479;1629,12346
33,36;0,5561;1630,98313
33,44;0,55754;1633,58022
33,52;0,55885;1635,88263
33,6;0,55999;1636,81693
33,68;0,56142;1639,2367
33,76;0,56286;1642,65446
33,84;0,56417;1645,09267
33,92;0,56549;1647,13711
34;0,5668;1648,83137
34,08;0,56824;1651,82985
34,16;0,56944;1653,8417
34,24;0,57063;1654,6879
34,32;0,57207;1657,46268
34,4;0,57344;1659,77404
34,48;0,57476;1661,7585
34,56;0,57607;1663,89626
34,64;0,57739;1666,46037
34,72;0,57882;1668,55399
34,8;0,58008;1671,00187
34,88;0,58127;1672,06284
34,96;0,58289;1677,23447
35,04;0,58414;1678,54056
35,12;0,58552;1680,39147
35,2;0,58683;1682,27293
35,28;0,58815;1683,70921
35,36;0,58952;1686,34187
35,44;0,59072;1687,71166
35,52;0,59204;1688,35856
35,6;0,59353;1691,32575
35,68;0,59479;1692,34741
35,76;0,5961;1695,27065
35,84;0,59748;1697,14224
35,92;0,59885;1699,71455
36;0,60017;1701,95196
36,08;0,60136;1702,61972
36,16;0,60268;1704,03942
36,24;0,60417;1707,2713
36,32;0,60543;1709,342
36,4;0,6068;1710,23346
36,48;0,60818;1712,18533
36,56;0,60955;1714,55666
36,64;0,61087;1716,95761
36,72;0,61201;1717,4704
36,8;0,61338;1718,71446
36,88;0,61482;1721,41585
36,96;0,61613;1722,97545
37,04;0,61745;1725,0523
37,12;0,61882;1727,34652
37,2;0,6202;1729,3442
37,28;0,62151;1730,99618
37,36;0,62265;1732,07466
37,44;0,62402;1733,78363
37,52;0,62546;1736,67204
37,6;0,62677;1738,20611
37,68;0,62815;1739,72752
37,76;0,62946;1741,89229
37,84;0,63084;1743,3526
37,92;0,63221;1747,77918
38;0,63335;1748,12265
38,08;0,63479;1750,14716
38,16;0,6361;1751,88705
38,24;0,63748;1753,55803
38,32;0,63879;1756,05584
38,4;0,64017;1756,99517
38,48;0,64154;1759,38252
38,56;0,6428;1760,72605
38,64;0,64399;1761,35581
38,72;0,64543;1764,03169
38,8;0,6468;1766,18919
38,88;0,64812;1768,57933
38,96;0,64949;1769,52686
39,04;0,65081;1771,48264
39,12;0,65218;1773,81523
39,2;0,65344;1774,74227
39,28;0,65469;1775,15205
39,36;0,65619;1778,90006
39,44;0,65751;1781,5778
39,52;0,65882;1782,53837
39,6;0,66014;1784,52544
39,68;0,66145;1786,13793
39,76;0,66289;1788,99728
39,84;0,66408;1789,98355
39,92;0,66534;1790,76754
40;0,66677;1793,74646
40,08;0,66809;1795,89875
40,16;0,66946;1797,49466
40,24;0,67078;1799,82875
40,32;0,67215;1801,20431
40,4;0,67353;1803,53504
40,48;0,67466;1804,55707
40,56;0,67604;1805,31293
40,64;0,67747;1809,03897
40,72;0,67879;1810,99325
40,8;0,68017;1812,67913
40,88;0,68154;1814,53172
40,96;0,68292;1816,01681
41,04;0,68417;1818,41515
41,12;0,68531;1818,9529
41,2;0,68668;1820,76544
41,28;0,68812;1823,47912
41,36;0,68943;1825,22703
41,44;0,69081;1827,60917
41,52;0,69212;1829,453
41,6;0,6935;1831,24635
41,68;0,69481;1833,88237
41,76;0,69595;1834,34188
41,84;0,69738;1837,61064
41,92;0,69876;1840,69574
42;0,70013;1842,94339
42,08;0,70151;1845,2879
42,16;0,70289;1847,73561
42,24;0,70426;1850,19504
42,32;0,7054;1852,32107
42,4;0,70665;1853,60629
42,48;0,70815;1858,11315
42,56;0,70946;1861,62833
42,64;0,71078;1863,694
42,72;0,71215;1866,53491
42,8;0,71347;1869,08618
42,88;0,71484;1872,92807
42,96;0,71604;1874,54373
43,04;0,71729;1875,84739
43,12;0,71885;1881,39547
43,2;0,7201;1884,22035
43,28;0,72148;1887,02028
43,36;0,7228;1889,2644
43,44;0,72417;1892,91667
43,52;0,72555;1894,98253
43,6;0,72668;1897,86628
43,68;0,728;1900,09698
43,76;0,72949;1905,72515
43,84;0,73081;1908,56569
43,92;0,73218;1911,68729
44;0,7335;1914,62915
44,08;0,73481;1917,07853
44,16;0,73619;1920,42459
44,24;0,73726;1921,9052
44,32;0,7387;1924,53656
44,4;0,74007;1928,23596
44,48;0,74139;1930,66653
44,56;0,74276;1933,71959
44,64;0,74408;1936,71566
44,72;0,74552;1940,32621
44,8;0,74683;1943,26937
44,88;0,74803;1945,3533
44,96;0,7494;1947,12654
45,04;0,75084;1951,96439
45,12;0,75215;1953,90042
45,2;0,75347;1957,02109
45,28;0,75478;1959,85176
45,36;0,75616;1963,3824
45,44;0,75753;1966,4295
45,52;0,75867;1967,79724
45,6;0,7601;1970,99857
45,68;0,76142;1974,03897
45,76;0,76273;1977,03727
45,84;0,76411;1979,76846
45,92;0,76543;1982,44229
46;0,76686;1985,18448
46,08;0,76812;1989,62428
46,16;0,76925;1989,58889
46,24;0,77075;1993,15306
46,32;0,77212;1997,17693
46,4;0,7735;1999,62631
46,48;0,77481;2002,62517
46,56;0,77613;2005,67115
46,64;0,77756;2008,24291
46,72;0,77882;2011,41294
46,8;0,77995;2013,15805
46,88;0,78139;2015,20473
46,96;0,78276;2019,50911
47,04;0,78408;2021,81935
47,12;0,78539;2024,3274
47,2;0,78671;2027,35402
47,28;0,78815;2031,74893
47,36;0,7894;2033,75239
47,44;0,7906;2035,00837
47,52;0,79209;2038,3738
47,6;0,79347;2042,56158
47,68;0,79478;2044,85096
47,76;0,7961;2047,2426
47,84;0,79747;2049,92797
47,92;0,79891;2053,61713
48;0,8001;2056,01528
48,08;0,8013;2057,74866
48,16;0,80285;2061,64476
48,24;0,80417;2065,13256
48,32;0,80548;2067,61286
48,4;0,8068;2069,92999
48,48;0,80817;2072,83236
48,56;0,80955;2076,28142
48,64;0,81069;2078,4352
48,72;0,81194;2080,82255
48,8;0,81356;2084,68698
48,88;0,81481;2087,85851
48,96;0,81613;2090,18085
49,04;0,8175;2093,23466
49,12;0,81888;2095,93326
49,2;0,82025;2098,9405
49,28;0,82139;2100,62228
49,36;0,82264;2102,99641
49,44;0,8242;2106,51997
49,52;0,82545;2109,34356
49,6;0,82677;2111,9494
49,68;0,82814;2114,58616
49,76;0,82958;2117,98232
49,84;0,83089;2120,83515
49,92;0,83197;2122,26789
50;0,83329;2124,4958
50,08;0,83478;2128,52228
50,16;0,8361;2131,79421
50,24;0,83741;2134,6692
50,32;0,83879;2137,11634
50,4;0,84016;2140,5682
50,48;0,84148;2143,43648
50,56;0,84267;2145,59436
50,64;0,84399;2147,51046
50,72;0,84572;2159,21625
50,8;0,84692;2161,91988
50,88;0,84811;2163,24385
50,96;0,84949;2165,8808
51,04;0,8508;2168,19439
51,12;0,852;2169,95515
51,2;0,85338;2171,89882
51,28;0,85481;2176,02514
51,36;0,85613;2178,14073
51,44;0,85744;2180,08701
51,52;0,85882;2182,27785
51,6;0,86019;2180,64226
51,68;0,86157;2177,9323
51,76;0,8627;2181,56837
51,84;0,86402;2184,54432
51,92;0,86551;2188,96139
52;0,86683;2192,33576
52,08;0,8682;2195,84443
52,16;0,86952;2198,28282
52,24;0,87083;2201,42826
52,32;0,87221;2204,1807
52,4;0,87335;2206,24972
52,48;0,87466;2208,28392
52,56;0,87616;2213,40824
52,64;0,87747;2215,52514
52,72;0,87885;2218,76688
52,8;0,88016;2221,32485
52,88;0,88148;2224,15142
52,96;0,88285;2227,96779
53,04;0,88399;2229,76152
53,12;0,8853;2231,92871
53,2;0,8868;2236,14518
53,28;0,88811;2239,48825
53,36;0,88949;2242,24497
53,44;0,8908;2244,56508
53,52;0,89218;2248,14471
53,6;0,89349;2251,60625
53,68;0,89463;2253,46852
53,76;0,89607;2255,58002
53,84;0,8975;2258,9067
53,92;0,89882;2262,78491
54;0,90013;2265,47848
54,08;0,90151;2267,89676
54,16;0,90288;2271,38214
54,24;0,90414;2274,30109
54,32;0,90521;2275,4455
54,4;0,90683;2282,96872
54,48;0,90808;2286,16707
54,56;0,90946;2288,75726
54,64;0,91083;2292,12139
54,72;0,91221;2295,11075
54,8;0,91352;2299,34454
54,88;0,91466;2299,6949
54,96;0,91603;2302,75039
55,04;0,91747;2305,97015
55,12;0,91879;2309,22792
55,2;0,92016;2311,74566
55,28;0,92148;2314,84212
55,36;0,92285;2317,54351
55,44;0,92417;2320,38554
55,52;0,9253;2321,76334
55,6;0,92668;2324,35036
55,68;0,92811;2328,71901
55,76;0,92943;2330,44606
55,84;0,9308;2334,01284
55,92;0,93218;2339,1623
56;0,93349;2342,15297
56,08;0,93475;2345,14475
56,16;0,93594;2346,31039
56,24;0,93744;2350,1914
56,32;0,93881;2353,69448
56,4;0,94013;2355,5221
56,48;0,94151;2358,51705
56,56;0,94282;2361,10836
56,64;0,9442;2364,29758
56,72;0,94539;2367,27167
56,8;0,94665;2368,75489
56,88;0,94814;2372,76889
56,96;0,94946;2375,66996
57,04;0,95077;2378,68316
57,12;0,95215;2382,40771
57,2;0,9534;2385,06701
57,28;0,95472;2386,74022
57,36;0,95603;2392,63885
57,44;0,95729;2394,21483
57,52;0,95878;2397,89896
57,6;0,9601;2401,01907
57,68;0,96147;2404,74083
57,76;0,96285;2407,75123
57,84;0,96417;2410,27791
57,92;0,96554;2413,69624
58;0,96668;2415,30016
58,08;0,96799;2417,54316
58,16;0,96949;2422,07982
58,24;0,9708;2424,86354
58,32;0,97212;2427,64652
58,4;0,97343;2430,57068
58,48;0,97481;2433,80107
58,56;0,97618;2437,23132
58,64;0,97732;2438,8494
58,72;0,97863;2442,27611
58,8;0,98013;2447,71335
58,88;0,98144;2449,6872
58,96;0,98282;2453,23107
59,04;0,98413;2456,33665
59,12;0,98557;2459,99712
59,2;0,98683;2463,84479
59,28;0,98796;2464,12437
59,36;0,98934;2467,54792
59,44;0,99077;2472,05868
59,52;0,99215;2475,23282
59,6;0,99352;2478,92421
59,68;0,99478;2482,34253
59,76;0,99621;2485,6139
59,84;0,99747;2489,51875
59,92;0,99866;2490,96174
60;1,0001;2494,47841
60,08;1,00147;2497,79634
60,16;1,00273;2500,9051
60,24;1,00404;2504,49702
60,32;1,00542;2508,03977
60,4;1,00686;2511,73936
60,48;1,00805;2514,98725
60,56;1,00925;2516,67127
60,64;1,0108;2520,53346
60,72;1,01212;2524,73783
60,8;1,01343;2527,70409
60,88;1,01481;2530,16297
60,96;1,01612;2535,30443
61,04;1,01756;2540,24751
61,12;1,01869;2541,86504
61,2;1,01995;2544,03576
61,28;1,0215;2547,92552
61,36;1,02276;2551,67242
61,44;1,02413;2554,28646
61,52;1,02545;2557,42669
61,6;1,02682;2561,09573
61,68;1,02814;2563,92136
61,76;1,02934;2566,9517
61,84;1,03071;2569,94497
61,92;1,03215;2573,84554
62;1,03346;2576,74977
62,08;1,03478;2580,08279
62,16;1,03615;2582,44853
62,24;1,03753;2586,54449
62,32;1,0389;2590,43556
62,4;1,04004;2592,54873
62,48;1,04135;2595,15811
62,56;1,04285;2599,75865
62,64;1,04416;2604,35175
62,72;1,04548;2607,35881
62,8;1,04685;2611,56168
62,88;1,04817;2614,87253
62,96;1,04948;2618,55014
63,04;1,05062;2621,31039
63,12;1,052;2624,17551
63,2;1,05349;2629,44605
63,28;1,05481;2633,05325
63,36;1,05618;2637,0883
63,44;1,0575;2641,74603
63,52;1,05887;2646,15994
63,6;1,06013;2649,86791
63,68;1,06132;2652,1774
63,76;1,0627;2656,6036
63,84;1,06413;2662,10679
63,92;1,06545;2667,00946
64;1,06688;2672,79018
64,08;1,0682;2677,18509
64,16;1,06951;2682,63165
64,24;1,07077;2687,43392
64,32;1,07197;2689,90342
64,4;1,0734;2695,26411
64,48;1,07478;2701,33968
64,56;1,07615;2706,05069
64,64;1,07747;2711,38977
64,72;1,07884;2715,63865
64,8;1,08022;2722,00387
64,88;1,08147;2725,9795
64,96001;1,08261;2729,93278
65,04;1,0841;2735,67382
65,12;1,08548;2741,39233
65,2;1,08685;2745,68759
65,28001;1,08817;2751,40833
65,36;1,08948;2756,35403
65,44;1,09086;2762,30946
65,52;1,09211;2767,00296
65,60001;1,09331;2769,78873
65,68;1,09475;2776,35716
65,76;1,09612;2783,13141
65,84001;1,0975;2788,44722
65,92001;1,09875;2793,389
66;1,10013;2798,09646
66,08;1,10156;2804,35514
66,16;1,10276;2808,46227
66,24001;1,10401;2813,06077
66,32;1,10545;2819,12293
66,4;1,10676;2823,30289
66,48;1,10814;2828,88599
66,56001;1,10945;2834,54917
66,64;1,11083;2839,56174
66,72;1,1122;2845,81576
66,8;1,11334;2849,02342
66,88001;1,11466;2853,81414
66,96001;1,11615;2860,08734
67,04;1,11741;2865,18801
67,12;1,11878;2870,46842
67,20001;1,1201;2876,21189
67,28001;1,12153;2883,2376
67,36;1,12279;2888,64113
67,44;1,12392;2891,9382
67,52001;1,12536;2897,25866
67,60001;1,12679;2904,36391
67,68;1,12811;2909,50779
67,76;1,12942;2914,93293
67,84001;1,1308;2919,77096
67,92001;1,13217;2925,60179
68;1,13343;2931,61105
68,08;1,13463;2936,20229
68,16;1,13612;2941,22119
68,24001;1,13744;2947,88107
68,32;1,13875;2952,14672
68,4;1,14013;2958,45456
68,48;1,1415;2963,9354
68,56001;1,14288;2969,77684
68,64001;1,14407;2973,99256
68,72;1,14527;2978,54804
68,8;1,14682;2985,10734
68,88001;1,14814;2991,64318
68,96001;1,14945;2996,47022
69,04;1,15083;3001,98309
69,12;1,1522;3008,45578
69,20001;1,15352;3013,32884
69,28001;1,15471;3018,80892
69,36;1,15591;3023,03582
69,44;1,15752;3032,15366
69,52001;1,15884;3036,67989
69,60001;1,16016;3043,14438
69,68;1,16147;3048,35308
69,76;1,16285;3053,47536
69,84001;1,16416;3060,31536
69,92001;1,16536;3064,58101
70;1,16667;3068,94928
70,08;1,16811;3075,45643
70,16;1,16942;3080,8391
70,24001;1,1708;3086,33242
70,32;1,17211;3092,90029
70,4;1,17343;3097,10279
70,48;1,1748;3103,77963
70,56001;1,176;3108,76295
70,64001;1,17731;3113,37877
70,72;1,17875;3120,39722
70,8;1,18012;3126,11759
70,88001;1,1815;3132,1127
70,96001;1,18282;3138,01728
71,04;1,18419;3144,08056
71,12;1,18551;3149,89574
71,20001;1,18664;3153,66499
71,28001;1,18802;3159,54462
71,36;1,18945;3166,05903
71,44;1,19077;3171,45139
71,52001;1,19214;3177,55975
71,60001;1,19346;3185,61457
71,68;1,19489;3191,33066
71,76;1,19609;3196,30578
71,84001;1,19728;3200,91918
71,92001;1,19878;3206,49594
72;1,20015;3213,17725
72,08;1,20147;3218,74097
72,16;1,20285;3224,22683
72,24001;1,20416;3229,54915
72,32;1,2056;3235,34496
72,4;1,20673;3241,06738
72,48;1,20799;3244,6336
72,56001;1,20948;3252,16167
72,64001;1,2108;3257,58867
72,72;1,21217;3263,54466
72,8;1,21349;3269,17283
72,88001;1,2148;3274,71308
72,96001;1,21624;3280,1725
73,04;1,21737;3285,5697
73,12;1,21863;3289,93239
73,20001;1,22012;3297,30622
73,28001;1,22144;3302,7377
73,36;1,22275;3308,45453
73,44;1,22407;3314,53085
73,52001;1,22545;3319,97126
73,60001;1,22682;3327,10035
73,68;1,22802;3331,22425
73,76;1,22933;3336,29102
73,84001;1,23089;3343,30611
73,92001;1,23214;3349,02145
74;1,23346;3354,76622
74,08;1,23477;3360,12766
74,16;1,23573;3365,51629
74,24001;1,23752;3377,31391
74,32001;1,23866;3379,54275
74,4;1,24009;3385,12845
74,48;1,24147;3391,68757
74,56001;1,24278;3396,48426
74,64001;1,2441;3403,05604
74,72;1,24547;3408,0375
74,8;1,24685;3414,21291
74,88001;1,24811;3418,95521
74,96001;1,2493;3423,2799
75,04;1,25086;3429,28246
75,12;1,25217;3435,81699
75,20001;1,25349;3441,28869
75,28001;1,25486;3447,54085
75,36;1,25624;3453,53484
75,44;1,25755;3458,76701
75,52001;1,25875;3463,69632
75,60001;1,26;3468,10557
75,68;1,2615;3474,56262
75,76;1,26275;3480,14012
75,84001;1,26407;3485,79697
75,92001;1,26544;3491,42887
76;1,26682;3497,76894
76,08;1,26819;3503,85532
76,16;1,26939;3509,03682
76,24001;1,27065;3513,60776
76,32001;1,27214;3521,29005
76,4;1,27346;3527,07207
76,48;1,27477;3532,19472
76,56001;1,27615;3538,10191
76,64001;1,27752;3544,35742
76,72;1,27872;3551,00632
76,8;1,28003;3557,3855
76,88001;1,28141;3561,35033
76,96001;1,28278;3568,92273
77,04;1,2841;3574,04537
77,12;1,28547;3579,40607
77,20001;1,28679;3585,56397
77,28001;1,2881;3590,72648
77,36;1,28948;3597,21594
77,44;1,29068;3602,01448
77,52001;1,29205;3607,421
77,60001;1,29349;3614,68866
77,68;1,2948;3620,83018
77,76;1,29618;3626,21546
77,84001;1,29749;3631,38802
77,92001;1,29887;3637,7281
78;1,30018;3642,25172
78,08;1,30132;3647,01189
78,16;1,30269;3652,42548
78,24001;1,30413;3659,38954
78,32001;1,3055;3664,76811
78,4;1,30682;3670,98711
78,48;1,30819;3677,02506
78,56001;1,30951;3682,17863
78,64001;1,31082;3687,44731
78,72;1,31196;3692,02979
78,8;1,3134;3697,55588
78,88001;1,31483;3706,99465
78,96001;1,31615;3711,84833
79,04;1,31746;3718,8977
79,12;1,31878;3723,86463
79,20001;1,32021;3730,07767
79,28001;1,32147;3735,81983
79,36;1,32266;3739,9698
79,44;1,3241;3745,99509
79,52001;1,32547;3751,47238
79,60001;1,32679;3758,44352
79,68;1,32816;3763,69916
79,76;1,32948;3769,91779
79,84001;1,33085;3775,88235
79,92001;1,33205;3780,91261
80;1,33331;3785,40419
80,08;1,3348;3791,98231
80,16;1,33612;3797,99642
80,24001;1,33743;3802,96335
80,32001;1,33875;3808,28939
80,4;1,34012;3814,71589
80,48;1,3415;3821,40353
80,56001;1,34269;3826,76497
80,64001;1,34401;3831,77064
80,72;1,3455;3839,70663
80,8;1,34676;3844,97084
80,88001;1,34819;3852,71199
80,96001;1,34951;3857,77466
81,04;1,35088;3863,79585
81,12;1,35214;3870,29052
81,20001;1,35334;3873,98563
81,28001;1,35471;3879,51881
81,36;1,35615;3886,01348
81,44;1,35746;3892,4668
81,52001;1,35878;3897,84798
81,60001;1,36009;3903,84607
81,68;1,36153;3910,2599
81,76;1,36278;3915,37696
81,84001;1,36392;3920,00675
81,92001;1,36541;3926,69402
82,00001;1,36685;3933,53589
82,08;1,36816;3939,48369
82,16;1,36954;3945,11707
82,24001;1,37085;3951,16471
82,32001;1,37217;3956,38794
82,4;1,37342;3963,15679
82,48;1,37474;3968,59907
82,56001;1,37617;3977,30321
82,64001;1,37743;3983,11019
82,72;1,37881;3989,33031
82,8;1,38006;3994,25104
82,88001;1,38144;4000,82357
82,96001;1,38281;4006,04196
83,04;1,38401;4010,64269
83,12;1,38532;4015,32389
83,20001;1,38676;4022,27566
83,28001;1,38813;4027,62145
83,36;1,38951;4034,39961
83,44;1,39082;4040,49642
83,52001;1,39214;4045,52035
83,60001;1,39351;4051,59332
83,68;1,39465;4056,44812
83,76;1,39602;4061,72164
83,84001;1,39746;4068,65925
83,92001;1,39878;4074,02515
84,00001;1,40015;4080,02511
84,08;1,40147;4086,08466
84,16;1,40284;4092,32192
84,24001;1,40416;4098,6374
84,32001;1,40535;4102,43645
84,4;1,40667;4107,77107
84,48;1,4081;4115,20191
84,56001;1,40942;4119,18983
84,64001;1,41073;4125,98588
84,72;1,41205;4131,30969
84,8;1,41348;4138,1713
84,88001;1,41486;4144,33554
84,96001;1,41599;4149,62135
85,04;1,41737;4154,38488
85,12;1,4188;4161,4119
85,20001;1,41994;4167,7203
85,28001;1,42155;4178,67005
85,36;1,42281;4183,68131
85,44;1,42425;4189,84629
85,52001;1,42538;4195,74864
85,60001;1,42664;4200,50547
85,68;1,42813;4207,27395
85,76;1,42951;4213,82226
85,84001;1,43082;4219,46645
85,92001;1,43214;4224,47622
86,00001;1,43345;4230,15766
86,08;1,43489;4237,08446
86,16;1,43608;4241,60399
86,24001;1,43734;4246,87751
86,32001;1,43883;4254,16268
86,4;1,44015;4260,6324
86,48;1,44146;4265,26368
86,56001;1,44284;4271,34186
86,64001;1,44416;4277,20025
86,72;1,44553;4282,88803
86,8;1,44667;4288,48229
86,88001;1,44798;4293,44587
86,96001;1,44954;4300,36746
87,04;1,45079;4305,85593
87,12;1,45211;4311,7512
87,20001;1,45342;4317,8644
87,28001;1,45486;4323,6196
87,36;1,45623;4330,4272
87,44;1,45731;4334,38942
87,52001;1,45862;4340,29698
87,60001;1,46018;4347,69467
87,68001;1,46149;4354,61551
87,76;1,46287;4360,34724
87,84001;1,46413;4365,76083
87,92001;1,4655;4371,69932
88,00001;1,46688;4377,65867
88,08;1,46801;4382,97875
88,16;1,46951;4390,81192
88,24001;1,47088;4399,34544
88,32001;1,47214;4404,33733
88,4;1,47345;4410,63009
88,48;1,47483;4415,8414
88,56001;1,4762;4423,09231
88,64001;1,47746;4427,99777
88,72;1,47859;4432,45955
88,8;1,48009;4438,67482
88,88001;1,48146;4444,8562
88,96001;1,48278;4450,27836
89,04;1,48415;4456,8263
89,12;1,48553;4463,04828
89,20001;1,4869;4469,2222
89,28001;1,4881;4474,46033
89,36;1,4893;4478,79061
89,44;1,49073;4485,1061
89,52001;1,49211;4492,03625
89,60001;1,49342;4497,87639
89,68001;1,4948;4502,77068
89,76;1,49617;4510,0756
89,84001;1,49749;4515,55438
89,92001;1,49874;4521,10656
90,00001;1,5;4525,94496
90,08;1,50143;4532,66539
90,16;1,50275;4539,70619
90,24001;1,50412;4544,95214
90,32001;1,5055;4551,46953
90,4;1,50681;4557,63638
90,48;1,50819;4563,99731
90,56001;1,50945;4572,09013
90,64001;1,5107;4576,6715
90,72;1,51214;4584,87198
90,8;1,51345;4589,07783
90,88001;1,51483;4595,39406
90,96001;1,51614;4600,63741
91,04;1,51752;4607,26582
91,12;1,51889;4613,53883
91,20001;1,52003;4617,94697
91,28001;1,52134;4623,34268
91,36;1,52278;4630,0184
91,44;1,52409;4636,4814
91,52001;1,52547;4642,74436
91,60001;1,52678;4648,82366
91,68001;1,52816;4653,67287
91,76;1,52947;4660,13178
91,84001;1,53067;4665,72344
91,92001;1,53205;4671,12921
92,00001;1,53354;4678,59246
92,08;1,53486;4684,21914
92,16;1,53617;4690,00973
92,24001;1,53749;4695,91804
92,32001;1,53886;4701,72949
92,4;1,54018;4707,72907
92,48;1,54131;4712,58238
92,56001;1,54275;4717,61823
92,64001;1,54412;4725,26103
92,72;1,54544;4731,27775
92,8;1,54681;4737,28105
92,88001;1,54813;4743,48702
92,96001;1,5495;4749,40725
93,04;1,55076;4755,27309
93,12;1,55196;4759,7751
93,20001;1,55339;4766,60319
93,28001;1,55477;4775,20786
93,36001;1,55614;4780,66392
93,44;1,55746;4786,81065
93,52001;1,55883;4793,98742
93,60001;1,56021;4799,87711
93,68001;1,5614;4805,25121
93,76;1,5626;4809,00519
93,84001;1,56409;4815,83029
93,92001;1,56547;4822,26424
94,00001;1,56678;4828,74848
94,08;1,56816;4834,53684
94,16;1,56947;4839,71313
94,24001;1,57091;4846,76957
94,32001;1,57199;4852,23271
94,4;1,5733;4855,64955
94,48;1,57474;4863,23312
94,56001;1,57605;4869,36308
94,64001;1,57743;4874,96108
94,72;1,5788;4881,16927
94,8;1,58018;4888,14302
94,88001;1,58155;4894,10423
94,96001;1,58269;4898,34175
95,04;1,584;4903,22709
95,12;1,5855;4910,8699
95,20001;1,58681;4916,68321
95,28001;1,58813;4922,34193
95,36001;1,5895;4927,86281
95,44;1,59082;4933,98309
95,52001;1,59213;4939,38066
95,60001;1,59333;4944,74694
95,68001;1,59471;4950,76962
95,76;1,59614;4958,18257
95,84001;1,5974;4963,04259
95,92001;1,59877;4969,9951
96,00001;1,60009;4975,76781
96,08;1,60146;4981,15197
96,16;1,60278;4988,28217
96,24001;1,60391;4993,52999
96,32001;1,60535;4998,79159
96,4;1,60678;5007,86602
96,48;1,6081;5013,46402
96,56001;1,60947;5018,88916
96,64001;1,61079;5025,06867
96,72;1,61216;5030,70652
96,8;1,61342;5036,37828
96,83;1,61384;5038,2264