File: SU - Suspension/test en traction/Courbes/triangles/Specimen_RawData_1.csv
Temps;Déplacement;Charge
(sec);(mm);(N)
0;0,00006;329,53664
0,08;0,00018;330,02689
0,16;0,00072;330,82254
0,24;0,00203;335,64905
0,32;0,00371;347,15859
0,4;0,00556;359,79713
0,48;0,00735;372,49548
0,56;0,00897;384,5375
0,64;0,01046;394,603
0,72;0,01196;404,7181
0,8;0,01339;413,48124
0,88;0,01453;421,93541
0,96;0,01584;430,16858
1,04;0,01734;440,18594
1,12;0,01859;448,29627
1,2;0,01997;456,77759
1,28;0,02129;465,49276
1,36;0,02272;474,23672
1,44;0,02404;483,92951
1,52;0,02511;489,71968
1,6;0,02649;498,60324
1,68;0,02804;508,11456
1,76;0,02936;516,4525
1,84;0,03067;524,83976
1,92;0,03205;533,77431
2;0,03348;542,51095
2,08;0,03468;550,17006
2,16;0,03587;556,67842
2,24;0,03737;565,23443
2,32;0,03868;574,22654
2,4;0,04;581,25234
2,48;0,04131;588,99811
2,56;0,04269;598,22155
2,64;0,04406;606,30003
2,72;0,04532;612,74692
2,8;0,04652;620,24468
2,88;0,04801;628,0561
2,96;0,04939;637,32928
3,04;0,0507;645,0464
3,12;0,05202;653,62966
3,2;0,05339;660,70668
3,28;0,05483;669,86093
3,36;0,05602;676,2635
3,44;0,05716;681,62167
3,52;0,05871;690,61578
3,6;0,06009;699,15517
3,68;0,0614;706,15481
3,76;0,06272;712,72855
3,84;0,06409;720,86193
3,92;0,06541;728,26808
4;0,06661;734,88592
4,08;0,06786;740,94236
4,16;0,06936;748,80794
4,24;0,07067;757,2508
4,32;0,07199;763,99944
4,4;0,0733;771,6347
4,48;0,07468;778,6585
4,56;0,07605;786,35719
4,64;0,07731;793,03449
4,72;0,07856;799,29493
4,8;0,08006;806,40223
4,88;0,08137;814,0835
4,96;0,08275;822,0451
5,04;0,08406;829,18731
5,12;0,08538;836,3883
5,2;0,08675;843,59301
5,28;0,08795;849,5518
5,36;0,08921;854,95925
5,44;0,0907;863,58599
5,52;0,09196;870,21682
5,6;0,09333;877,89567
5,68;0,09465;883,59285
5,76;0,09602;890,63235
5,84;0,0974;898,94254
5,92;0,09853;904,74524
6;0,09991;911,30901
6,08;0,10134;919,30553
6,16;0,10266;924,97077
6,24;0,10409;932,14596
6,32;0,10541;937,90088
6,4;0,10678;945,05949
6,48;0,1081;951,90303
6,56;0,10924;956,2945
6,64;0,11061;962,39606
6,72;0,11199;970,11589
6,8;0,1133;975,73763
6,88;0,11468;981,14759
6,96;0,11599;988,17665
7,04;0,11737;994,66844
7,12;0,11868;1000,61931
7,2;0,11982;1005,73543
7,28;0,12131;1012,94136
7,36;0,12269;1019,6574
7,44;0,12406;1025,5863
7,52;0,12538;1032,62747
7,6;0,12669;1037,99691
7,68;0,12813;1044,26797
7,76;0,12932;1049,50629
7,84;0,13058;1054,53879
7,92;0,13207;1060,85036
8;0,13339;1067,38526
8,08;0,13471;1073,06065
8,16;0,13602;1078,95015
8,24;0,1374;1084,72696
8,32;0,13877;1090,62018
8,4;0,13991;1094,88387
8,48;0,14122;1099,10788
8,56;0,14266;1106,20344
8,64;0,14397;1112,3538
8,72;0,14535;1117,34299
8,8;0,14666;1123,02685
8,88;0,14804;1128,97381
8,96;0,14941;1135,16245
9,04;0,15055;1139,03871
9,12;0,15193;1143,758
9,2;0,15342;1150,11064
9,28;0,15474;1155,35716
9,36;0,15605;1160,11649
9,44;0,15743;1165,39318
9,52;0,15874;1171,2824
9,6;0,16006;1176,18022
9,68;0,16119;1179,84554
9,76;0,16263;1184,84618
9,84;0,164;1190,94197
9,92;0,16532;1195,69572
10;0,16663;1200,69608
10,08;0,16795;1205,63796
10,16;0,16938;1211,34771
10,24;0,1707;1216,69509
10,32;0,17183;1219,90712
10,4;0,17333;1224,88756
10,48;0,1747;1230,87484
10,56;0,17608;1235,56349
10,64;0,1774;1240,63296
10,72;0,17877;1245,20408
10,8;0,18015;1250,48533
10,88;0,18134;1254,80574
10,96;0,18254;1258,27892
11,04;0,18403;1263,30135
11,12;0,18535;1268,99444
11,2;0,18666;1273,367
11,28;0,18804;1278,00656
11,36;0,18929;1281,77674
11,44;0,19073;1286,76882
11,52;0,19198;1291,5385
11,6;0,19318;1295,05582
11,68;0,19467;1300,38401
11,76;0,19599;1304,61762
11,84;0,19737;1308,76182
11,92;0,19874;1313,47962
12;0,20006;1317,53748
12,08;0,20143;1321,87381
12,16;0,20269;1325,68162
12,24;0,20388;1328,729
12,32;0,20538;1334,75428
12,4;0,20669;1338,36903
12,48;0,20801;1342,88212
12,56;0,20932;1346,68257
12,64;0,2107;1350,0833
12,72;0,21207;1355,10778
12,8;0,21327;1357,5701
12,88;0,21452;1360,59113
12,96;0,21602;1365,85245
13,04;0,21739;1369,30132
13,12;0,21871;1373,41889
13,2;0,22003;1376,79689
13,28;0,2214;1380,80399
13,36;0,22272;1384,12639
13,44;0,22391;1386,49959
13,52;0,22523;1388,80797
13,6;0,22672;1394,44619
13,68;0,22804;1398,64096
13,76;0,22941;1402,6151
13,84;0,23073;1406,35306
13,92;0,2321;1410,174
14;0,23342;1413,95098
14,08;0,23455;1416,07178
14,16;0,23593;1419,7777
14,24;0,23736;1424,32908
14,32;0,23862;1427,34041
14,4;0,24;1430,74924
14,48;0,24137;1435,36581
14,56;0,24281;1439,47545
14,64;0,24406;1443,20345
14,72;0,2452;1444,74171
14,8;0,24663;1448,8345
14,88;0,24807;1453,04371
14,96;0,24938;1456,05877
15,04;0,2507;1459,29419
15,12;0,25207;1463,38148
15,2;0,25345;1467,23036
15,28;0,2547;1469,78935
15,36;0,2559;1472,35189
15,44;0,25733;1475,30418
15,52;0,25871;1480,3892
15,6;0,26002;1483,59016
15,68;0,26134;1486,76336
15,76;0,26266;1489,88385
15,84;0,26409;1494,01119
15,92;0,26535;1497,70901
16;0,26654;1499,84406
16,08;0,26798;1502,59249
16,16;0,26935;1506,96812
16,24;0,27067;1509,73415
16,32;0,27204;1512,88286
16,4;0,27342;1515,92344
16,48;0,27479;1519,80268
16,56;0,27605;1523,54734
16,64;0,27718;1524,85082
16,72;0,27874;1529,18333
16,8;0,28005;1535,20666
16,88;0,28143;1536,91238
16,96;0,28274;1539,85992
17,04;0,28406;1542,693
17,12;0,28538;1545,56455
17,2;0,28663;1547,438
17,28;0,28789;1549,78158
17,36;0,28944;1553,08638
17,44;0,2907;1556,39509
17,52;0,29201;1558,52446
17,6;0,29339;1561,46027
17,68;0,2947;1563,15863
17,76;0,29614;1565,61602
17,84;0,29733;1568,163
17,92;0,29853;1569,36441
18;0,30002;1571,94305
18,08;0,30134;1573,88002
18,16;0,30271;1576,68479
18,24;0,30403;1578,82869
18,32;0,3054;1580,77218
18,4;0,30678;1581,90373
18,48;0,30798;1584,34063
18,56;0,30917;1584,07763
18,64;0,31067;1587,46578
18,72;0,31204;1589,06784
18,8;0,31336;1591,39782
18,88;0,31473;1592,49231
18,96;0,31605;1593,65777
19,04;0,31742;1595,29634
19,12;0,31856;1595,80242
19,2;0,31987;1596,4156
19,28;0,32137;1597,73007
19,36;0,32268;1599,13246
19,44;0,324;1599,72589
19,52;0,32537;1600,21875
19,6;0,32675;1600,97759
19,68;0,32812;1600,87999
19,76;0,32926;1599,59774
19,84;0,33052;1599,5685
19,92;0,33201;1600,51584
20;0,33333;1601,0277
20,08;0,33482;1604,80067
20,16;0,33614;1605,14675
20,24;0,33751;1604,65892
20,32;0,33865;1603,26622
20,4;0,33984;1601,73047
20,48;0,34134;1602,64075
20,56;0,34265;1603,41989
20,64;0,34403;1602,63348
20,72;0,34534;1602,91735
20,8;0,34672;1602,89686
20,88;0,34809;1602,98273
20,96;0,34929;1603,33365
21,04;0,35055;1601,9864
21,12;0,35204;1603,46664
21,2;0,35336;1604,17184
21,28;0,35467;1604,36928
21,36;0,35599;1604,4911
21,44;0,3573;1603,76672
21,52;0,35874;1604,44956
21,6;0,35993;1604,21617
21,68;0,36119;1603,49738
21,76;0,36268;1603,73226
21,84;0,364;1603,71065
21,92;0,36531;1602,94622
22;0,36669;1602,33565
22,08;0,368;1601,31715
22,16;0,36944;1600,97443
22,24;0,37058;1599,63127
22,32;0,37183;1597,97631
22,4;0,37339;1597,7649
22,48;0,37464;1597,5967
22,56;0,37602;1596,75963
22,64;0,37733;1596,14999
22,72;0,37871;1594,60604
22,8;0,38008;1595,61969
22,88;0,38122;1594,88954
22,96;0,38271;1598,86722
23,04;0,38403;1598,92086
23,12;0,38534;1599,49325
23,2;0,38666;1600,44823
23,28;0,38797;1600,95915
23,36;0,38935;1602,26561
23,44;0,39066;1603,57319
23,52;0,39186;1603,99508
23,6;0,3933;1606,17325
23,68;0,39467;1608,09513
23,76;0,39599;1610,82633
23,84;0,39736;1612,67165
23,92;0,39868;1615,93053
24;0,40011;1619,05289
24,08;0,40131;1621,37095
24,16;0,4025;1622,3371
24,24;0,404;1626,80037
24,32;0,40531;1631,73098
24,4;0,40669;1633,67614
24,48;0,408;1638,19864
24,56;0,40932;1640,60704
24,64;0,41075;1645,52703
24,72;0,41195;1647,96449
24,8;0,41321;1651,00936
24,88;0,4147;1655,64716
24,96;0,41602;1659,21729
25,04;0,41733;1663,71316
25,12;0,41865;1667,27975
25,2;0,42002;1671,03
25,28;0,42146;1676,51679
25,36;0,42259;1679,2709
25,44;0,42391;1680,81652
25,52;0,4254;1687,40302
25,6;0,42666;1690,98787
25,68;0,42797;1695,18609
25,76;0,42929;1698,13596
25,84;0,43072;1702,53795
25,92;0,4321;1707,35195
26;0,43323;1709,87807
26,08;0,43455;1713,32695
26,16;0,43616;1722,17749
26,24;0,43742;1726,02218
26,32;0,43868;1728,56227
26,4;0,43999;1732,43266
26,48;0,44143;1735,42798
26,56;0,44268;1739,24007
26,64;0,44388;1741,40111
26,72;0,44537;1745,14893
26,8;0,44675;1749,73104
26,88;0,448;1753,91827
26,96;0,44938;1756,13053
27,04;0,45075;1759,59356
27,12;0,45207;1763,20784
27,2;0,45332;1766,2866
27,28;0,45452;1768,02073
27,36;0,45601;1772,89955
27,44;0,45733;1777,4608
27,52;0,45865;1780,12773
27,6;0,46002;1783,61628
27,68;0,4614;1787,01021
27,76;0,46277;1789,82951
27,84;0,46397;1793,06101
27,92;0,46516;1795,3977
28;0,46666;1799,45063
28,08;0,46803;1803,66095
28,16;0,46935;1806,98298
28,24;0,47072;1810,67213
28,32;0,47204;1814,10033
28,4;0,47341;1817,87647
28,48;0,47461;1820,00548
28,56;0,47586;1821,69154
28,64;0,47742;1827,82114
28,72;0,47867;1831,69432
28,8;0,48005;1835,48573
28,88;0,48137;1838,13609
28,96;0,48274;1841,32885
29,04;0,48406;1844,13753
29,12;0,48531;1847,52569
29,2;0,48657;1849,3535
29,28;0,48806;1853,99652
29,36;0,48932;1857,12874
29,44;0,49069;1860,64262
29,52;0,49207;1864,61024
29,6;0,49344;1867,72738
29,68;0,49476;1872,14706
29,76;0,49595;1873,91452
29,84;0,49721;1875,79803
29,92;0,49852;1880,90559
30;0,50002;1885,81254
30,08;0,50139;1888,66705
30,16;0,50271;1892,40351
30,24;0,50409;1895,71418
30,32;0,5054;1899,5855
30,4;0,5066;1901,62268
30,48;0,50791;1904,39504
30,56;0,50941;1908,91363
30,64;0,51072;1912,64339
30,72;0,51204;1915,44611
30,8;0,51335;1919,37834
30,88;0,51479;1922,62027
30,96;0,5161;1926,87046
31,04;0,5173;1928,67164
31,12;0,51861;1931,54961
31,2;0,52005;1936,18238
31,28;0,52107;1939,33714
31,36;0,52274;1945,2421
31,44;0,524;1947,68179
31,52;0,52537;1951,1817
31,6;0,52669;1955,16869
31,68;0,52788;1958,06976
31,76;0,52932;1961,57862
31,84;0,53069;1965,88449
31,92;0,53201;1968,5762
32;0,53332;1971,88128
32,08;0,5347;1974,93136
32,16;0,53607;1979,05675
32,24;0,53733;1982,57733
32,32;0,53852;1984,643
32,4;0,54002;1989,563
32,48;0,54139;1994,21812
32,56;0,54271;1996,58703
32,64;0,54402;2000,1661
32,72;0,54534;2004,00203
32,8;0,54677;2008,04584
32,88;0,54797;2011,03631
32,96;0,54917;2013,78427
33,04;0,55066;2017,53285
33,12;0,55198;2021,72752
33,2;0,55329;2024,85304
33,28;0,55467;2028,92255
33,36;0,55604;2033,15411
33,44;0,55742;2036,83749
33,52;0,55855;2038,83033
33,6;0,55993;2041,58425
33,68;0,56142;2046,6717
33,76;0,56262;2049,74394
33,84;0,56411;2055,26687
33,92;0,56537;2058,27076
34;0,56674;2061,96271
34,08;0,568;2064,95821
34,16;0,5692;2067,67991
34,24;0,57063;2069,92533
34,32;0,57207;2075,92696
34,4;0,57332;2078,6101
34,48;0,5747;2082,20314
34,56;0,57601;2086,04503
34,64;0,57739;2089,11542
34,72;0,5787;2092,84034
34,8;0,5799;2095,21763
34,88;0,58127;2099,28956
34,96;0,58271;2102,63301
35,04;0,58402;2106,62484
35,12;0,5854;2110,55595
35,2;0,58671;2114,42765
35,28;0,58809;2117,91769
35,36;0,58934;2121,37438
35,44;0,59054;2123,91503
35,52;0,59198;2127,14635
35,6;0,59329;2131,14079
35,68;0,59467;2134,7113
35,76;0,59604;2140,33276
35,84;0,5973;2143,30014
35,92;0,59867;2147,66618
36;0,59993;2150,97759
36,08;0,60118;2152,65993
36,16;0,60268;2157,56409
36,24;0,60399;2161,61106
36,32;0,60537;2164,32102
36,4;0,60668;2167,57767
36,48;0,608;2171,18915
36,56;0,60949;2175,17056
36,64;0,61063;2178,091
36,72;0,61189;2179,94712
36,8;0,61338;2184,76132
36,88;0,6147;2188,10365
36,96;0,61607;2192,05171
37,04;0,61739;2195,07832
37,12;0,6187;2198,65665
37,2;0,62014;2203,64109
37,28;0,62127;2205,35137
37,36;0,62253;2207,29653
37,44;0,62402;2212,63822
37,52;0,62534;2216,01669
37,6;0,62671;2219,52666
37,68;0,62803;2222,67229
37,76;0,6294;2226,17164
37,84;0,63078;2231,15738
37,92;0,63192;2233,49109
38;0,63323;2236,02187
38,08;0,63473;2241,44347
38,16;0,63604;2244,96406
38,24;0,63736;2247,14614
38,32;0,63867;2251,32275
38,4;0,64011;2254,7368
38,48;0,64142;2258,33077
38,56;0,64256;2260,71812
38,64;0,64387;2262,86743
38,72;0,64537;2268,46207
38,8;0,64668;2271,39629
38,88;0,648;2274,61439
38,96;0,64931;2277,79318
39,04;0,65069;2281,45849
39,12;0,65206;2285,98714
39,2;0,6532;2288,05672
39,28;0,65464;2291,73545
39,36;0,65613;2299,90222
39,44;0,65745;2303,89349
39,52;0,65876;2307,52993
39,6;0,66002;2309,87612
39,68;0,66139;2312,96774
39,76;0,66265;2315,83733
39,84;0,6639;2317,78156
39,92;0,6654;2322,47114
40;0,66671;2325,50874
40,08;0,66803;2329,31674
40,16;0,6694;2332,65795
40,24;0,67072;2336,28713
40,32;0,67209;2339,92767
40,4;0,67329;2342,18519
40,48;0,67455;2344,71783
40,56;0,67604;2349,33253
40,64;0,67736;2352,45954
40,72;0,67867;2355,84918
40,8;0,68011;2359,20567
40,88;0,68148;2362,76928
40,96;0,6828;2365,70295
41,04;0,68399;2368,51852
41,12;0,68519;2370,86713
41,2;0,68668;2374,62111
41,28;0,688;2378,66919
41,36;0,68937;2382,2749
41,44;0,69075;2388,78578
41,52;0,69206;2391,9927
41,6;0,69338;2395,48869
41,68;0,69451;2398,02599
41,76;0,69595;2399,80388
41,84;0,69732;2404,86655
41,92;0,6987;2407,9863
42;0,70002;2411,64397
42,08;0,70139;2413,84376
42,16;0,70277;2417,64635
42,24;0,70408;2420,82607
42,32;0,70528;2423,11079
42,4;0,70665;2425,45921
42,48;0,70803;2430,3982
42,56;0,70934;2434,02217
42,64;0,71072;2436,9508
42,72;0,71203;2439,97946
42,8;0,71341;2443,65204
42,88;0,71472;2446,91912
42,96;0,71586;2448,49399
43,04;0,71723;2451,71189
43,12;0,71867;2456,39402
43,2;0,71999;2458,88103
43,28;0,72136;2462,80227
43,36;0,72268;2466,32062
43,44;0,72411;2469,24553
43,52;0,72537;2472,37831
43,6;0,72656;2473,59294
43,68;0,72776;2477,40727
43,76;0,72943;2485,1013
43,84;0,73075;2487,8297
43,92;0,73206;2490,51247
44;0,73338;2492,50568
44,08;0,73475;2495,7804
44,16;0,73601;2498,80124
44,24;0,7372;2499,49489
44,32;0,73864;2504,42587
44,4;0,73995;2507,90846
44,48;0,74133;2510,95481
44,56;0,74265;2512,90146
44,64;0,74396;2512,64032
44,72;0,7454;2516,66624
44,8;0,74659;2519,3423
44,88;0,74785;2522,47527
44,96;0,74934;2527,37757
45,04;0,75072;2531,61862
45,12;0,75203;2535,46275
45,2;0,75341;2539,00848
45,28;0,75478;2542,32865
45,36;0,7561;2547,31867
45,44;0,75723;2549,21615
45,52;0,75855;2551,78791
45,6;0,76004;2557,76253
45,68;0,76136;2560,98937
45,76;0,76267;2564,78135
45,84;0,76405;2569,62404
45,92;0,76543;2573,59333
46;0,76668;2577,32309
46,08;0,76782;2579,47724
46,16;0,76931;2583,8431
46,24;0,77069;2588,0307
46,32;0,772;2591,38756
46,4;0,77338;2595,76738
46,48;0,77475;2598,63846
46,56;0,77613;2603,58155
46,64;0,77732;2606,7283
46,72;0,77852;2608,03439
46,8;0,78001;2612,8782
46,88;0,78139;2617,34016
46,96;0,7827;2621,48883
47,04;0,78408;2625,38847
47,12;0,78539;2628,34076
47,2;0,78671;2632,4667
47,28;0,78797;2635,87628
47,36;0,78916;2639,1698
47,44;0,7906;2644,19205
47,52;0,79197;2650,94135
47,6;0,79335;2654,82236
47,68;0,79472;2657,55616
47,76;0,79604;2663,19662
47,84;0,79741;2666,62464
47,92;0,79855;2669,88594
48;0,79992;2672,70561
48,08;0,80136;2678,84843
48,16;0,80267;2683,03361
48,24;0,80405;2687,64347
48,32;0,80536;2691,76085
48,4;0,80674;2696,56312
48,48;0,80805;2700,74997
48,56;0,80919;2704,01519
48,64;0,81057;2706,94885
48,72;0,812;2713,13302
48,8;0,81332;2716,29021
48,88;0,81469;2721,52983
48,96;0,81601;2725,99217
49,04;0,81738;2730,51485
49,12;0,8187;2735,00998
49,2;0,81989;2737,9103
49,28;0,82127;2741,63261
49,36;0,82276;2748,41636
49,44;0,82402;2754,0613
49,52;0,82539;2758,54506
49,6;0,82671;2761,72869
49,68;0,82808;2766,78186
49,76;0,8294;2771,00988
49,84;0,83054;2773,10032
49,92;0,83197;2777,35665
50;0,83335;2781,47925
50,08;0,83466;2784,95923
50,16;0,83604;2789,73095
50,24;0,83735;2793,48735
50,32;0,83879;2798,16538
50,4;0,84004;2802,24252
50,48;0,84118;2804,51961
50,56;0,84267;2808,99033
50,64;0,84405;2814,73901
50,72;0,84536;2818,52968
50,8;0,84668;2822,67425
50,88;0,84799;2826,47926
50,96;0,84943;2830,72833
51,04;0,85068;2834,59648
51,12;0,85188;2837,56889
51,2;0,85338;2843,02123
51,28;0,85469;2847,4953
51,36;0,85607;2851,32304
51,44;0,85738;2855,01387
51,52;0,8587;2858,40388
51,6;0,86007;2862,97835
51,68;0,86127;2866,44902
51,76;0,86252;2869,59596
51,84;0,86408;2875,17644
51,92;0,86533;2879,46016
52;0,86671;2883,61832
52,08;0,86802;2887,24191
52,16;0,8694;2890,94578
52,24;0,87077;2895,55527
52,32;0,87191;2898,41201
52,4;0,87317;2902,47202
52,48;0,8749;2912,26469
52,56;0,87616;2918,99964
52,64;0,87741;2921,73512
52,72;0,87873;2924,72113
52,8;0,8801;2929,19092
52,88;0,8813;2932,19518
52,96;0,88249;2934,34653
53,04;0,88405;2939,11286
53,12;0,88536;2943,18814
53,2;0,88668;2947,52065
53,28;0,88805;2952,17242
53,36;0,88943;2956,05175
53,44;0,8908;2959,7912
53,52;0,892;2963,57013
53,6;0,8932;2966,22496
53,68;0,89469;2971,50426
53,76;0,89601;2976,64367
53,84;0,89732;2979,9277
53,92;0,8987;2984,90599
54;0,90007;2989,83511
54,08;0,90145;2993,67551
54,16;0,90258;2996,48978
54,24;0,90384;2999,04794
54,32;0,90533;3005,48933
54,4;0,90665;3008,92983
54,48;0,90796;3012,03839
54,56;0,90934;3017,24281
54,64;0,91071;3021,57961
54,72;0,91209;3025,98253
54,8;0,91322;3029,28872
54,88;0,9146;3032,86351
54,96;0,91603;3037,86155
55,04;0,91735;3041,01165
55,12;0,91873;3045,76196
55,2;0,92004;3049,629
55,28;0,92142;3053,96467
55,36;0,92273;3058,99326
55,44;0,92393;3062,02862
55,52;0,92524;3064,73467
55,6;0,92668;3070,26841
55,68;0,92799;3074,26937
55,76;0,92931;3078,08071
55,84;0,93068;3081,17829
55,92;0,93212;3089,1452
56;0,93337;3092,6466
56,08;0,93451;3095,83377
56,16;0,93594;3099,57489
56,24;0,93738;3104,47644
56,32;0,9387;3108,54577
56,4;0,94007;3111,79329
56,48;0,94139;3116,7319
56,56;0,94276;3120,29589
56,64;0,94408;3124,48442
56,72;0,94521;3127,67997
56,8;0,94665;3131,53341
56,88;0,94802;3136,78123
56,96;0,94934;3140,13734
57,04;0,95071;3144,86027
57,12;0,95203;3148,5077
57,2;0,9534;3153,21535
57,28;0,95472;3156,70297
57,36;0,95585;3158,84724
57,44;0,95735;3162,37845
57,52;0,95866;3168,27483
57,6;0,96004;3172,66509
57,68;0,96142;3177,03262
57,76;0,96267;3180,73034
57,84;0,96411;3184,31705
57,92;0,96536;3188,27555
58;0,96662;3191,55455
58,08;0,96805;3198,25485
58,16;0,96931;3202,10382
58,24;0,97068;3205,4618
58,32;0,972;3209,73657
58,4;0,97337;3213,78112
58,48;0,97475;3217,49635
58,56;0,97588;3220,11523
58,64;0,9772;3222,41671
58,72;0,97869;3227,98826
58,8;0,98001;3231,9732
58,88;0,98132;3236,36755
58,96;0,9827;3240,06155
59,04;0,98408;3243,70712
59,12;0,98545;3249,07899
59,2;0,98653;3251,52278
59,28;0,9879;3254,95005
59,36;0,98934;3260,50781
59,44;0,99065;3262,67369
59,52;0,99203;3266,71414
59,6;0,99334;3270,64022
59,68;0,99478;3275,03122
59,76;0,99603;3278,92192
59,84;0,99717;3281,06023
59,92;0,99872;3286,88137
60;1,00004;3291,21351
60,08;1,00135;3293,79067
60,16;1,00273;3296,92662
60,24;1,00404;3300,92907
60,32;1,00542;3305,03248
60,4;1,00662;3307,84433
60,48;1,00787;3311,00971
60,56;1,00937;3315,69165
60,64;1,01068;3319,68702
60,72;1,012;3322,63522
60,8;1,01337;3325,72013
60,88;1,01469;3329,33329
60,96;1,01606;3333,31823
61,04;1,01726;3335,74042
61,12;1,01851;3338,80037
61,2;1,02001;3343,74309
61,28;1,02132;3347,44379
61,36;1,0227;3350,64642
61,44;1,02401;3354,04351
61,52;1,02533;3356,92018
61,6;1,02676;3361,11151
61,68;1,0279;3364,01798
61,76;1,02922;3364,65426
61,84;1,03071;3370,52457
61,92;1,03197;3373,9049
62;1,03334;3377,59592
62,08;1,03466;3380,81233
62,16;1,03603;3383,56793
62,24;1,03741;3387,06598
62,32;1,03854;3390,12332
62,4;1,03986;3391,71961
62,48;1,04135;3396,20598
62,56;1,04267;3398,89117
62,64;1,04404;3402,98526
62,72;1,04536;3406,67963
62,8;1,04673;3409,24747
62,88;1,04811;3413,01262
62,96;1,04925;3414,86856
63,04;1,05056;3417,10635
63,12;1,052;3421,29879
63,2;1,05337;3424,339
63,28;1,05475;3427,48463
63,36;1,05606;3430,59301
63,44;1,05744;3432,85911
63,52;1,05875;3436,69578
63,6;1,05989;3437,77724
63,68;1,06126;3440,26498
63,76;1,0627;3446,06228
63,84;1,06401;3448,28516
63,92;1,06539;3451,6938
64;1,0667;3454,16479
64,08;1,06808;3457,20164
64,16;1,06939;3460,72167
64,24;1,07053;3462,30306
64,32;1,07191;3465,24231
64,4;1,07334;3471,92772
64,48;1,07472;3473,73374
64,56;1,07603;3477,01721
64,64;1,07741;3480,27423
64,72;1,07878;3484,33033
64,8;1,07992;3486,06221
64,88;1,08117;3486,96895
64,96001;1,08273;3491,19753
65,04;1,08398;3494,42102
65,12;1,08536;3496,37978
65,2;1,08667;3499,79326
65,28001;1,08805;3502,14988
65,36;1,08942;3506,06218
65,44;1,09056;3507,98368
65,52;1,09194;3510,02105
65,60001;1,09343;3514,48841
65,68;1,09469;3516,44643
65,76;1,09606;3519,8357
65,84001;1,09732;3522,54212
65,92001;1,09869;3525,11927
66;1,10007;3529,45775
66,08;1,10126;3530,97171
66,16;1,10264;3533,45089
66,24001;1,10407;3537,77222
66,32;1,10539;3540,29611
66,4;1,1067;3543,14595
66,48;1,10808;3545,16506
66,56001;1,10945;3547,98697
66,64;1,11077;3551,41535
66,72;1,11191;3552,89653
66,8;1,11328;3555,78922
66,88001;1,11472;3559,49737
66,96001;1,11597;3561,72733
67,04;1,11735;3565,79386
67,12;1,11872;3568,37325
67,20001;1,1201;3570,58682
67,28001;1,12135;3574,58927
67,36;1,12255;3575,39393
67,44;1,12392;3578,30524
67,52001;1,12536;3582,43473
67,60001;1,12667;3584,74329
67,68;1,12799;3587,73991
67,76;1,12936;3589,69122
67,84001;1,13074;3593,60687
67,92001;1,13205;3596,46901
68;1,13325;3597,66409
68,08;1,13468;3600,71175
68,16;1,136;3604,56668
68,24001;1,13738;3606,39542
68,32;1,13875;3610,44407
68,4;1,14001;3613,18886
68,48;1,14144;3616,84784
68,56001;1,1427;3617,92929
68,64001;1,14389;3622,66712
68,72;1,14533;3625,28041
68,8;1,14664;3628,09002
68,88001;1,14802;3631,38877
68,96001;1,14933;3634,58991
69,04;1,15071;3636,79044
69,12;1,15208;3640,0903
69,20001;1,15328;3641,89669
69,28001;1,15454;3642,86192
69,36;1,15603;3646,09882
69,44;1,15735;3650,11469
69,52001;1,15878;3652,27722
69,60001;1,1601;3655,33866
69,68;1,16141;3658,0503
69,76;1,16279;3660,84389
69,84001;1,16392;3663,34431
69,92001;1,16524;3664,54311
70;1,16667;3668,63348
70,08;1,16799;3671,69529
70,16;1,16936;3674,23259
70,24001;1,17068;3677,5317
70,32;1,17205;3680,37708
70,4;1,17343;3683,22842
70,48;1,17462;3685,25274
70,56001;1,17588;3686,59124
70,64001;1,17731;3690,76766
70,72;1,17869;3693,1511
70,8;1,18001;3695,89515
70,88001;1,18132;3698,82025
70,96001;1,18276;3701,18767
71,04;1,18407;3704,79934
71,12;1,18521;3706,21048
71,20001;1,18658;3707,40891
71,28001;1,18802;3712,0156
71,36;1,18933;3714,58083
71,44;1,19065;3717,63259
71,52001;1,19202;3719,95419
71,60001;1,1934;3723,47459
71,68;1,19471;3726,3792
71,76;1,19579;3727,12202
71,84001;1,19728;3730,20321
71,92001;1,19872;3734,78755
72;1,20003;3737,22315
72,08;1,20135;3740,11956
72,16;1,20273;3742,75222
72,24001;1,2041;3745,68962
72,32;1,20536;3748,25709
72,4;1,20655;3748,58826
72,48;1,20805;3752,64846
72,56001;1,20936;3755,46142
72,64001;1,21068;3757,96221
72,72;1,21205;3760,78188
72,8;1,21337;3762,4184
72,88001;1,21474;3765,51561
72,96001;1,21594;3767,01392
73,04;1,21719;3768,18441
73,12;1,21863;3772,70766
73,20001;1,22;3777,24953
73,28001;1,22138;3779,15837
73,36;1,2227;3780,79861
73,44;1,22407;3783,6764
73,52001;1,22539;3786,10827
73,60001;1,22658;3788,03611
73,68;1,22796;3789,41894
73,76;1,22939;3794,08598
73,84001;1,23065;3795,70164
73,92001;1,23202;3797,96103
74;1,2334;3800,92077
74,08;1,23471;3803,06952
74,16;1,23609;3805,29873
74,24001;1,23722;3807,23961
74,32001;1,23866;3809,01806
74,4;1,24003;3813,00375
74,48;1,24135;3814,96884
74,56001;1,24272;3817,9718
74,64001;1,24404;3820,28297
74,72;1,24542;3822,33374
74,8;1,24673;3826,16445
74,88001;1,24787;3827,51673
74,96001;1,2493;3830,1181
75,04;1,25068;3834,0468
75,12;1,25205;3837,07955
75,20001;1,25343;3841,2597
75,28001;1,25474;3843,49003
75,36;1,25612;3847,25258
75,44;1,25731;3850,00147
75,52001;1,25851;3851,58323
75,60001;1,26;3855,00826
75,68;1,26132;3859,62278
75,76;1,26269;3862,97256
75,84001;1,26401;3865,64471
75,92001;1,26532;3868,36939
76;1,2667;3872,48732
76,08;1,26796;3875,72721
76,16;1,26915;3877,9363
76,24001;1,27065;3882,51804
76,32001;1,27202;3885,79331
76,4;1,27334;3889,36549
76,48;1,27465;3891,90242
76,56001;1,27603;3896,04606
76,64001;1,27746;3899,34368
76,72;1,27866;3902,2889
76,8;1,27985;3903,88034
76,88001;1,28135;3908,32536
76,96001;1,28272;3911,36818
77,04;1,28404;3914,82972
77,12;1,28535;3917,7727
77,20001;1,28667;3920,21388
77,28001;1,2881;3923,62215
77,36;1,28924;3926,95665
77,44;1,29056;3928,61106
77,52001;1,29199;3933,19614
77,60001;1,29337;3936,47701
77,68;1,29468;3940,74284
77,76;1,296;3942,14578
77,84001;1,29737;3945,2333
77,92001;1,29875;3949,18323
78;1,29988;3950,70091
78,08;1,30126;3953,20281
78,16;1,30275;3957,67651
78,24001;1,30407;3960,42094
78,32001;1,30538;3962,85988
78,4;1,30664;3965,86806
78,48;1,30807;3968,85499
78,56001;1,30939;3972,51733
78,64001;1,31053;3972,98373
78,72;1,31184;3975,54711
78,8;1,3134;3983,41417
78,88001;1,31471;3984,66103
78,96001;1,31603;3986,99455
79,04;1,31734;3989,65068
79,12;1,31878;3992,48339
79,20001;1,31997;3995,25799
79,28001;1,32117;3995,71843
79,36;1,32272;3999,64862
79,44;1,32404;4002,49064
79,52001;1,32535;4004,82565
79,60001;1,32673;4007,83457
79,68;1,3281;4010,40912
79,76;1,32948;4013,386
79,84001;1,33062;4014,94838
79,92001;1,33187;4016,69517
80;1,33337;4021,45945
80,08;1,33462;4024,47246
80,16;1,33594;4026,98927
80,24001;1,33737;4031,70474
80,32001;1,33875;4037,17831
80,4;1,34006;4042,67795
80,48;1,34126;4047,2988
80,56001;1,34251;4051,97144
80,64001;1,34407;4058,61847
80,72;1,34532;4064,67691
80,8;1,3467;4070,03947
80,88001;1,34801;4074,42041
80,96001;1,34939;4081,04174
81,04;1,35076;4085,32508
81,12;1,3519;4090,22272
81,20001;1,35328;4095,16171
81,28001;1,35471;4100,88561
81,36;1,35597;4106,13306
81,44;1,35734;4111,74931
81,52001;1,35866;4116,49756
81,60001;1,36003;4121,91339
81,68;1,36141;4128,398
81,76;1,36254;4132,90635
81,84001;1,36392;4137,08426
81,92001;1,36535;4143,79798
82,00001;1,36667;4149,0104
82,08;1,36804;4154,15689
82,16;1,36936;4158,30947
82,24001;1,37079;4164,299
82,32001;1,37211;4169,32665
82,4;1,37325;4173,43788
82,48;1,37456;4177,60573
82,56001;1,37606;4184,67112
82,64001;1,37737;4189,79786
82,72;1,37875;4194,01489
82,8;1,38006;4199,25973
82,88001;1,38138;4204,53586
82,96001;1,38269;4209,94237
83,04;1,38389;4213,27688
83,12;1,38526;4218,5504
83,20001;1,3867;4224,50602
83,28001;1,38801;4230,20795
83,36;1,38939;4235,35071
83,44;1,3907;4240,60635
83,52001;1,39208;4245,79345
83,60001;1,39339;4251,13067
83,68;1,39459;4254,48194
83,76;1,39597;4260,80301
83,84001;1,3974;4269,49784
83,92001;1,39872;4273,59417
84,00001;1,40009;4279,19775
84,08;1,40135;4284,90452
84,16;1,40272;4290,36915
84,24001;1,40398;4296,16496
84,32001;1,40517;4300,29854
84,4;1,40667;4306,06268
84,48;1,40798;4313,29645
84,56001;1,4093;4319,51731
84,64001;1,41067;4325,19466
84,72;1,41199;4331,42856
84,8;1,41342;4338,23727
84,88001;1,41456;4343,32341
84,96001;1,41587;4348,50119
85,04;1,41737;4356,16747
85,12;1,41868;4363,1237
85,20001;1,42006;4368,01538
85,28001;1,42138;4374,42362
85,36;1,42275;4380,18143
85,44;1,42413;4386,13519
85,52001;1,42526;4390,48223
85,60001;1,42658;4396,05191
85,68;1,42801;4403,80871
85,76;1,42933;4409,43353
85,84001;1,4307;4415,16526
85,92001;1,43202;4420,71781
86,00001;1,43339;4426,53112
86,08;1,43471;4432,78439
86,16;1,4359;4437,05805
86,24001;1,4374;4444,27058
86,32001;1,43871;4453,44038
86,4;1,44009;4458,5716
86,48;1,44141;4463,1701
86,56001;1,44272;4468,86979
86,64001;1,4441;4473,36212
86,72;1,44529;4477,83247
86,8;1,44649;4481,29848
86,88001;1,44804;4487,85983
86,96001;1,44936;4493,29466
87,04;1,45067;4498,34019
87,12;1,45205;4502,87946
87,20001;1,45336;4508,19395
87,28001;1,45474;4513,1173
87,36;1,45593;4516,84073
87,44;1,45719;4520,17412
87,52001;1,45868;4526,57714
87,60001;1,46;4531,20656
87,68001;1,46137;4536,17908
87,76;1,46275;4539,9718
87,84001;1,46407;4544,93798
87,92001;1,46544;4549,69592
88,00001;1,46664;4552,87807
88,08;1,46789;4555,44516
88,16;1,46933;4560,41768
88,24001;1,47064;4566,33121
88,32001;1,47202;4569,22576
88,4;1,47339;4574,0094
88,48;1,47471;4578,10871
88,56001;1,47608;4582,67219
88,64001;1,47728;4585,58314
88,72;1,47847;4587,73859
88,8;1,48003;4593,1533
88,88001;1,48128;4596,58653
88,96001;1,48266;4601,21259
89,04;1,48404;4605,2292
89,12;1,48535;4609,16124
89,20001;1,48679;4612,6999
89,28001;1,48798;4616,86291
89,36;1,48924;4618,78739
89,44;1,49067;4623,29835
89,52001;1,49205;4627,35705
89,60001;1,49342;4630,95009
89,68001;1,49468;4635,03413
89,76;1,49605;4639,51975
89,84001;1,49749;4643,2171
89,92001;1,49856;4646,45475
90,00001;1,49982;4648,14231
90,08;1,50137;4652,64507
90,16;1,50269;4657,62168
90,24001;1,50406;4661,39913
90,32001;1,50532;4664,48478
90,4;1,5067;4668,60533
90,48;1,50807;4672,91363
90,56001;1,50927;4676,13488
90,64001;1,51052;4678,99889
90,72;1,51202;4684,06752
90,8;1,51333;4687,94294
90,88001;1,51471;4692,45389
90,96001;1,51602;4696,28796
91,04;1,5174;4699,75583
91,12;1,51877;4705,03941
91,20001;1,51991;4707,55324
91,28001;1,52122;4711,78219
91,36;1,52272;4717,00504
91,44;1,52403;4720,95832
91,52001;1,52535;4725,12953
91,60001;1,52666;4728,69463
91,68001;1,52804;4733,58743
91,76;1,52942;4737,56306
91,84001;1,53049;4740,65877
91,92001;1,53193;4745,00135
92,00001;1,53342;4751,1898
92,08;1,53474;4755,80804
92,16;1,53605;4759,27293
92,24001;1,53737;4763,66617
92,32001;1,53874;4768,27361
92,4;1,54006;4771,96015
92,48;1,54119;4775,62249
92,56001;1,54263;4779,8004
92,64001;1,54406;4786,19412
92,72;1,54532;4789,91643
92,8;1,54669;4794,26645
92,88001;1,54807;4798,11206
92,96001;1,54944;4803,62512
93,04;1,5507;4807,14887
93,12;1,5519;4811,32865
93,20001;1,55327;4815,34526
93,28001;1,55471;4821,19024
93,36001;1,55596;4825,1342
93,44;1,55734;4829,45293
93,52001;1,55871;4833,93595
93,60001;1,56009;4838,51321
93,68001;1,56134;4842,94817
93,76;1,56254;4846,71146
93,84001;1,56254;4851,586
93,92001;1,56559;4871,51518
94,00001;1,56678;4870,51941
94,08;1,56804;4873,40279
94,16;1,56941;4876,84682
94,24001;1,57061;4880,26775
94,32001;1,57187;4883,13586
94,4;1,5733;4887,1953
94,48;1,57462;4892,21923
94,56001;1,57593;4896,99356
94,64001;1,57731;4900,77436
94,72;1,57868;4904,57639
94,8;1,58006;4908,92343
94,88001;1,58131;4913,81027
94,96001;1,58257;4917,432
95,04;1,584;4921,57675
95,12;1,58538;4926,65954
95,20001;1,58669;4930,17584
95,28001;1,58807;4935,05038
95,36001;1,58944;4939,55351
95,44;1,59076;4944,39341
95,52001;1,59201;4948,3411
95,60001;1,59321;4951,2621
95,68001;1,59471;4956,02377
95,76;1,59602;4960,93966
95,84001;1,5974;4965,86263
95,92001;1,59871;4969,30294
96,00001;1,60003;4974,17487
96,08;1,60146;4981,60832
96,16;1,6026;4985,6592
96,24001;1,60385;4988,00576
96,32001;1,60535;4994,26648
96,4;1,60672;4999,18386
96,48;1,60804;5003,07791
96,56001;1,60935;5007,01889
96,64001;1,61073;5010,96547
96,72;1,6121;5016,51205
96,8;1,6133;5019,31645
96,88001;1,6145;5022,97953
96,912;1,61521;5024,78555